{"stream":"btcusdt@depth@100ms","data":{"e":"depthUpdate","E":1790299049314,"s":"BTCUSDT","U":100639375226,"u":100639375237,"b":[["84735.39000000","5.75031000"],["84734.03000000","0.01699000"],["84725.03000000","0.00000000"],["77944.04000000","0.00000000"],["76261.86000000","0.00353000"]],"a":[["84735.40000000","0.45117000"],["84749.07000000","0.00400000"],["84760.44000000","0.05585000"],["84777.00000000","0.00000000"],["84787.66000000","0.73612000"],["84802.06000000","0.73599000"]]}}
{"stream":"dogeusdt@depth@100ms","data":{"e":"depthUpdate","E":1790299049374,"s":"DOGEUSDT","U":25516667542,"u":25516667543,"b":[],"a":[["0.09683000","176937.00000000"],["0.09687000","381725.00000000"]]}}
{"stream":"btcusdt@depth@100ms","data":{"e":"depthUpdate","E":1790299049414,"s":"BTCUSDT","U":100639375238,"u":100639375246,"b":[["84735.39000000","5.74841000"],["84725.20000000","0.00000000"],["84528.01000000","0.00000000"],["84526.01000000","0.00734000"],["83464.36000000","0.00024000"],["67788.32000000","0.00261000"],["67788.31000000","0.00000000"]],"a":[]}}
{"stream":"btcusdt@depth@100ms","data":{"e":"depthUpdate","E":1790299049514,"s":"BTCUSDT","U":100639375247,"u":100639375267,"b":[["84735.39000000","5.75026000"],["84734.82000000","0.01136000"],["84734.27000000","0.00590000"],["84734.03000000","0.01693000"],["84732.76000000","0.00000000"],["84418.42000000","0.01417000"],["84362.10000000","0.00000000"],["83464.36000000","0.00016000"],["76261.86000000","0.00353000"],["76261.00000000","0.00000000"],["67788.00000000","0.00300000"]],"a":[["84735.40000000","0.21470000"],["84749.66000000","0.00000000"],["84749.91000000","0.00200000"],["84750.27000000","0.00590000"],["84765.61000000","0.00000000"],["84943.82000000","0.00000000"],["85011.28000000","0.01411000"]]}}
{"stream":"btcusdt@depth@100ms","data":{"e":"depthUpdate","E":1790299049614,"s":"BTCUSDT","U":100639375268,"u":100639375271,"b":[["84690.47000000","0.00000000"],["83464.36000000","0.00024000"],["76261.86000000","0.00338000"],["67788.32000000","0.00232000"]],"a":[]}}
{"stream":"btcusdt@depth@100ms","data":{"e":"depthUpdate","E":1790299049714,"s":"BTCUSDT","U":100639375272,"u":100639375291,"b":[["84735.39000000","5.75033000"],["84734.82000000","0.01130000"],["84734.27000000","0.00000000"],["84734.03000000","0.01699000"],["84733.43000000","0.00590000"],["84690.47000000","0.00354000"],["84685.27000000","0.97348000"],["83464.36000000","0.00024000"],["83464.35000000","0.00030000"],["76261.86000000","0.00353000"]],"a":[["84735.40000000","0.45053000"],["84749.07000000","0.00400000"],["84760.43000000","0.05585000"],["84760.44000000","0.00000000"],["84825.55000000","1.16771000"]]}}
{"stream":"dogeusdt@depth@100ms","data":{"e":"depthUpdate","E":1790299049774,"s":"DOGEUSDT","U":25516667544,"u":25516667545,"b":[["0.09673000","122819.00000000"]],"a":[["0.09675000","7435.00000000"]]}}
{"stream":"btcusdt@depth@100ms","data":{"e":"depthUpdate","E":1790299049814,"s":"BTCUSDT","U":100639375292,"u":100639375306,"b":[["84542.09000000","0.00000000"],["82676.47000000","0.00287000"],["76261.86000000","0.00353000"],["67788.32000000","0.00203000"],["67788.31000000","0.00000000"]],"a":[["84735.40000000","0.45203000"],["84740.53000000","0.00014000"],["84740.54000000","0.18015000"],["84765.61000000","0.01967000"],["84825.55000000","0.79836000"],["84827.15000000","0.00020000"],["84829.94000000","1.57930000"],["84935.14000000","0.00000000"]]}}
{"stream":"dogeusdt@depth@100ms","data":{"e":"depthUpdate","E":1790299049874,"s":"DOGEUSDT","U":25516667546,"u":25516667549,"b":[["0.09674000","75163.00000000"]],"a":[["0.09675000","47137.00000000"]]}}
{"stream":"btcusdt@depth@100ms","data":{"e":"depthUpdate","E":1790299049914,"s":"BTCUSDT","U":100639375307,"u":100639375334,"b":[["84735.39000000","5.70853000"],["84733.93000000","0.00000000"],["84733.86000000","0.00200000"],["84733.61000000","0.00200000"],["84725.17000000","0.00190000"],["84556.57000000","0.00000000"],["84547.96000000","0.00000000"],["83464.36000000","0.00024000"],["67788.00000000","0.00400000"]],"a":[["84735.40000000","0.45168000"],["84735.41000000","0.00039000"],["84738.94000000","0.00020000"],["84745.39000000","0.00000000"],["84748.56000000","0.00590000"],["84752.93000000","0.00000000"],["84765.61000000","0.00000000"],["84782.00000000","0.70000000"],["86006.44000000","0.00030000"]]}}
{"stream":"dogeusdt@depth@100ms","data":{"e":"depthUpdate","E":1790299049974,"s":"DOGEUSDT","U":25516667550,"u":25516667576,"b":[["0.09674000","30742.00000000"],["0.09673000","114819.00000000"],["0.09669000","253190.00000000"]],"a":[["0.09675000","62023.00000000"],["0.09676000","54582.00000000"],["0.09677000","92931.00000000"],["0.09680000","155976.00000000"],["0.09681000","215527.00000000"]]}}
{"stream":"btcusdt@depth@100ms","data":{"e":"depthUpdate","E":1790299050014,"s":"BTCUSDT","U":100639375335,"u":100639375603,"b":[["84735.39000000","4.82195000"],["84735.38000000","0.00075000"],["84735.36000000","2.70216000"],["84734.82000000","0.00000000"],["84734.04000000","0.00236000"],["84734.03000000","0.01687000"],["84733.86000000","0.00000000"],["84733.61000000","0.00000000"],["84733.43000000","0.00000000"],["84733.42000000","0.00000000"],["84733.39000000","0.00000000"],["84733.19000000","0.00000000"],["84732.75000000","0.00236000"],["84732.74000000","0.00014000"],["84732.73000000","0.29512000"],["84732.72000000","0.00000000"],["84732.71000000","0.00018000"],["84732.70000000","0.00012000"],["84731.90000000","0.00000000"],["84731.74000000","0.00000000"],["84731.60000000","0.00000000"],["84731.30000000","0.03006000"],["84731.05000000","0.03006000"],["84730.90000000","0.00236000"],["84730.31000000","0.00000000"],["84730.11000000","0.00000000"],["84730.05000000","0.00596000"],["84728.80000000","0.04000000"],["84728.65000000","0.00200000"],["84728.48000000","0.00000000"],["84728.47000000","0.01341000"],["84727.99000000","0.00590000"],["84726.74000000","0.01014000"],["84726.73000000","0.86344000"],["84725.09000000","0.00048000"],["84724.37000000","0.00000000"],["84724.27000000","0.00007000"],["84722.55000000","0.00000000"],["84719.82000000","0.00013000"],["84716.10000000","0.00407000"],["84710.47000000","0.00000000"],["84708.92000000","0.00200000"],["84699.15000000","0.00007000"],["84682.20000000","0.00007000"],["84666.80000000","1.16962000"],["84665.25000000","0.00007000"],["84658.37000000","0.04600000"],["84654.19000000","0.00000000"],["84648.30000000","0.00007000"],["84631.35000000","0.00007000"],["84614.40000000","0.00007000"],["84603.13000000","0.00000000"],["84597.45000000","0.00007000"],["84580.50000000","0.00007000"],["84563.55000000","0.00007000"],["84546.60000000","0.00007000"],["84543.94000000","4.17650000"],["84542.80000000","0.00616000"],["84529.65000000","0.00007000"],["84515.67000000","0.00000000"],["84512.70000000","0.00007000"],["84495.75000000","0.00007000"],["84478.80000000","0.00007000"],["83464.36000000","0.00016000"],["76261.86000000","0.00353000"],["67788.32000000","0.00290000"]],"a":[["84735.40000000","1.74767000"],["84735.41000000","0.00018000"],["84737.66000000","0.00007000"],["84737.67000000","0.01345000"],["84737.68000000","0.03031000"],["84738.81000000","0.00012000"],["84738.94000000","0.00000000"],["84738.95000000","0.00000000"],["84738.96000000","0.00013000"],["84739.74000000","0.00014000"],["84739.75000000","0.01110000"],["84739.82000000","0.00000000"],["84740.53000000","0.00000000"],["84740.54000000","0.00000000"],["84740.55000000","0.00000000"],["84741.49000000","0.00014000"],["84741.50000000","0.16872000"],["84742.04000000","0.00000000"],["84742.05000000","0.01122000"],["84742.38000000","0.00007000"],["84742.39000000","0.18008000"],["84742.75000000","0.00000000"],["84742.90000000","0.00672000"],["84744.14000000","0.18001000"],["84744.22000000","0.00000000"],["84744.44000000","0.00200000"],["84744.94000000","0.11432000"],["84745.53000000","0.00000000"],["84745.68000000","0.00000000"],["84746.66000000","0.00010000"],["84746.99000000","0.00590000"],["84747.16000000","0.00000000"],["84747.84000000","0.00236000"],["84747.86000000","0.00000000"],["84749.08000000","0.00000000"],["84749.12000000","0.00407000"],["84749.71000000","0.00007000"],["84749.91000000","0.00000000"],["84750.00000000","0.00007000"],["84750.27000000","0.00000000"],["84750.33000000","0.00000000"],["84751.86000000","0.00000000"],["84766.95000000","0.00007000"],["84776.68000000","0.00000000"],["84779.39000000","0.02314000"],["84783.14000000","0.00000000"],["84783.90000000","0.00007000"],["84800.85000000","0.00007000"],["84817.80000000","0.00007000"],["84834.75000000","0.00007000"],["84851.70000000","0.00007000"],["84868.65000000","0.00007000"],["84885.60000000","0.00007000"],["84902.55000000","0.00007000"],["84919.50000000","0.00007000"],["84934.70000000","4.22508000"],["84936.45000000","0.00007000"],["84953.40000000","0.00007000"],["84970.35000000","0.00007000"],["84987.30000000","0.00007000"],["93625.51000000","0.00000000"]]}}
{"stream":"dogeusdt@depth@100ms","data":{"e":"depthUpdate","E":1790299050074,"s":"DOGEUSDT","U":25516667577,"u":25516667599,"b":[["0.09674000","71478.00000000"],["0.09673000","114830.00000000"],["0.09672000","196152.00000000"],["0.09656000","266373.00000000"]],"a":[["0.09675000","62023.00000000"],["0.09676000","54593.00000000"]]}}
{"stream":"btcusdt@depth@100ms","data":{"e":"depthUpdate","E":1790299050114,"s":"BTCUSDT","U":100639375604,"u":100639375652,"b":[["84735.39000000","4.77978000"],["84735.38000000","0.00096000"],["84735.14000000","0.00328000"],["84735.13000000","0.04185000"],["84734.75000000","0.01107000"],["84734.03000000","0.01687000"],["84733.29000000","0.00000000"],["84732.74000000","0.00000000"],["84730.05000000","0.00590000"],["84728.80000000","0.00000000"],["84726.73000000","0.86351000"],["84726.50000000","0.04000000"],["84725.30000000","0.00060000"],["84722.40000000","0.00008000"],["84721.04000000","0.00000000"],["84654.54000000","0.00000000"],["83464.36000000","0.00024000"],["82386.87000000","0.00010000"]],"a":[["84735.40000000","1.74815000"],["84737.66000000","0.00014000"],["84740.74000000","0.00000000"],["84741.49000000","0.18015000"],["84742.38000000","0.00000000"],["84742.39000000","0.00007000"],["84743.88000000","0.00658000"],["84745.68000000","0.00283000"],["84745.72000000","0.01415000"],["84746.36000000","0.00000000"],["84746.70000000","0.00000000"],["84746.74000000","0.00000000"],["84747.86000000","0.18001000"],["84748.95000000","0.00000000"],["84749.06000000","0.18001000"],["84754.94000000","0.00000000"],["93625.51000000","0.02329000"]]}}
{"stream":"dogeusdt@depth@100ms","data":{"e":"depthUpdate","E":1790299050174,"s":"DOGEUSDT","U":25516667600,"u":25516667601,"b":[["0.09671000","168114.00000000"],["0.09644000","1742025.00000000"]],"a":[]}}
{"stream":"btcusdt@depth@100ms","data":{"e":"depthUpdate","E":1790299050214,"s":"BTCUSDT","U":100639375653,"u":100639375739,"b":[["84735.39000000","4.78214000"],["84735.38000000","0.00096000"],["84734.04000000","0.00000000"],["84731.05000000","0.03000000"],["84728.65000000","0.00000000"],["84726.74000000","0.01200000"],["84726.73000000","0.86337000"],["84726.50000000","0.34000000"],["84725.80000000","0.00400000"],["84721.04000000","0.00006000"],["83464.36000000","0.00024000"],["76261.86000000","0.00353000"],["67788.32000000","0.00261000"]],"a":[["84735.40000000","1.26493000"],["84735.41000000","0.00032000"],["84737.68000000","0.03037000"],["84738.06000000","0.00014000"],["84738.07000000","0.01110000"],["84738.81000000","0.00006000"],["84739.75000000","0.01128000"],["84739.83000000","0.00000000"],["84740.72000000","0.18008000"],["84740.73000000","0.23926000"],["84740.74000000","0.00000000"],["84741.48000000","0.00000000"],["84741.49000000","0.00000000"],["84741.50000000","0.00006000"],["84742.05000000","0.01116000"],["84742.39000000","0.00000000"],["84744.14000000","0.18001000"],["84744.44000000","0.00000000"],["84744.93000000","0.00012000"],["84744.94000000","0.11432000"],["84746.23000000","0.00200000"],["84747.86000000","0.00000000"],["84749.06000000","0.18001000"],["84754.94000000","0.00006000"]]}}
{"stream":"btcusdt@depth@100ms","data":{"e":"depthUpdate","E":1790299050314,"s":"BTCUSDT","U":100639375740,"u":100639375789,"b":[["84735.39000000","4.77713000"],["84735.38000000","0.00089000"],["84731.24000000","0.01335000"],["84726.74000000","0.01200000"],["84726.73000000","0.86337000"],["84725.50000000","0.00000000"],["84725.30000000","0.00012000"],["84603.16000000","0.00000000"]],"a":[["84735.40000000","1.26500000"],["84735.41000000","0.00039000"],["84739.75000000","0.01122000"],["84740.69000000","0.00019000"],["84740.70000000","0.17123000"],["84740.71000000","0.13168000"],["84740.72000000","0.00000000"],["84740.73000000","0.00000000"],["84742.05000000","0.01122000"],["84742.39000000","0.00000000"],["84744.14000000","0.00000000"],["84744.94000000","0.11432000"],["84747.86000000","0.00000000"],["84749.06000000","0.18001000"],["89076.24000000","0.00010000"]]}}
{"stream":"dogeusdt@depth@100ms","data":{"e":"depthUpdate","E":1790299050374,"s":"DOGEUSDT","U":25516667602,"u":25516667607,"b":[["0.09673000","133454.00000000"],["0.09671000","182037.00000000"],["0.09670000","229840.00000000"]],"a":[["0.09676000","22023.00000000"],["0.09677000","113954.00000000"],["0.09678000","291356.00000000"]]}}
{"stream":"btcusdt@depth@100ms","data":{"e":"depthUpdate","E":1790299050414,"s":"BTCUSDT","U":100639375790,"u":100639375864,"b":[["84735.39000000","5.08750000"],["84726.74000000","0.01214000"],["84726.73000000","0.86351000"],["84651.58000000","0.72324000"],["84651.40000000","1.09604000"],["83464.36000000","0.00024000"],["76261.86000000","0.00360000"],["76261.85000000","0.00008000"],["67788.32000000","0.00232000"],["67788.31000000","0.00000000"]],"a":[["84735.40000000","1.26271000"],["84735.41000000","0.00032000"],["84737.67000000","0.04752000"],["84738.07000000","0.01116000"],["84739.44000000","0.00014000"],["84739.45000000","0.10845000"],["84739.74000000","0.00000000"],["84739.75000000","0.01116000"],["84740.68000000","0.18008000"],["84740.69000000","0.22011000"],["84740.70000000","0.00000000"],["84740.71000000","0.00000000"],["84742.05000000","0.01122000"],["84742.39000000","0.18001000"],["84744.14000000","0.18001000"],["84744.93000000","0.00012000"],["84744.94000000","0.11432000"],["84745.62000000","0.00192000"],["84745.72000000","0.01415000"],["84747.86000000","0.00000000"],["84749.06000000","0.18001000"],["84840.38000000","1.18129000"]]}}
{"stream":"dogeusdt@depth@100ms","data":{"e":"depthUpdate","E":1790299050474,"s":"DOGEUSDT","U":25516667608,"u":25516667611,"b":[["0.09665000","227954.00000000"],["0.09656000","261660.00000000"]],"a":[["0.09676000","31233.00000000"]]}}
{"stream":"btcusdt@depth@100ms","data":{"e":"depthUpdate","E":1790299050514,"s":"BTCUSDT","U":100639375865,"u":100639375891,"b":[["84735.39000000","5.08757000"],["84726.74000000","0.01200000"],["84726.73000000","0.86337000"],["83464.36000000","0.00016000"],["76261.86000000","0.00360000"],["67788.00000000","0.00500000"]],"a":[["84735.40000000","1.26271000"],["84739.75000000","0.01122000"],["84740.67000000","0.18554000"],["84740.69000000","0.00012000"],["84742.05000000","0.01116000"],["84742.39000000","0.00000000"],["84744.14000000","0.18001000"],["84744.94000000","0.19176000"],["84745.62000000","0.00000000"],["84745.64000000","0.00190000"],["84747.86000000","0.16664000"],["84765.03000000","0.00000000"],["84807.42000000","0.00000000"],["84841.32000000","0.00000000"]]}}
{"stream":"btcusdt@depth@100ms","data":{"e":"depthUpdate","E":1790299050614,"s":"BTCUSDT","U":100639375892,"u":100639375910,"b":[["84735.39000000","5.08646000"],["83464.36000000","0.00024000"],["76261.00000000","0.00000000"],["67788.32000000","0.00203000"],["67788.00000000","0.00500000"]],"a":[["84735.40000000","1.26459000"],["84739.75000000","0.01122000"],["84740.66000000","0.00007000"],["84740.67000000","0.18547000"],["84740.68000000","0.00000000"],["84742.05000000","0.01122000"],["84742.39000000","0.18001000"],["84745.64000000","0.00000000"],["84747.86000000","0.00000000"],["84835.47000000","0.00377000"]]}}
{"stream":"btcusdt@depth@100ms","data":{"e":"depthUpdate","E":1790299050714,"s":"BTCUSDT","U":100639375911,"u":100639375919,"b":[["83464.36000000","0.00024000"],["83464.35000000","0.00030000"],["76261.86000000","0.00360000"],["67788.00000000","0.00400000"]],"a":[["84775.00000000","0.70000000"],["84782.00000000","0.00000000"]]}}
{"stream":"dogeusdt@depth@100ms","data":{"e":"depthUpdate","E":1790299050774,"s":"DOGEUSDT","U":25516667612,"u":25516667614,"b":[["0.09674000","26842.00000000"]],"a":[]}}
{"stream":"btcusdt@depth@100ms","data":{"e":"depthUpdate","E":1790299050814,"s":"BTCUSDT","U":100639375920,"u":100639375931,"b":[["84735.39000000","5.09086000"],["84666.81000000","0.70271000"],["84618.57000000","0.00099000"],["84604.84000000","0.00000000"],["67788.32000000","0.00174000"],["67788.31000000","0.00000000"],["67788.00000000","0.00600000"]],"a":[["84738.81000000","0.00012000"],["84746.55000000","0.00200000"],["84765.51000000","0.01967000"]]}}
{"stream":"dogeusdt@depth@100ms","data":{"e":"depthUpdate","E":1790299050874,"s":"DOGEUSDT","U":25516667615,"u":25516667618,"b":[["0.09672000","200041.00000000"],["0.09671000","201482.00000000"]],"a":[["0.09699000","321961.00000000"]]}}
{"stream":"btcusdt@depth@100ms","data":{"e":"depthUpdate","E":1790299050914,"s":"BTCUSDT","U":100639375932,"u":100639375956,"b":[["84735.39000000","5.09086000"],["84726.74000000","0.01214000"],["84726.73000000","0.86351000"],["83464.36000000","0.00024000"],["76261.86000000","0.00360000"],["67788.00000000","0.00400000"]],"a":[["84739.75000000","0.01128000"],["84740.65000000","0.00007000"],["84740.66000000","0.18008000"],["84744.94000000","0.11432000"],["84749.06000000","0.00000000"],["84765.51000000","0.00000000"],["84767.11000000","0.00200000"],["84768.64000000","0.00000000"],["86006.44000000","0.00030000"],["87000.00000000","58.71256000"]]}}
{"stream":"dogeusdt@depth@100ms","data":{"e":"depthUpdate","E":1790299050974,"s":"DOGEUSDT","U":25516667619,"u":25516667619,"b":[],"a":[["0.09675000","63515.00000000"]]}}
{"stream":"btcusdt@depth@100ms","data":{"e":"depthUpdate","E":1790299051014,"s":"BTCUSDT","U":100639375957,"u":100639375966,"b":[["84482.99000000","0.01848000"],["84475.46000000","0.00000000"],["83464.36000000","0.00016000"],["76261.86000000","0.00345000"],["67788.32000000","0.00261000"]],"a":[["84759.18000000","0.00377000"]]}}
{"stream":"dogeusdt@depth@100ms","data":{"e":"depthUpdate","E":1790299051074,"s":"DOGEUSDT","U":25516667620,"u":25516667637,"b":[["0.09674000","92340.00000000"],["0.09673000","122830.00000000"],["0.09669000","245190.00000000"]],"a":[["0.09675000","8935.00000000"],["0.09676000","22023.00000000"],["0.09677000","92931.00000000"]]}}
{"stream":"btcusdt@depth@100ms","data":{"e":"depthUpdate","E":1790299051114,"s":"BTCUSDT","U":100639375967,"u":100639376044,"b":[["84735.39000000","5.09079000"],["84735.38000000","0.00082000"],["84735.14000000","0.00000000"],["84731.24000000","0.01135000"],["84727.69000000","0.00000000"],["84726.74000000","0.00800000"],["84726.73000000","0.86337000"],["84721.80000000","0.00013000"],["84719.82000000","0.00000000"],["83464.36000000","0.00024000"],["76261.86000000","0.00360000"],["76261.85000000","0.00000000"]],"a":[["84735.40000000","1.25720000"],["84735.41000000","0.00039000"],["84737.67000000","0.01345000"],["84738.07000000","0.01110000"],["84738.81000000","0.00006000"],["84739.44000000","0.00000000"],["84739.45000000","0.00000000"],["84739.74000000","0.00014000"],["84740.24000000","0.00000000"],["84740.65000000","0.00000000"],["84740.66000000","0.00007000"],["84740.67000000","0.16989000"],["84742.05000000","0.01122000"],["84742.39000000","0.18001000"],["84744.14000000","0.18001000"],["84744.93000000","0.00012000"],["84744.94000000","0.11432000"],["84745.66000000","0.00192000"],["84746.23000000","0.00000000"],["84746.55000000","0.00000000"],["84747.31000000","0.00200000"],["84747.86000000","0.00000000"],["84749.06000000","0.00000000"],["84749.07000000","0.00000000"],["84749.09000000","0.00200000"],["84749.11000000","0.18001000"],["84749.12000000","0.01007000"],["85150.63000000","0.00000000"]]}}
{"stream":"dogeusdt@depth@100ms","data":{"e":"depthUpdate","E":1790299051174,"s":"DOGEUSDT","U":25516667638,"u":25516667643,"b":[["0.09674000","100340.00000000"],["0.09673000","126719.00000000"],["0.09672000","196152.00000000"]],"a":[["0.09675000","6185.00000000"],["0.09676000","23523.00000000"]]}}
{"stream":"btcusdt@depth@100ms","data":{"e":"depthUpdate","E":1790299051214,"s":"BTCUSDT","U":100639376045,"u":100639376093,"b":[["84735.39000000","5.09073000"],["84734.75000000","0.00000000"],["84734.04000000","0.01120000"],["84732.74000000","0.00014000"],["84732.24000000","0.00000000"],["84727.69000000","0.00000000"],["84726.74000000","0.00614000"],["84722.45000000","0.03785000"],["84721.04000000","0.00006000"],["84708.92000000","0.00000000"],["84694.63000000","0.00000000"],["84616.76000000","0.00010000"],["83464.36000000","0.00024000"],["76261.86000000","0.00360000"],["76100.00000000","2.53320000"],["67788.32000000","0.00232000"]],"a":[["84735.40000000","1.25707000"],["84737.67000000","0.06835000"],["84738.81000000","0.00012000"],["84738.95000000","0.00014000"],["84738.96000000","0.18014000"],["84739.74000000","0.00000000"],["84740.65000000","0.00007000"],["84740.66000000","0.18008000"],["84742.39000000","0.00000000"],["84744.14000000","0.00000000"],["84744.94000000","0.18966000"],["84747.86000000","0.00000000"],["84749.11000000","0.00000000"],["84754.94000000","0.00006000"],["84759.18000000","0.00000000"],["84765.51000000","0.01967000"],["84767.11000000","0.00000000"],["84801.56000000","0.00000000"],["84835.47000000","0.00000000"]]}}
{"stream":"dogeusdt@depth@100ms","data":{"e":"depthUpdate","E":1790299051274,"s":"DOGEUSDT","U":25516667644,"u":25516667645,"b":[],"a":[["0.09675000","7435.00000000"],["0.09678000","310142.00000000"]]}}
{"stream":"btcusdt@depth@100ms","data":{"e":"depthUpdate","E":1790299051314,"s":"BTCUSDT","U":100639376094,"u":100639376139,"b":[["84735.39000000","5.09073000"],["84735.38000000","0.00082000"],["84735.13000000","0.04191000"],["84732.74000000","0.00000000"],["84726.73000000","0.86351000"]],"a":[["84735.40000000","1.25707000"],["84735.41000000","0.00039000"],["84737.67000000","0.06835000"],["84738.95000000","0.00000000"],["84738.96000000","0.00013000"],["84739.74000000","0.00014000"],["84739.75000000","0.01128000"],["84740.63000000","0.00007000"],["84740.64000000","0.18008000"],["84740.65000000","0.13176000"],["84740.66000000","0.00000000"],["84740.67000000","0.00000000"],["84742.05000000","0.01122000"],["84742.39000000","0.18001000"],["84744.14000000","0.18001000"],["84744.93000000","0.00012000"],["84744.94000000","0.11432000"],["84747.86000000","0.00000000"],["84749.11000000","0.00000000"],["84765.51000000","0.00000000"]]}}
{"stream":"dogeusdt@depth@100ms","data":{"e":"depthUpdate","E":1790299051374,"s":"DOGEUSDT","U":25516667646,"u":25516667649,"b":[],"a":[["0.09677000","61646.00000000"],["0.09678000","194224.00000000"],["0.09681000","256815.00000000"],["0.09682000","384540.00000000"]]}}
{"stream":"btcusdt@depth@100ms","data":{"e":"depthUpdate","E":1790299051414,"s":"BTCUSDT","U":100639376140,"u":100639376151,"b":[["84734.26000000","0.00000000"],["84727.99000000","0.00596000"],["84709.49000000","0.00200000"],["84598.23000000","0.01200000"],["83464.36000000","0.00024000"],["76261.86000000","0.00345000"],["67788.32000000","0.00203000"],["67788.31000000","0.00000000"]],"a":[["84831.21000000","0.00377000"],["84854.02000000","0.00010000"]]}}
{"stream":"dogeusdt@depth@100ms","data":{"e":"depthUpdate","E":1790299051474,"s":"DOGEUSDT","U":25516667650,"u":25516667650,"b":[["0.09674000","92340.00000000"]],"a":[]}}
{"stream":"btcusdt@depth@100ms","data":{"e":"depthUpdate","E":1790299051514,"s":"BTCUSDT","U":100639376152,"u":100639376165,"b":[["84735.39000000","5.01770000"],["84726.74000000","0.01014000"],["83464.36000000","0.00016000"],["76261.85000000","0.00008000"],["67788.32000000","0.00319000"]],"a":[["84735.40000000","1.25700000"],["84735.41000000","0.00032000"],["84825.55000000","1.16771000"],["84827.15000000","1.57950000"],["84829.94000000","0.00000000"]]}}
{"stream":"btcusdt@depth@100ms","data":{"e":"depthUpdate","E":1790299051614,"s":"BTCUSDT","U":100639376166,"u":100639376180,"b":[["84731.53000000","0.00200000"],["84726.93000000","0.00200000"],["83464.36000000","0.00024000"],["76261.86000000","0.00345000"],["67788.32000000","0.00290000"],["67788.00000000","0.00400000"]],"a":[["84735.40000000","1.25713000"],["84745.59000000","0.00188000"],["84745.66000000","0.00000000"],["84980.61000000","0.00000000"],["84981.75000000","0.00000000"],["85038.48000000","0.01411000"],["85045.40000000","0.01411000"]]}}
{"stream":"btcusdt@depth@100ms","data":{"e":"depthUpdate","E":1790299051714,"s":"BTCUSDT","U":100639376181,"u":100639376197,"b":[["84735.39000000","5.01777000"],["84726.00000000","0.00013000"],["84725.19000000","0.00013000"],["84724.38000000","0.00013000"],["84723.57000000","0.00013000"],["84716.28000000","0.00000000"],["84715.47000000","0.00000000"],["84714.66000000","0.00000000"],["84713.85000000","0.00000000"],["84690.47000000","0.00000000"],["84690.37000000","0.00354000"],["83464.36000000","0.00024000"],["83464.35000000","0.00030000"]],"a":[["84743.88000000","0.00068000"],["84928.20000000","0.00000000"],["84966.54000000","0.01412000"]]}}
{"stream":"btcusdt@depth@100ms","data":{"e":"depthUpdate","E":1790299051814,"s":"BTCUSDT","U":100639376198,"u":100639376233,"b":[["84732.48000000","0.00013000"],["84731.67000000","0.00013000"],["84731.53000000","0.00000000"],["84730.86000000","0.00013000"],["84730.05000000","0.00603000"],["84729.24000000","0.00013000"],["84728.43000000","0.00013000"],["84727.62000000","0.00013000"],["84726.81000000","0.00013000"],["84726.74000000","0.00600000"],["84726.73000000","0.86337000"],["84724.38000000","0.00000000"],["84723.57000000","0.00000000"],["84721.14000000","0.00000000"],["84720.33000000","0.00000000"],["84719.52000000","0.00000000"],["84718.71000000","0.00000000"],["84717.90000000","0.00000000"],["84717.09000000","0.00000000"],["76261.86000000","0.00345000"],["76261.00000000","0.00000000"],["67788.32000000","0.00261000"],["67788.31000000","0.00020000"]],"a":[["84742.39000000","0.00000000"],["84749.11000000","0.00200000"],["84749.12000000","0.00807000"],["84754.93000000","0.00389000"],["84765.51000000","0.00000000"],["84767.09000000","0.00200000"]]}}
{"stream":"btcusdt@depth@100ms","data":{"e":"depthUpdate","E":1790299051914,"s":"BTCUSDT","U":100639376234,"u":100639376257,"b":[["84735.39000000","5.01770000"],["84726.82000000","0.00400000"],["84726.74000000","0.00614000"],["84726.73000000","0.86351000"],["83464.36000000","0.00024000"],["76261.86000000","0.00330000"],["67788.31000000","0.00000000"],["67788.00000000","0.00300000"]],"a":[["84737.67000000","0.06821000"],["84737.68000000","0.00012000"],["84738.96000000","0.16767000"],["84740.63000000","0.00014000"],["84742.05000000","0.01116000"],["84742.39000000","0.18001000"],["84744.94000000","0.19512000"],["84747.86000000","0.18001000"],["84749.10000000","0.18001000"],["86006.44000000","0.00030000"]]}}
{"stream":"btcusdt@depth@100ms","data":{"e":"depthUpdate","E":1790299052014,"s":"BTCUSDT","U":100639376258,"u":100639376278,"b":[["83464.36000000","0.00016000"],["76261.86000000","0.00345000"],["67788.32000000","0.00232000"]],"a":[["84735.40000000","1.25692000"],["84735.41000000","0.00018000"],["84737.67000000","0.10223000"],["84738.95000000","0.00014000"],["84739.74000000","0.00000000"],["84742.05000000","0.01122000"],["84744.94000000","0.11432000"],["84747.86000000","0.00000000"],["84749.10000000","0.17150000"],["84797.31000000","0.00377000"]]}}
{"stream":"btcusdt@depth@100ms","data":{"e":"depthUpdate","E":1790299052114,"s":"BTCUSDT","U":100639376279,"u":100639376295,"b":[["84735.39000000","5.01777000"],["84735.14000000","0.00328000"],["84731.40000000","0.00200000"],["84727.99000000","0.00590000"],["84726.73000000","0.86337000"],["83464.36000000","0.00024000"],["76261.86000000","0.00345000"]],"a":[["84735.40000000","1.25762000"],["84745.58000000","0.00192000"],["84745.59000000","0.00000000"],["84868.46000000","0.01868000"],["84879.85000000","0.00000000"],["85925.41000000","0.00029000"]]}}
{"stream":"dogeusdt@depth@100ms","data":{"e":"depthUpdate","E":1790299052174,"s":"DOGEUSDT","U":25516667651,"u":25516667654,"b":[["0.09674000","100340.00000000"]],"a":[["0.09675000","6185.00000000"],["0.09677000","61668.00000000"]]}}
{"stream":"btcusdt@depth@100ms","data":{"e":"depthUpdate","E":1790299052214,"s":"BTCUSDT","U":100639376296,"u":100639376308,"b":[["84735.14000000","0.00000000"],["84721.04000000","0.00006000"],["83464.36000000","0.00024000"],["67788.32000000","0.00203000"],["67788.00000000","0.00300000"]],"a":[["84735.40000000","1.25762000"],["84745.58000000","0.00000000"],["84745.83000000","0.00590000"],["84754.94000000","0.00006000"]]}}
{"stream":"dogeusdt@depth@100ms","data":{"e":"depthUpdate","E":1790299052274,"s":"DOGEUSDT","U":25516667655,"u":25516667657,"b":[["0.09673000","122830.00000000"],["0.09671000","182037.00000000"]],"a":[]}}
{"stream":"btcusdt@depth@100ms","data":{"e":"depthUpdate","E":1790299052314,"s":"BTCUSDT","U":100639376309,"u":100639376316,"b":[["76261.86000000","0.00345000"]],"a":[["84745.58000000","0.00192000"],["84749.09000000","0.00600000"],["84765.51000000","0.01967000"],["84923.46000000","0.01848000"],["84974.60000000","0.00000000"]]}}
{"stream":"btcusdt@depth@100ms","data":{"e":"depthUpdate","E":1790299052414,"s":"BTCUSDT","U":100639376317,"u":100639376322,"b":[["83464.36000000","0.00024000"],["67788.32000000","0.00174000"],["67788.31000000","0.00000000"]],"a":[["84765.51000000","0.00000000"]]}}
{"stream":"dogeusdt@depth@100ms","data":{"e":"depthUpdate","E":1790299052474,"s":"DOGEUSDT","U":25516667658,"u":25516667663,"b":[["0.09671000","185926.00000000"],["0.09670000","216717.00000000"]],"a":[["0.09675000","26047.00000000"]]}}
{"stream":"btcusdt@depth@100ms","data":{"e":"depthUpdate","E":1790299052514,"s":"BTCUSDT","U":100639376323,"u":100639376331,"b":[["84735.39000000","5.01767000"],["83464.36000000","0.00016000"],["76261.86000000","0.00345000"],["67788.32000000","0.00290000"]],"a":[["84746.78000000","0.00200000"]]}}
{"stream":"dogeusdt@depth@100ms","data":{"e":"depthUpdate","E":1790299052574,"s":"DOGEUSDT","U":25516667664,"u":25516667665,"b":[["0.09674000","92340.00000000"]],"a":[["0.09936000","7837.00000000"]]}}
{"stream":"btcusdt@depth@100ms","data":{"e":"depthUpdate","E":1790299052614,"s":"BTCUSDT","U":100639376332,"u":100639376338,"b":[["83464.36000000","0.00024000"],["76261.86000000","0.00330000"],["67788.32000000","0.00261000"]],"a":[["84735.40000000","1.25953000"],["84745.58000000","0.00000000"],["84923.46000000","0.00000000"],["84947.57000000","0.01848000"]]}}
{"stream":"btcusdt@depth@100ms","data":{"e":"depthUpdate","E":1790299052714,"s":"BTCUSDT","U":100639376339,"u":100639376345,"b":[["83464.36000000","0.00024000"],["83464.35000000","0.00030000"],["76261.86000000","0.00345000"]],"a":[["84947.57000000","0.00000000"],["84975.60000000","0.01848000"]]}}
{"stream":"btcusdt@depth@100ms","data":{"e":"depthUpdate","E":1790299052814,"s":"BTCUSDT","U":100639376346,"u":100639376348,"b":[["76261.86000000","0.00345000"],["67788.32000000","0.00232000"]],"a":[]}}
{"stream":"dogeusdt@depth@100ms","data":{"e":"depthUpdate","E":1790299052874,"s":"DOGEUSDT","U":25516667666,"u":25516667669,"b":[["0.09671000","182037.00000000"]],"a":[["0.09675000","46675.00000000"],["0.09677000","81238.00000000"],["0.09678000","175438.00000000"]]}}
{"stream":"btcusdt@depth@100ms","data":{"e":"depthUpdate","E":1790299052914,"s":"BTCUSDT","U":100639376349,"u":100639376356,"b":[["83464.36000000","0.00024000"],["76261.00000000","0.00000000"],["67788.31000000","0.00000000"]],"a":[["86006.44000000","0.00030000"]]}}
{"stream":"btcusdt@depth@100ms","data":{"e":"depthUpdate","E":1790299053014,"s":"BTCUSDT","U":100639376357,"u":100639376372,"b":[["84734.91000000","0.00013000"],["84734.10000000","0.00013000"],["84733.29000000","0.00013000"],["84726.81000000","0.00000000"],["84726.74000000","0.00600000"],["84726.00000000","0.00000000"],["84725.19000000","0.00000000"],["83464.36000000","0.00016000"],["76261.86000000","0.00345000"],["67788.32000000","0.00319000"]],"a":[]}}
{"stream":"dogeusdt@depth@100ms","data":{"e":"depthUpdate","E":1790299053074,"s":"DOGEUSDT","U":25516667670,"u":25516667680,"b":[["0.09650000","68355.00000000"]],"a":[["0.09675000","26047.00000000"],["0.09677000","61668.00000000"],["0.09679000","139750.00000000"],["0.09680000","155976.00000000"]]}}
{"stream":"btcusdt@depth@100ms","data":{"e":"depthUpdate","E":1790299053114,"s":"BTCUSDT","U":100639376373,"u":100639376385,"b":[["84735.14000000","0.00328000"],["84734.26000000","0.00007000"],["83464.36000000","0.00024000"]],"a":[["84746.53000000","0.00200000"],["84746.78000000","0.00000000"],["84749.09000000","0.00800000"],["84749.11000000","0.00000000"],["84765.51000000","0.00000000"]]}}
{"stream":"dogeusdt@depth@100ms","data":{"e":"depthUpdate","E":1790299053174,"s":"DOGEUSDT","U":25516667681,"u":25516667683,"b":[["0.09674000","100340.00000000"],["0.09671000","185926.00000000"]],"a":[["0.09675000","7435.00000000"]]}}
{"stream":"btcusdt@depth@100ms","data":{"e":"depthUpdate","E":1790299053214,"s":"BTCUSDT","U":100639376386,"u":100639376393,"b":[["84721.04000000","0.00006000"],["83464.36000000","0.00024000"],["76261.86000000","0.00345000"],["67788.32000000","0.00290000"]],"a":[["84754.94000000","0.00006000"]]}}
{"stream":"dogeusdt@depth@100ms","data":{"e":"depthUpdate","E":1790299053274,"s":"DOGEUSDT","U":25516667684,"u":25516667684,"b":[],"a":[["0.09678000","193730.00000000"]]}}
{"stream":"btcusdt@depth@100ms","data":{"e":"depthUpdate","E":1790299053314,"s":"BTCUSDT","U":100639376394,"u":100639376400,"b":[["84735.39000000","4.83192000"],["84735.38000000","0.00089000"],["76261.86000000","0.00330000"]],"a":[["84735.40000000","1.15520000"],["84737.18000000","0.18001000"]]}}
{"stream":"dogeusdt@depth@100ms","data":{"e":"depthUpdate","E":1790299053374,"s":"DOGEUSDT","U":25516667685,"u":25516667688,"b":[["0.09674000","92340.00000000"]],"a":[["0.09675000","28063.00000000"],["0.09677000","80532.00000000"],["0.09678000","175438.00000000"]]}}
{"stream":"btcusdt@depth@100ms","data":{"e":"depthUpdate","E":1790299053414,"s":"BTCUSDT","U":100639376401,"u":100639376463,"b":[["84735.39000000","4.83185000"],["84731.40000000","0.00000000"],["84709.49000000","0.00000000"],["84708.93000000","0.00200000"],["83464.36000000","0.00024000"],["76261.86000000","0.00345000"],["67788.32000000","0.00261000"],["67788.31000000","0.00000000"]],"a":[["84735.40000000","1.52502000"],["84735.41000000","0.00032000"],["84737.16000000","0.00014000"],["84737.17000000","0.09392000"],["84737.18000000","0.00000000"],["84737.66000000","0.00000000"],["84737.67000000","0.00000000"],["84738.06000000","0.00000000"],["84738.07000000","0.01116000"],["84738.31000000","0.00014000"],["84738.32000000","0.10845000"],["84738.34000000","0.00190000"],["84738.95000000","0.00000000"],["84738.96000000","0.00013000"],["84740.64000000","0.18015000"],["84742.05000000","0.01116000"],["84742.39000000","0.18008000"],["84744.10000000","0.00283000"],["84744.14000000","0.19416000"],["84744.94000000","0.18871000"],["84745.68000000","0.00000000"],["84745.72000000","0.00000000"],["84746.53000000","0.00000000"],["84747.86000000","0.18001000"],["84749.08000000","0.00200000"],["84749.09000000","0.00200000"]]}}
{"stream":"dogeusdt@depth@100ms","data":{"e":"depthUpdate","E":1790299053474,"s":"DOGEUSDT","U":25516667689,"u":25516667694,"b":[["0.09674000","71098.00000000"],["0.09671000","204538.00000000"]],"a":[["0.09676000","51345.00000000"],["0.09677000","80510.00000000"]]}}
{"stream":"btcusdt@depth@100ms","data":{"e":"depthUpdate","E":1790299053514,"s":"BTCUSDT","U":100639376464,"u":100639376587,"b":[["84735.39000000","3.00026000"],["84735.38000000","0.00130000"],["84734.78000000","0.00006000"],["84733.38000000","0.02000000"],["84732.74000000","0.34492000"],["84732.28000000","0.00000000"],["84731.30000000","0.00006000"],["84731.05000000","0.00006000"],["84730.94000000","0.00000000"],["84730.90000000","0.00000000"],["84728.92000000","0.00000000"],["84728.50000000","0.00000000"],["84728.47000000","0.01141000"],["84727.70000000","0.02000000"],["84727.65000000","0.00000000"],["84727.55000000","0.00200000"],["84726.82000000","0.00000000"],["84726.74000000","0.00600000"],["84726.72000000","0.88526000"],["84726.71000000","0.01124000"],["84726.70000000","0.00000000"],["84726.56000000","0.00006000"],["84726.50000000","0.04000000"],["84726.10000000","0.08000000"],["84725.47000000","0.11839000"],["84725.45000000","0.00000000"],["84721.80000000","0.00000000"],["84719.82000000","0.00013000"],["84718.34000000","0.00000000"],["84708.93000000","0.00000000"],["84708.73000000","0.11805000"],["84598.23000000","0.00000000"],["84223.55000000","0.00017000"],["83464.36000000","0.00016000"],["76261.86000000","0.00345000"]],"a":[["84735.40000000","2.00837000"],["84735.41000000","0.00018000"],["84737.16000000","0.16774000"],["84738.06000000","0.00014000"],["84738.32000000","0.00000000"],["84738.34000000","0.00000000"],["84738.96000000","0.16710000"],["84740.63000000","0.18001000"],["84740.64000000","0.00000000"],["84741.60000000","0.03540000"],["84742.05000000","0.01122000"],["84742.38000000","0.18001000"],["84742.39000000","0.00000000"],["84743.00000000","0.00590000"],["84743.19000000","0.00163000"],["84744.13000000","0.18001000"],["84744.14000000","0.01415000"],["84744.15000000","0.00000000"],["84744.58000000","0.00000000"],["84744.93000000","0.00012000"],["84744.94000000","0.11432000"],["84747.84000000","0.00000000"],["84747.86000000","0.00000000"],["84748.56000000","0.00000000"],["84748.61000000","0.35516000"],["84749.10000000","0.00000000"],["84749.11000000","0.18001000"],["84753.47000000","0.02994000"],["84779.11000000","0.00000000"]]}}
{"stream":"btcusdt@depth@100ms","data":{"e":"depthUpdate","E":1790299053614,"s":"BTCUSDT","U":100639376588,"u":100639376794,"b":[["84735.39000000","2.99618000"],["84735.38000000","0.00130000"],["84734.78000000","0.00012000"],["84734.03000000","0.01693000"],["84733.38000000","0.02006000"],["84732.76000000","0.00236000"],["84732.75000000","0.00014000"],["84732.74000000","0.34493000"],["84732.70000000","0.00006000"],["84732.67000000","0.02036000"],["84732.55000000","0.00000000"],["84732.19000000","0.00000000"],["84732.16000000","0.00000000"],["84731.59000000","0.01109000"],["84731.35000000","0.00000000"],["84731.33000000","0.02928000"],["84731.31000000","0.00000000"],["84731.24000000","0.01141000"],["84730.11000000","0.00236000"],["84730.05000000","0.00013000"],["84729.54000000","0.00236000"],["84729.46000000","0.03540000"],["84728.47000000","0.01135000"],["84728.00000000","0.00590000"],["84727.99000000","0.00000000"],["84727.70000000","0.00000000"],["84727.55000000","0.00000000"],["84727.02000000","0.00024000"],["84726.93000000","0.00000000"],["84726.75000000","0.00000000"],["84726.74000000","0.00000000"],["84726.73000000","0.47131000"],["84726.60000000","0.03000000"],["84726.52000000","0.00000000"],["84726.50000000","0.00000000"],["84726.37000000","0.00200000"],["84726.10000000","0.00000000"],["84725.81000000","0.00590000"],["84725.12000000","0.00000000"],["84724.90000000","0.04000000"],["84724.50000000","0.00047000"],["84724.46000000","0.00000000"],["84724.25000000","0.00200000"],["84724.20000000","0.08000000"],["84723.19000000","0.00600000"],["84719.82000000","0.00000000"],["84710.42000000","0.54678000"],["84708.73000000","0.00000000"],["84694.79000000","0.00000000"],["84694.00000000","2.15755000"],["84690.45000000","0.00000000"],["84690.12000000","0.02343000"],["84651.40000000","0.00000000"],["84648.61000000","1.09604000"],["83464.36000000","0.00024000"],["76261.85000000","0.00000000"],["76261.84000000","0.00008000"],["67788.32000000","0.00232000"]],"a":[["84735.40000000","2.11853000"],["84737.14000000","0.00000000"],["84737.15000000","0.00000000"],["84737.16000000","0.00000000"],["84737.17000000","0.00000000"],["84738.06000000","0.00014000"],["84738.07000000","0.01110000"],["84738.31000000","0.00000000"],["84738.95000000","0.00000000"],["84738.96000000","0.00013000"],["84739.74000000","0.00014000"],["84739.75000000","0.01134000"],["84740.61000000","0.00014000"],["84740.62000000","0.05511000"],["84740.63000000","0.18001000"],["84740.64000000","0.00414000"],["84740.65000000","0.17148000"],["84741.59000000","0.00000000"],["84742.05000000","0.01122000"],["84742.06000000","0.00000000"],["84742.38000000","0.00000000"],["84742.39000000","0.00000000"],["84742.90000000","0.00678000"],["84743.85000000","0.00590000"],["84744.13000000","0.16227000"],["84744.93000000","0.00012000"],["84744.94000000","0.24001000"],["84746.48000000","0.00236000"],["84746.99000000","0.00000000"],["84747.43000000","0.00000000"],["84747.44000000","0.35516000"],["84747.86000000","0.00000000"],["84748.60000000","0.00200000"],["84748.61000000","0.00000000"],["84749.11000000","0.00000000"],["84749.12000000","0.00607000"],["84753.23000000","0.00000000"],["84756.13000000","0.35516000"],["84757.17000000","0.11799000"],["84757.18000000","0.00000000"],["84764.57000000","0.00000000"],["84767.09000000","0.00000000"],["84774.56000000","0.00000000"],["84774.86000000","0.02292000"],["84779.11000000","0.00006000"],["84779.39000000","0.00000000"]]}}
{"stream":"dogeusdt@depth@100ms","data":{"e":"depthUpdate","E":1790299053674,"s":"DOGEUSDT","U":25516667695,"u":25516667695,"b":[["0.09673000","141390.00000000"]],"a":[]}}
{"stream":"btcusdt@depth@100ms","data":{"e":"depthUpdate","E":1790299053714,"s":"BTCUSDT","U":100639376795,"u":100639376824,"b":[["84735.39000000","2.99195000"],["84732.71000000","0.00012000"],["83464.36000000","0.00024000"],["83464.35000000","0.00030000"],["76261.86000000","0.00345000"]],"a":[["84735.40000000","2.08720000"],["84739.75000000","0.01122000"],["84740.61000000","0.00000000"],["84740.62000000","0.00000000"],["84740.63000000","0.00000000"],["84741.59000000","0.00014000"],["84742.05000000","0.01122000"],["84742.15000000","0.00596000"],["84742.38000000","0.00007000"],["84742.39000000","0.18001000"],["84745.83000000","0.00000000"],["84766.91000000","0.00118000"]]}}
{"stream":"btcusdt@depth@100ms","data":{"e":"depthUpdate","E":1790299053814,"s":"BTCUSDT","U":100639376825,"u":100639376853,"b":[["84728.52000000","0.02994000"],["84706.62000000","0.00200000"],["84690.37000000","0.00000000"],["84686.47000000","0.00354000"],["84615.70000000","0.00000000"],["83842.83000000","0.00614000"],["67788.32000000","0.00203000"],["67788.00000000","0.00500000"]],"a":[["84739.75000000","0.01134000"],["84740.61000000","0.00014000"],["84740.62000000","0.05511000"],["84740.63000000","0.18001000"],["84740.65000000","0.12935000"],["84741.59000000","0.00000000"],["84742.15000000","0.00590000"],["84742.38000000","0.00000000"],["84742.39000000","0.00000000"],["84744.13000000","0.18001000"],["84779.11000000","0.00000000"],["84873.71000000","0.00000000"]]}}
{"stream":"btcusdt@depth@100ms","data":{"e":"depthUpdate","E":1790299053914,"s":"BTCUSDT","U":100639376854,"u":100639376866,"b":[["84619.95000000","0.03659000"],["84526.01000000","0.00000000"],["84524.01000000","0.00734000"],["83464.36000000","0.00024000"],["76261.86000000","0.00345000"],["67788.31000000","0.00000000"],["67788.00000000","0.00300000"]],"a":[["84874.20000000","0.06821000"],["86006.44000000","0.00030000"]]}}
{"stream":"btcusdt@depth@100ms","data":{"e":"depthUpdate","E":1790299054014,"s":"BTCUSDT","U":100639376867,"u":100639376878,"b":[["84728.06000000","0.00200000"],["84723.19000000","0.01000000"],["84710.43000000","0.88514000"],["83464.36000000","0.00016000"],["76261.86000000","0.00330000"],["67788.32000000","0.00290000"],["67788.00000000","0.00400000"]],"a":[]}}
{"stream":"btcusdt@depth@100ms","data":{"e":"depthUpdate","E":1790299054114,"s":"BTCUSDT","U":100639376879,"u":100639376905,"b":[["84735.39000000","2.99188000"],["84735.38000000","0.00130000"],["84735.14000000","0.00000000"],["84723.20000000","0.35516000"],["83464.36000000","0.00024000"],["76261.86000000","0.00345000"],["76261.84000000","0.00000000"],["76261.00000000","0.00000000"],["67788.00000000","0.00300000"]],"a":[["84735.40000000","2.07539000"],["84739.75000000","0.01122000"],["84740.61000000","0.00000000"],["84740.62000000","0.00000000"],["84740.63000000","0.00000000"],["84741.59000000","0.00014000"],["84742.15000000","0.00596000"],["84742.38000000","0.00007000"],["84742.39000000","0.17366000"],["84984.99000000","0.00017000"]]}}
{"stream":"btcusdt@depth@100ms","data":{"e":"depthUpdate","E":1790299054214,"s":"BTCUSDT","U":100639376906,"u":100639376913,"b":[["84735.39000000","2.99430000"],["84721.04000000","0.00000000"],["83464.36000000","0.00024000"],["76261.86000000","0.00345000"],["67788.32000000","0.00261000"]],"a":[["84754.94000000","0.00000000"],["84761.61000000","0.01967000"]]}}
{"stream":"dogeusdt@depth@100ms","data":{"e":"depthUpdate","E":1790299054274,"s":"DOGEUSDT","U":25516667696,"u":25516667698,"b":[["0.09674000","71088.00000000"]],"a":[["0.09675000","47137.00000000"],["0.09676000","51357.00000000"]]}}
{"stream":"btcusdt@depth@100ms","data":{"e":"depthUpdate","E":1790299054314,"s":"BTCUSDT","U":100639376914,"u":100639376920,"b":[["84721.04000000","0.00006000"],["84706.17000000","0.57893000"],["67788.00000000","0.00300000"]],"a":[["84754.94000000","0.00006000"],["84761.61000000","0.00000000"],["84764.28000000","0.00200000"]]}}
{"stream":"dogeusdt@depth@100ms","data":{"e":"depthUpdate","E":1790299054374,"s":"DOGEUSDT","U":25516667699,"u":25516667706,"b":[["0.09674000","35641.00000000"],["0.09673000","133390.00000000"],["0.09669000","253190.00000000"]],"a":[["0.09675000","50129.00000000"],["0.09676000","49857.00000000"],["0.09917000","1522.00000000"]]}}
{"stream":"btcusdt@depth@100ms","data":{"e":"depthUpdate","E":1790299054414,"s":"BTCUSDT","U":100639376921,"u":100639376948,"b":[["83464.36000000","0.00024000"],["77944.04000000","0.00013000"],["76261.86000000","0.00345000"],["67788.32000000","0.00232000"],["67788.31000000","0.00020000"]],"a":[["84739.75000000","0.01128000"],["84740.19000000","0.00602000"],["84740.61000000","0.00014000"],["84740.62000000","0.05511000"],["84740.63000000","0.18001000"],["84741.59000000","0.00000000"],["84742.05000000","0.01116000"],["84742.15000000","0.00000000"],["84742.38000000","0.00000000"],["84742.39000000","0.00000000"],["84743.33000000","0.00200000"],["84747.43000000","0.00400000"]]}}
{"stream":"btcusdt@depth@100ms","data":{"e":"depthUpdate","E":1790299054514,"s":"BTCUSDT","U":100639376949,"u":100639376981,"b":[["84735.39000000","2.99414000"],["83464.36000000","0.00016000"],["76261.85000000","0.00008000"],["67788.31000000","0.00000000"]],"a":[["84740.19000000","0.00590000"],["84740.59000000","0.00000000"],["84740.60000000","0.00000000"],["84740.61000000","0.00000000"],["84740.62000000","0.00000000"],["84740.63000000","0.00000000"],["84741.59000000","0.00014000"],["84742.39000000","0.16352000"],["87467.87000000","0.00873000"]]}}
{"stream":"dogeusdt@depth@100ms","data":{"e":"depthUpdate","E":1790299054574,"s":"DOGEUSDT","U":25516667707,"u":25516667711,"b":[["0.09674000","26865.00000000"],["0.09673000","73689.00000000"],["0.09672000","47001.00000000"]],"a":[]}}
{"stream":"btcusdt@depth@100ms","data":{"e":"depthUpdate","E":1790299054614,"s":"BTCUSDT","U":100639376982,"u":100639376993,"b":[["84717.34000000","0.11803000"],["83464.36000000","0.00024000"],["76261.86000000","0.00330000"],["67788.32000000","0.00203000"],["67788.00000000","0.00300000"]],"a":[["84740.63000000","0.18001000"],["84742.05000000","0.01122000"],["84742.38000000","0.00007000"],["84747.43000000","0.00000000"],["87467.87000000","0.01746000"]]}}
{"stream":"btcusdt@depth@100ms","data":{"e":"depthUpdate","E":1790299054714,"s":"BTCUSDT","U":100639376994,"u":100639377015,"b":[["83464.36000000","0.00024000"],["83464.35000000","0.00030000"],["76261.86000000","0.00315000"]],"a":[["84740.19000000","0.00602000"],["84740.61000000","0.00014000"],["84740.62000000","0.05511000"],["84740.65000000","0.12358000"],["84741.59000000","0.00000000"],["84742.05000000","0.01116000"],["84742.38000000","0.00000000"],["84742.39000000","0.00000000"],["84744.13000000","0.16465000"]]}}
{"stream":"btcusdt@depth@100ms","data":{"e":"depthUpdate","E":1790299054814,"s":"BTCUSDT","U":100639377016,"u":100639377033,"b":[["84735.39000000","2.99414000"],["84732.74000000","0.34492000"],["84729.70000000","0.00200000"],["84728.06000000","0.00000000"],["84723.21000000","0.00200000"],["84723.19000000","0.00400000"],["76261.86000000","0.00330000"],["67788.32000000","0.00174000"]],"a":[["84735.40000000","2.14857000"],["84737.55000000","0.01115000"],["84742.39000000","0.18001000"],["84747.43000000","0.00400000"]]}}
{"stream":"dogeusdt@depth@100ms","data":{"e":"depthUpdate","E":1790299054874,"s":"DOGEUSDT","U":25516667712,"u":25516667763,"b":[["0.09674000","664.00000000"],["0.09673000","25755.00000000"],["0.09672000","67900.00000000"],["0.09671000","184644.00000000"],["0.09668000","141990.00000000"],["0.09664000","65189.00000000"],["0.09663000","240050.00000000"]],"a":[["0.09675000","70758.00000000"],["0.09676000","63488.00000000"],["0.09677000","91181.00000000"],["0.09678000","178351.00000000"],["0.09679000","139802.00000000"],["0.09680000","155872.00000000"],["0.09684000","172997.00000000"]]}}
{"stream":"btcusdt@depth@100ms","data":{"e":"depthUpdate","E":1790299054914,"s":"BTCUSDT","U":100639377034,"u":100639377058,"b":[["84729.70000000","0.00000000"],["83464.36000000","0.00024000"],["77944.04000000","0.00000000"],["76261.86000000","0.00330000"],["67788.31000000","0.00000000"]],"a":[["84735.40000000","2.14863000"],["84737.54000000","0.00014000"],["84740.64000000","0.00400000"],["84740.65000000","0.12833000"],["84742.05000000","0.01116000"],["84742.39000000","0.00000000"],["84744.13000000","0.18001000"],["86006.44000000","0.00000000"]]}}
{"stream":"dogeusdt@depth@100ms","data":{"e":"depthUpdate","E":1790299054974,"s":"DOGEUSDT","U":25516667764,"u":25516667785,"b":[["0.09673000","22023.00000000"],["0.09672000","51001.00000000"],["0.09671000","180755.00000000"],["0.09654000","337829.00000000"],["0.09645000","51773.00000000"]],"a":[["0.09675000","78758.00000000"],["0.09676000","89024.00000000"],["0.09677000","150842.00000000"],["0.09678000","193351.00000000"],["0.09679000","121357.00000000"],["0.09680000","147872.00000000"],["0.09681000","248815.00000000"],["0.09682000","376540.00000000"]]}}
{"stream":"btcusdt@depth@100ms","data":{"e":"depthUpdate","E":1790299055014,"s":"BTCUSDT","U":100639377059,"u":100639377090,"b":[["84710.44000000","0.82609000"],["84710.42000000","0.00000000"],["83464.36000000","0.00016000"],["67788.32000000","0.00261000"]],"a":[["84735.40000000","2.14869000"],["84737.53000000","0.00014000"],["84737.54000000","0.01369000"],["84740.19000000","0.00590000"],["84740.61000000","0.00000000"],["84740.62000000","0.00000000"],["84740.63000000","0.00000000"],["84740.64000000","0.00407000"],["84742.05000000","0.01122000"],["84742.39000000","0.18001000"],["84770.42000000","0.74343000"],["84773.00000000","0.70000000"],["84775.00000000","0.00000000"],["86006.44000000","0.00030000"]]}}
{"stream":"dogeusdt@depth@100ms","data":{"e":"depthUpdate","E":1790299055074,"s":"DOGEUSDT","U":25516667786,"u":25516667787,"b":[["0.09673000","22034.00000000"],["0.09671000","184643.00000000"]],"a":[]}}
{"stream":"btcusdt@depth@100ms","data":{"e":"depthUpdate","E":1790299055114,"s":"BTCUSDT","U":100639377091,"u":100639377134,"b":[["84735.39000000","2.99179000"],["84735.38000000","0.00137000"],["84735.14000000","0.00328000"],["84734.03000000","0.01687000"],["84733.38000000","0.00006000"],["84731.24000000","0.01147000"],["84731.18000000","0.02000000"],["84729.54000000","0.00000000"],["84727.37000000","0.00236000"],["84723.21000000","0.00000000"],["84723.19000000","0.00200000"],["84722.55000000","0.00400000"],["84709.87000000","0.76732000"],["83464.36000000","0.00024000"],["76261.86000000","0.00330000"]],"a":[["84737.54000000","0.11273000"],["84738.95000000","0.00014000"],["84738.96000000","0.00013000"],["84739.74000000","0.00000000"],["84740.19000000","0.00596000"],["84740.62000000","0.00007000"],["84740.63000000","0.18001000"],["84742.05000000","0.01116000"],["84742.39000000","0.00000000"],["84743.12000000","0.02000000"],["84743.33000000","0.00000000"],["84744.31000000","0.01330000"],["84744.93000000","0.00012000"],["84746.48000000","0.00000000"],["84747.43000000","0.00000000"],["84751.63000000","0.00000000"]]}}
{"stream":"dogeusdt@depth@100ms","data":{"e":"depthUpdate","E":1790299055174,"s":"DOGEUSDT","U":25516667788,"u":25516667801,"b":[["0.09674000","12127.00000000"],["0.09673000","29274.00000000"],["0.09672000","82042.00000000"],["0.09671000","184643.00000000"],["0.09670000","215646.00000000"],["0.09654000","329097.00000000"]],"a":[["0.09675000","86599.00000000"]]}}
{"stream":"btcusdt@depth@100ms","data":{"e":"depthUpdate","E":1790299055214,"s":"BTCUSDT","U":100639377135,"u":100639377176,"b":[["84735.39000000","2.99179000"],["84735.38000000","0.00137000"],["84730.04000000","0.00000000"],["84723.21000000","0.00400000"],["84696.12000000","0.00400000"],["83464.36000000","0.00024000"],["67788.32000000","0.00232000"]],"a":[["84737.54000000","0.06736000"],["84738.36000000","0.00000000"],["84738.52000000","0.00400000"],["84738.95000000","0.00000000"],["84738.96000000","0.00013000"],["84739.74000000","0.00014000"],["84740.19000000","0.00006000"],["84740.65000000","0.18266000"],["84742.05000000","0.01116000"],["84742.39000000","0.18001000"],["84772.44000000","0.00000000"]]}}
{"stream":"dogeusdt@depth@100ms","data":{"e":"depthUpdate","E":1790299055274,"s":"DOGEUSDT","U":25516667802,"u":25516667803,"b":[["0.09673000","34062.00000000"],["0.09671000","179452.00000000"]],"a":[]}}
{"stream":"btcusdt@depth@100ms","data":{"e":"depthUpdate","E":1790299055314,"s":"BTCUSDT","U":100639377177,"u":100639377193,"b":[["84727.95000000","0.00200000"],["84723.21000000","0.00000000"],["84721.04000000","0.00006000"],["76261.86000000","0.00330000"],["76261.00000000","0.00000000"]],"a":[["84737.62000000","0.00007000"],["84738.07000000","0.01116000"],["84739.36000000","0.00590000"],["84739.75000000","0.01122000"],["84742.38000000","0.00000000"],["84742.39000000","0.00000000"],["84754.94000000","0.00006000"]]}}
{"stream":"dogeusdt@depth@100ms","data":{"e":"depthUpdate","E":1790299055374,"s":"DOGEUSDT","U":25516667804,"u":25516667804,"b":[["0.09655000","590638.00000000"]],"a":[]}}
{"stream":"btcusdt@depth@100ms","data":{"e":"depthUpdate","E":1790299055414,"s":"BTCUSDT","U":100639377194,"u":100639377277,"b":[["84735.39000000","1.73042000"],["84735.37000000","1.02690000"],["84734.78000000","0.00006000"],["84732.76000000","0.00000000"],["84732.74000000","0.00000000"],["84730.12000000","0.00236000"],["84730.11000000","0.00000000"],["84728.65000000","0.00236000"],["84728.00000000","0.00000000"],["84727.95000000","0.00000000"],["84727.37000000","0.00000000"],["84726.80000000","0.01000000"],["84726.74000000","0.34492000"],["84726.60000000","0.00000000"],["84726.44000000","0.00236000"],["84725.70000000","0.02000000"],["84725.48000000","0.00590000"],["84724.25000000","0.00000000"],["84724.20000000","0.00000000"],["84723.21000000","0.00200000"],["84723.20000000","0.43516000"],["84723.19000000","0.00000000"],["84722.55000000","0.00000000"],["84721.80000000","0.00200000"],["84720.63000000","0.00200000"],["84717.34000000","0.00000000"],["84714.94000000","0.00000000"],["84709.55000000","0.29511000"],["84706.62000000","0.00000000"],["84704.73000000","0.00200000"],["84598.23000000","0.00000000"],["83464.36000000","0.00024000"],["76261.86000000","0.00315000"],["67788.32000000","0.00203000"],["67788.00000000","0.00400000"]],"a":[["84735.40000000","2.14882000"],["84737.12000000","0.00316000"],["84737.16000000","0.01580000"],["84737.18000000","0.00000000"],["84737.54000000","0.06253000"],["84738.47000000","0.00000000"],["84738.96000000","0.00013000"],["84739.75000000","0.01128000"],["84740.19000000","0.00000000"],["84740.62000000","0.00007000"],["84740.63000000","0.16618000"],["84740.64000000","0.00400000"],["84742.39000000","0.18001000"],["84743.38000000","0.00236000"],["84743.87000000","0.01871000"],["84743.88000000","0.00000000"],["84744.10000000","0.00000000"],["84744.14000000","0.00000000"],["84744.31000000","0.01094000"],["84744.93000000","0.00012000"],["84747.44000000","0.00000000"],["84749.12000000","0.36123000"],["84755.21000000","0.00000000"],["84756.13000000","0.00000000"],["84764.14000000","0.59003000"],["84813.81000000","0.00000000"],["84821.57000000","1.57930000"],["84825.55000000","0.79836000"],["84827.15000000","0.00020000"]]}}
{"stream":"btcusdt@depth@100ms","data":{"e":"depthUpdate","E":1790299055514,"s":"BTCUSDT","U":100639377278,"u":100639377466,"b":[["84735.39000000","0.90135000"],["84735.38000000","0.00123000"],["84735.37000000","0.00026000"],["84735.13000000","0.00006000"],["84734.78000000","0.00006000"],["84734.04000000","0.00000000"],["84733.54000000","0.12000000"],["84733.38000000","0.00000000"],["84732.75000000","0.00000000"],["84732.74000000","0.00014000"],["84732.21000000","0.04183000"],["84730.90000000","0.00000000"],["84730.75000000","0.00012000"],["84730.12000000","0.00000000"],["84729.51000000","0.00000000"],["84729.48000000","0.00000000"],["84729.46000000","0.00006000"],["84728.65000000","0.00000000"],["84728.53000000","0.00236000"],["84728.52000000","0.00000000"],["84727.74000000","0.00000000"],["84726.80000000","0.00000000"],["84726.74000000","0.34506000"],["84726.57000000","0.00236000"],["84726.44000000","0.00000000"],["84726.37000000","0.00000000"],["84725.81000000","0.00000000"],["84725.70000000","0.00000000"],["84725.48000000","0.00000000"],["84724.90000000","0.00000000"],["84723.69000000","0.00590000"],["84723.26000000","0.00000000"],["84723.21000000","0.36106000"],["84723.20000000","0.15000000"],["84723.08000000","0.00000000"],["84722.45000000","0.00000000"],["84722.27000000","0.00000000"],["84721.82000000","0.00000000"],["84721.80000000","0.00000000"],["84721.69000000","0.00200000"],["84720.87000000","0.00000000"],["84720.63000000","0.00000000"],["84720.14000000","0.00200000"],["84719.19000000","0.00000000"],["84717.98000000","0.00200000"],["84717.92000000","0.00200000"],["84709.81000000","0.00000000"],["84706.65000000","0.00000000"],["84704.73000000","0.00000000"],["84703.34000000","0.29512000"],["84698.87000000","0.29512000"],["84690.45000000","0.00000000"],["84686.42000000","0.00000000"],["84683.05000000","0.00000000"],["83464.36000000","0.00016000"],["76261.86000000","0.00330000"],["76261.85000000","0.00000000"],["76261.84000000","0.00008000"],["67788.32000000","0.00319000"],["67788.31000000","0.00000000"],["67788.00000000","0.00300000"]],"a":[["84735.40000000","4.27319000"],["84736.40000000","0.00400000"],["84737.15000000","0.00014000"],["84737.81000000","0.00000000"],["84738.52000000","0.00400000"],["84738.96000000","0.00013000"],["84739.15000000","0.03540000"],["84739.19000000","0.00590000"],["84739.74000000","0.00017000"],["84740.62000000","0.35516000"],["84740.63000000","0.00000000"],["84740.65000000","0.13390000"],["84741.50000000","0.00006000"],["84741.60000000","0.00000000"],["84741.71000000","2.12425000"],["84742.39000000","0.00000000"],["84742.78000000","0.00200000"],["84743.38000000","0.00000000"],["84743.85000000","0.00000000"],["84744.13000000","0.00000000"],["84744.15000000","0.00000000"],["84744.68000000","0.00000000"],["84744.93000000","0.00212000"],["84745.59000000","0.00000000"],["84746.88000000","0.00200000"],["84747.31000000","0.00000000"],["84747.86000000","0.00000000"],["84748.60000000","0.00000000"],["84749.08000000","0.00000000"],["84749.09000000","0.00000000"],["84749.11000000","0.00000000"],["84756.64000000","0.00000000"],["84766.91000000","0.00000000"],["84770.32000000","0.00000000"],["84791.53000000","0.00000000"],["84813.19000000","0.16945000"],["84871.57000000","0.00000000"],["84884.28000000","0.00000000"]]}}
{"stream":"btcusdt@depth@100ms","data":{"e":"depthUpdate","E":1790299055614,"s":"BTCUSDT","U":100639377467,"u":100639377586,"b":[["84735.39000000","1.30683000"],["84735.38000000","0.00102000"],["84735.13000000","0.00000000"],["84734.03000000","0.01693000"],["84733.67000000","0.11035000"],["84733.54000000","0.00000000"],["84732.67000000","0.02036000"],["84731.59000000","0.00006000"],["84731.33000000","0.02107000"],["84731.24000000","0.01141000"],["84729.46000000","0.00000000"],["84726.75000000","0.00014000"],["84726.73000000","0.47138000"],["84724.56000000","0.00236000"],["84721.80000000","0.00200000"],["84720.14000000","0.00000000"],["84719.19000000","0.00200000"],["84717.92000000","0.00000000"],["84717.86000000","0.11803000"],["84690.45000000","0.00006000"],["84685.27000000","0.70755000"],["84678.00000000","0.02800000"],["84675.14000000","1.19044000"],["84668.95000000","0.23608000"],["83464.36000000","0.00024000"],["82386.87000000","0.00000000"],["76261.86000000","0.00345000"],["67788.32000000","0.00290000"]],"a":[["84735.40000000","4.27325000"],["84736.94000000","0.00590000"],["84737.54000000","0.12502000"],["84738.06000000","0.00000000"],["84738.07000000","0.01116000"],["84739.14000000","0.00014000"],["84739.15000000","0.03546000"],["84739.36000000","0.00000000"],["84739.74000000","0.00010000"],["84739.75000000","0.01128000"],["84740.61000000","0.00014000"],["84740.64000000","0.00407000"],["84740.65000000","0.69639000"],["84741.70000000","0.00000000"],["84742.76000000","0.01534000"],["84742.90000000","0.00672000"],["84744.60000000","0.00400000"],["84744.93000000","0.00212000"],["84746.88000000","0.00000000"],["84749.12000000","0.35923000"],["84753.93000000","0.11799000"],["84757.17000000","0.00000000"],["84760.16000000","0.31863000"],["84764.28000000","0.00000000"],["84766.50000000","0.00118000"],["84780.10000000","0.00000000"],["84783.61000000","1.18891000"],["89076.24000000","0.00000000"]]}}
{"stream":"dogeusdt@depth@100ms","data":{"e":"depthUpdate","E":1790299055674,"s":"DOGEUSDT","U":25516667805,"u":25516667813,"b":[["0.09674000","20740.00000000"],["0.09672000","87437.00000000"],["0.09671000","175564.00000000"]],"a":[["0.09675000","70758.00000000"],["0.09676000","81024.00000000"],["0.09680000","155872.00000000"]]}}
{"stream":"btcusdt@depth@100ms","data":{"e":"depthUpdate","E":1790299055714,"s":"BTCUSDT","U":100639377587,"u":100639377623,"b":[["84735.39000000","1.30927000"],["84732.21000000","0.04189000"],["84731.35000000","0.01133000"],["84726.39000000","0.00200000"],["84725.82000000","0.00236000"],["84724.56000000","0.00000000"],["84721.80000000","0.00400000"],["84720.14000000","0.00000000"],["84719.19000000","0.00000000"],["84690.45000000","0.00000000"],["84619.95000000","0.00000000"],["83464.36000000","0.00024000"],["83464.35000000","0.00030000"]],"a":[["84735.40000000","2.14850000"],["84739.15000000","0.03540000"],["84739.19000000","0.00000000"],["84740.61000000","0.00014000"],["84741.70000000","0.00590000"],["84744.60000000","0.00200000"],["84744.93000000","0.00012000"],["84745.59000000","0.00200000"],["84746.66000000","0.00210000"],["84767.08000000","0.00442000"],["84874.20000000","0.00024000"]]}}
{"stream":"btcusdt@depth@100ms","data":{"e":"depthUpdate","E":1790299055814,"s":"BTCUSDT","U":100639377624,"u":100639377717,"b":[["84735.39000000","1.62477000"],["84735.38000000","0.00116000"],["84735.37000000","0.95281000"],["84734.78000000","0.00012000"],["84734.26000000","0.00000000"],["84734.03000000","0.01699000"],["84734.02000000","0.01081000"],["84733.67000000","0.11041000"],["84732.75000000","0.00014000"],["84732.74000000","0.34493000"],["84731.33000000","0.02104000"],["84728.16000000","0.00236000"],["84726.83000000","0.00000000"],["84726.75000000","0.00000000"],["84726.74000000","0.00014000"],["84726.39000000","0.00000000"],["84725.82000000","0.00000000"],["84609.64000000","0.04014000"],["76261.86000000","0.00345000"],["67788.32000000","0.00261000"]],"a":[["84735.40000000","2.14825000"],["84736.78000000","0.00007000"],["84736.94000000","0.00000000"],["84737.55000000","0.00000000"],["84739.74000000","0.00000000"],["84739.75000000","0.01134000"],["84739.87000000","0.00590000"],["84740.07000000","0.00000000"],["84740.61000000","0.00014000"],["84740.65000000","0.69645000"],["84742.78000000","0.00000000"],["84743.19000000","0.00153000"],["84744.60000000","0.00000000"],["84745.25000000","0.00000000"],["84745.26000000","0.00000000"],["84745.33000000","0.00200000"],["84745.35000000","0.00000000"],["84745.38000000","0.00000000"],["84745.40000000","0.00000000"],["84745.42000000","0.00000000"],["84745.43000000","0.00000000"],["84745.59000000","0.00000000"],["84745.65000000","0.00000000"],["84746.66000000","0.00010000"],["84747.24000000","0.00200000"],["84747.47000000","0.00200000"],["84747.59000000","0.00200000"],["84863.86000000","0.06797000"]]}}
{"stream":"dogeusdt@depth@100ms","data":{"e":"depthUpdate","E":1790299055874,"s":"DOGEUSDT","U":25516667814,"u":25516667873,"b":[["0.09674000","78791.00000000"],["0.09673000","46351.00000000"],["0.09672000","44396.00000000"],["0.09671000","194176.00000000"],["0.09669000","253190.00000000"],["0.09668000","141938.00000000"],["0.09663000","308071.00000000"],["0.09662000","641067.00000000"],["0.09659000","137749.00000000"],["0.09658000","154109.00000000"],["0.09644000","1579613.00000000"]],"a":[["0.09675000","27082.00000000"],["0.09676000","23535.00000000"],["0.09677000","61646.00000000"],["0.09678000","183438.00000000"],["0.09679000","128357.00000000"],["0.09681000","256815.00000000"],["0.09684000","175943.00000000"]]}}
{"stream":"btcusdt@depth@100ms","data":{"e":"depthUpdate","E":1790299055914,"s":"BTCUSDT","U":100639377718,"u":100639377744,"b":[["84735.39000000","1.62505000"],["84735.38000000","0.00144000"],["84722.00000000","0.00200000"],["84704.53000000","0.00200000"],["84686.47000000","0.00000000"],["84685.27000000","0.52794000"],["84682.57000000","0.00354000"],["84524.01000000","0.00000000"],["84522.01000000","0.00734000"],["83464.36000000","0.00024000"],["67788.31000000","0.00000000"]],"a":[["84735.40000000","2.14838000"],["84739.15000000","0.03546000"],["84739.53000000","0.00014000"],["84739.54000000","0.04000000"],["84740.64000000","0.00400000"],["84780.43000000","0.00616000"],["84863.86000000","0.00000000"]]}}
{"stream":"dogeusdt@depth@100ms","data":{"e":"depthUpdate","E":1790299055974,"s":"DOGEUSDT","U":25516667874,"u":25516667897,"b":[["0.09674000","92219.00000000"],["0.09673000","54351.00000000"],["0.09672000","46990.00000000"],["0.09670000","196199.00000000"],["0.09669000","245190.00000000"],["0.09668000","126058.00000000"],["0.09667000","175380.00000000"],["0.09663000","1084228.00000000"]],"a":[["0.09675000","25625.00000000"],["0.09676000","42147.00000000"],["0.09679000","128305.00000000"],["0.09681000","256919.00000000"]]}}
{"stream":"btcusdt@depth@100ms","data":{"e":"depthUpdate","E":1790299056014,"s":"BTCUSDT","U":100639377745,"u":100639377806,"b":[["84735.39000000","2.15574000"],["84735.38000000","0.00137000"],["84734.03000000","0.01693000"],["84734.02000000","0.00000000"],["84732.74000000","0.00000000"],["84732.22000000","0.00236000"],["84731.19000000","0.00590000"],["84730.76000000","0.00236000"],["84729.25000000","0.00590000"],["84728.63000000","0.02994000"],["84728.53000000","0.00000000"],["84726.74000000","0.00400000"],["84726.73000000","0.47131000"],["84726.57000000","0.00000000"],["84723.69000000","0.00200000"],["84723.21000000","0.35516000"],["84722.00000000","0.00000000"],["84721.80000000","0.00000000"],["84717.98000000","0.00000000"],["83464.36000000","0.00016000"],["76261.86000000","0.00345000"],["67788.32000000","0.00232000"]],"a":[["84735.40000000","1.48470000"],["84740.50000000","0.00024000"],["84740.62000000","0.00000000"],["84741.70000000","0.00000000"],["84743.00000000","0.00000000"],["84743.85000000","0.00000000"],["84743.87000000","0.00000000"],["84743.88000000","0.00068000"],["84745.07000000","0.00590000"],["84745.33000000","0.00000000"],["84746.65000000","0.00590000"],["84746.66000000","0.00000000"],["84747.47000000","0.00000000"],["84747.59000000","0.00000000"],["84747.61000000","0.00000000"],["84747.69000000","0.00000000"],["84747.76000000","0.00000000"],["84747.92000000","0.00000000"],["84748.35000000","0.00000000"],["84748.56000000","0.00000000"],["84749.11000000","0.00200000"],["84821.57000000","0.00000000"],["84864.07000000","0.03658000"],["86006.44000000","0.00030000"]]}}
{"stream":"dogeusdt@depth@100ms","data":{"e":"depthUpdate","E":1790299056074,"s":"DOGEUSDT","U":25516667898,"u":25516667972,"b":[["0.09675000","47309.00000000"],["0.09674000","110200.00000000"],["0.09673000","23012.00000000"],["0.09672000","55846.00000000"],["0.09671000","178452.00000000"],["0.09670000","196147.00000000"],["0.09665000","224957.00000000"],["0.09656000","261649.00000000"],["0.09655000","580354.00000000"]],"a":[["0.09675000","0.00000000"],["0.09676000","1623.00000000"],["0.09677000","371.00000000"],["0.09678000","32253.00000000"],["0.09679000","44577.00000000"],["0.09680000","114350.00000000"],["0.09681000","263919.00000000"],["0.09682000","384540.00000000"],["0.09683000","184937.00000000"],["0.09685000","112611.00000000"],["0.09686000","167043.00000000"],["0.09687000","369000.00000000"],["0.09688000","147188.00000000"],["0.09694000","63928.00000000"],["0.09703000","106414.00000000"],["0.09715000","190360.00000000"]]}}
{"stream":"btcusdt@depth@100ms","data":{"e":"depthUpdate","E":1790299056114,"s":"BTCUSDT","U":100639377807,"u":100639377976,"b":[["84735.39000000","2.18800000"],["84735.38000000","0.00095000"],["84735.37000000","0.95293000"],["84735.17000000","0.01103000"],["84735.14000000","0.00000000"],["84734.92000000","0.00000000"],["84734.34000000","0.02994000"],["84733.67000000","0.11035000"],["84733.28000000","0.00000000"],["84732.75000000","0.00000000"],["84732.74000000","0.00014000"],["84732.22000000","0.00000000"],["84731.24000000","0.01147000"],["84731.18000000","0.02006000"],["84730.76000000","0.00000000"],["84730.29000000","0.00236000"],["84729.25000000","0.00596000"],["84728.44000000","0.00000000"],["84728.16000000","0.00000000"],["84727.93000000","0.00400000"],["84727.63000000","0.00200000"],["84726.74000000","0.00400000"],["84726.14000000","0.03540000"],["84723.69000000","0.00000000"],["84721.78000000","0.88527000"],["84721.69000000","0.00000000"],["84720.63000000","0.00000000"],["84704.53000000","0.00000000"],["84698.24000000","0.00558000"],["84694.00000000","2.15355000"],["83464.36000000","0.00024000"],["76261.86000000","0.00330000"]],"a":[["84735.40000000","0.68717000"],["84737.12000000","0.00000000"],["84737.15000000","0.00000000"],["84737.16000000","0.00000000"],["84737.53000000","0.00000000"],["84737.54000000","0.00000000"],["84737.68000000","0.00006000"],["84738.06000000","0.00000000"],["84738.07000000","0.00006000"],["84738.81000000","0.00006000"],["84738.95000000","0.13107000"],["84738.96000000","0.17824000"],["84739.54000000","0.04006000"],["84739.75000000","0.00012000"],["84739.87000000","0.00000000"],["84740.50000000","0.00000000"],["84740.61000000","0.00000000"],["84740.62000000","0.00014000"],["84740.63000000","0.18001000"],["84740.64000000","0.00407000"],["84740.65000000","0.06227000"],["84741.50000000","0.00000000"],["84741.71000000","0.00000000"],["84742.05000000","0.00000000"],["84742.84000000","0.00006000"],["84743.12000000","0.00000000"],["84745.07000000","0.00000000"],["84746.62000000","0.02000000"],["84746.65000000","0.00000000"],["84746.87000000","0.00006000"],["84747.24000000","0.00000000"],["84747.59000000","0.00000000"],["84748.24000000","0.00000000"],["84748.25000000","0.00000000"],["84748.56000000","0.00590000"],["84749.11000000","0.00000000"],["84750.27000000","0.00590000"],["84750.89000000","0.00000000"],["84750.90000000","0.00006000"],["84751.50000000","0.07000000"],["84751.56000000","0.00000000"],["84751.62000000","0.00000000"],["84752.58000000","0.00000000"],["84753.47000000","0.00000000"],["84753.93000000","0.00000000"],["84754.93000000","0.00383000"],["84756.62000000","0.00200000"],["84760.16000000","0.00000000"],["84760.74000000","0.11798000"],["84775.24000000","0.00000000"],["84779.11000000","0.00006000"],["84786.97000000","0.31853000"],["84811.32000000","1.16768000"]]}}
{"stream":"dogeusdt@depth@100ms","data":{"e":"depthUpdate","E":1790299056174,"s":"DOGEUSDT","U":25516667973,"u":25516668404,"b":[["0.09678000","0.00000000"],["0.09677000","0.00000000"],["0.09676000","96050.00000000"],["0.09675000","108410.00000000"],["0.09674000","105637.00000000"],["0.09673000","29727.00000000"],["0.09672000","46886.00000000"],["0.09671000","168338.00000000"],["0.09670000","151560.00000000"],["0.09668000","105881.00000000"],["0.09667000","101164.00000000"],["0.09666000","296161.00000000"],["0.09665000","241479.00000000"],["0.09664000","342739.00000000"],["0.09663000","1062958.00000000"],["0.09662000","522450.00000000"],["0.09661000","381529.00000000"],["0.09659000","129882.00000000"],["0.09658000","154109.00000000"],["0.09657000","689388.00000000"],["0.09656000","105337.00000000"],["0.09655000","63320.00000000"],["0.09654000","338604.00000000"],["0.09648000","417212.00000000"],["0.09647000","134.00000000"],["0.09644000","1579601.00000000"],["0.09628000","42043.00000000"],["0.09624000","24403.00000000"],["0.09617000","5291.00000000"],["0.09612000","11584.00000000"],["0.09599000","85.00000000"],["0.09597000","2528882.00000000"],["0.09575000","503.00000000"]],"a":[["0.09676000","0.00000000"],["0.09677000","19628.00000000"],["0.09678000","58415.00000000"],["0.09679000","65353.00000000"],["0.09680000","40347.00000000"],["0.09681000","210456.00000000"],["0.09682000","243728.00000000"],["0.09683000","177669.00000000"],["0.09684000","175943.00000000"],["0.09685000","101271.00000000"],["0.09686000","119344.00000000"],["0.09687000","220182.00000000"],["0.09688000","266096.00000000"],["0.09689000","178149.00000000"],["0.09691000","186567.00000000"],["0.09692000","324158.00000000"],["0.09693000","334607.00000000"],["0.09694000","548836.00000000"],["0.09695000","157145.00000000"],["0.09696000","226593.00000000"],["0.09697000","274358.00000000"],["0.09698000","256218.00000000"],["0.09699000","239900.00000000"],["0.09701000","94520.00000000"],["0.09707000","14590.00000000"],["0.09710000","127642.00000000"],["0.09713000","83185.00000000"],["0.09715000","231895.00000000"],["0.09724000","838.00000000"],["0.09751000","3365.00000000"],["0.09752000","3271.00000000"],["0.09753000","2105.00000000"],["0.09754000","1475.00000000"]]}}
{"stream":"btcusdt@depth@100ms","data":{"e":"depthUpdate","E":1790299056214,"s":"BTCUSDT","U":100639377977,"u":100639378019,"b":[["84735.39000000","2.18814000"],["84735.38000000","0.00109000"],["84727.93000000","0.00000000"],["84609.64000000","0.00000000"],["83464.36000000","0.00024000"],["76261.86000000","0.00345000"],["67788.32000000","0.00203000"]],"a":[["84735.40000000","0.68723000"],["84736.40000000","0.00000000"],["84738.94000000","0.00014000"],["84740.64000000","0.00400000"],["84740.65000000","0.10804000"],["84744.15000000","0.18001000"],["84744.93000000","0.18013000"],["84749.11000000","0.00600000"],["84751.19000000","0.00200000"],["84751.20000000","0.02000000"],["84751.38000000","0.00000000"],["84751.50000000","0.07000000"],["84771.00000000","0.70000000"],["84773.00000000","0.00000000"],["84774.56000000","0.00400000"],["84864.07000000","0.00000000"]]}}
{"stream":"dogeusdt@depth@100ms","data":{"e":"depthUpdate","E":1790299056274,"s":"DOGEUSDT","U":25516668405,"u":25516668436,"b":[["0.09676000","98117.00000000"],["0.09675000","95074.00000000"],["0.09674000","68938.00000000"],["0.09673000","50107.00000000"],["0.09671000","160888.00000000"],["0.09670000","172180.00000000"],["0.09669000","246167.00000000"],["0.09665000","359527.00000000"],["0.09664000","322226.00000000"],["0.09600000","10808.00000000"]],"a":[["0.09677000","20889.00000000"],["0.09678000","41674.00000000"],["0.09679000","57353.00000000"],["0.09681000","208456.00000000"],["0.09682000","238728.00000000"],["0.09683000","184669.00000000"],["0.09685000","95054.00000000"],["0.09686000","122185.00000000"],["0.09690000","346577.00000000"],["0.09753000","2052.00000000"],["0.09754000","1422.00000000"]]}}
{"stream":"btcusdt@depth@100ms","data":{"e":"depthUpdate","E":1790299056314,"s":"BTCUSDT","U":100639378020,"u":100639378056,"b":[["84735.39000000","2.18862000"],["84731.43000000","0.00236000"],["84730.29000000","0.00000000"],["84726.74000000","0.00600000"],["84724.50000000","0.00000000"],["84721.04000000","0.00006000"],["84708.94000000","0.00200000"],["84690.74000000","0.05800000"],["84616.12000000","0.03660000"],["76261.86000000","0.00345000"],["76261.84000000","0.00000000"]],"a":[["84735.40000000","0.68713000"],["84738.96000000","0.17830000"],["84739.04000000","0.00014000"],["84739.05000000","0.11035000"],["84739.54000000","0.04000000"],["84740.47000000","0.00024000"],["84740.62000000","0.00000000"],["84740.63000000","0.00000000"],["84740.65000000","0.10810000"],["84740.99000000","0.00590000"],["84742.84000000","0.00012000"],["84744.93000000","0.00012000"],["84746.87000000","0.00012000"],["84749.10000000","0.17486000"],["84749.11000000","0.00400000"],["84750.90000000","0.00012000"],["84754.93000000","0.00389000"],["84754.94000000","0.00006000"],["84771.00000000","0.00000000"],["84870.36000000","0.06797000"]]}}
{"stream":"dogeusdt@depth@100ms","data":{"e":"depthUpdate","E":1790299056374,"s":"DOGEUSDT","U":25516668437,"u":25516668449,"b":[["0.09674000","77617.00000000"]],"a":[["0.09677000","19639.00000000"],["0.09678000","39658.00000000"],["0.09679000","57375.00000000"],["0.09680000","32336.00000000"],["0.09682000","245728.00000000"],["0.09683000","177669.00000000"],["0.09684000","183943.00000000"]]}}
{"stream":"btcusdt@depth@100ms","data":{"e":"depthUpdate","E":1790299056414,"s":"BTCUSDT","U":100639378057,"u":100639378133,"b":[["84735.39000000","2.20862000"],["84734.26000000","0.00007000"],["84731.43000000","0.00000000"],["84731.24000000","0.01141000"],["84731.18000000","0.00006000"],["84730.29000000","0.00236000"],["84730.04000000","0.00400000"],["84696.12000000","0.00000000"],["83464.36000000","0.00024000"],["67788.32000000","0.00174000"],["67777.00000000","0.34633000"],["67772.00000000","0.00738000"],["67739.00000000","0.00000000"],["67734.00000000","0.00000000"]],"a":[["84735.40000000","0.68489000"],["84736.78000000","0.00000000"],["84737.62000000","0.00000000"],["84738.81000000","0.00012000"],["84738.92000000","0.00014000"],["84738.93000000","0.16474000"],["84738.94000000","0.18001000"],["84738.95000000","0.00000000"],["84738.96000000","0.00019000"],["84739.54000000","0.04006000"],["84740.63000000","0.00000000"],["84740.64000000","0.00400000"],["84740.65000000","0.11786000"],["84740.99000000","0.00590000"],["84742.39000000","0.00000000"],["84744.93000000","0.00012000"],["84749.09000000","0.00200000"],["84749.10000000","0.00000000"],["84765.16000000","0.00000000"]]}}
{"stream":"dogeusdt@depth@100ms","data":{"e":"depthUpdate","E":1790299056474,"s":"DOGEUSDT","U":25516668450,"u":25516668461,"b":[["0.09675000","104520.00000000"],["0.09674000","82144.00000000"],["0.09673000","370399.00000000"],["0.09661000","333944.00000000"],["0.09660000","154991.00000000"],["0.09657000","545552.00000000"],["0.09655000","10462.00000000"],["0.09654000","136635.00000000"],["0.09649000","127845.00000000"],["0.09634000","124595.00000000"],["0.09629000","446.00000000"]],"a":[]}}
{"stream":"btcusdt@depth@100ms","data":{"e":"depthUpdate","E":1790299056514,"s":"BTCUSDT","U":100639378134,"u":100639378202,"b":[["84727.63000000","0.00600000"],["84725.52000000","0.00048000"],["84725.09000000","0.00000000"],["84721.41000000","0.00000000"],["84679.04000000","0.00000000"],["84645.16000000","0.00000000"],["83464.36000000","0.00016000"],["82386.87000000","0.00010000"],["76261.86000000","0.00345000"],["76261.00000000","0.00020000"],["67788.32000000","0.00290000"],["67788.31000000","0.00000000"],["67788.00000000","0.00300000"]],"a":[["84735.40000000","0.87024000"],["84735.41000000","0.00067000"],["84738.93000000","0.05707000"],["84738.94000000","0.00000000"],["84739.04000000","0.00020000"],["84739.54000000","0.04000000"],["84740.64000000","0.00407000"],["84740.99000000","0.00596000"],["84742.39000000","0.18001000"],["84749.10000000","0.18001000"],["84754.93000000","0.00012000"],["84797.31000000","0.00000000"],["84831.21000000","0.00000000"],["84833.03000000","0.00377000"]]}}
{"stream":"dogeusdt@depth@100ms","data":{"e":"depthUpdate","E":1790299056574,"s":"DOGEUSDT","U":25516668462,"u":25516668572,"b":[["0.09677000","152573.00000000"],["0.09676000","120469.00000000"],["0.09675000","132704.00000000"],["0.09674000","337218.00000000"],["0.09673000","373317.00000000"],["0.09672000","38834.00000000"],["0.09667000","98299.00000000"],["0.09665000","359538.00000000"],["0.09658000","136621.00000000"],["0.09657000","517107.00000000"],["0.09655000","1252.00000000"],["0.09654000","115730.00000000"],["0.09653000","175783.00000000"],["0.09648000","365850.00000000"],["0.09645000","112.00000000"],["0.09644000","1498923.00000000"],["0.09628000","42032.00000000"],["0.09623000","168.00000000"],["0.09605000","1036070.00000000"],["0.09597000","1493365.00000000"]],"a":[["0.09677000","0.00000000"],["0.09678000","19708.00000000"],["0.09679000","53375.00000000"],["0.09680000","48546.00000000"],["0.09681000","232190.00000000"],["0.09682000","238739.00000000"],["0.09683000","184669.00000000"],["0.09684000","183969.00000000"],["0.09696000","226604.00000000"],["0.09706000","1536961.00000000"],["0.09714000","1838.00000000"],["0.09716000","2023.00000000"],["0.09741000","7317.00000000"],["0.09749000","1036742.00000000"]]}}
{"stream":"btcusdt@depth@100ms","data":{"e":"depthUpdate","E":1790299056614,"s":"BTCUSDT","U":100639378203,"u":100639378236,"b":[["84735.39000000","2.20702000"],["84732.64000000","0.00200000"],["84642.52000000","0.00377000"],["83490.79000000","0.00000000"],["83464.36000000","0.00024000"],["76261.00000000","0.00000000"],["67788.32000000","0.00261000"],["67788.00000000","0.00400000"]],"a":[["84735.40000000","0.87018000"],["84735.41000000","0.00067000"],["84738.47000000","0.00007000"],["84738.92000000","0.00000000"],["84738.93000000","0.00000000"],["84740.63000000","0.18001000"],["84740.64000000","0.00414000"],["84742.38000000","0.00007000"],["84749.09000000","0.00000000"],["84750.08000000","0.00000000"],["84750.12000000","0.00000000"],["84750.13000000","0.00000000"],["84751.19000000","0.00000000"],["84868.46000000","0.00020000"],["84939.13000000","0.01848000"]]}}
{"stream":"dogeusdt@depth@100ms","data":{"e":"depthUpdate","E":1790299056674,"s":"DOGEUSDT","U":25516668573,"u":25516668601,"b":[["0.09677000","175977.00000000"],["0.09676000","100050.00000000"],["0.09675000","132757.00000000"],["0.09674000","373904.00000000"],["0.09673000","331450.00000000"],["0.09664000","97912.00000000"],["0.09663000","286801.00000000"],["0.09638000","118541.00000000"],["0.09636000","265.00000000"],["0.09608000","30784.00000000"],["0.09601000","508.00000000"]],"a":[["0.09685000","115577.00000000"],["0.09686000","146073.00000000"],["0.09696000","226615.00000000"],["0.09698000","327828.00000000"],["0.09734000","526.00000000"],["0.09739000","24730.00000000"],["0.09753000","2105.00000000"],["0.09768000","1078.00000000"],["0.09774000","32503.00000000"]]}}
{"stream":"btcusdt@depth@100ms","data":{"e":"depthUpdate","E":1790299056714,"s":"BTCUSDT","U":100639378237,"u":100639378279,"b":[["84730.29000000","0.00000000"],["84630.36000000","0.00000000"],["84617.84000000","0.03659000"],["84616.12000000","0.00000000"],["83464.36000000","0.00024000"],["83464.35000000","0.00030000"],["76261.86000000","0.00345000"],["67788.00000000","0.00300000"]],"a":[["84735.40000000","0.87181000"],["84735.41000000","0.00081000"],["84738.81000000","0.00006000"],["84739.03000000","0.00014000"],["84739.04000000","0.11094000"],["84739.54000000","0.04006000"],["84740.62000000","0.00014000"],["84740.64000000","0.00400000"],["84740.99000000","0.00590000"],["84742.16000000","0.00000000"],["84742.38000000","0.00000000"],["84742.39000000","0.00000000"],["84748.60000000","0.00236000"],["84749.09000000","0.00400000"],["84750.15000000","0.00200000"],["84766.05000000","0.00200000"],["84870.36000000","0.00000000"],["84872.08000000","0.06797000"]]}}
{"stream":"dogeusdt@depth@100ms","data":{"e":"depthUpdate","E":1790299056774,"s":"DOGEUSDT","U":25516668602,"u":25516668612,"b":[["0.09677000","167977.00000000"],["0.09673000","331439.00000000"],["0.09665000","337451.00000000"],["0.09639000","522762.00000000"],["0.09635000","167970.00000000"]],"a":[["0.09679000","71987.00000000"],["0.09680000","52546.00000000"],["0.09681000","228190.00000000"],["0.09711000","95271.00000000"],["0.09715000","748887.00000000"]]}}
{"stream":"btcusdt@depth@100ms","data":{"e":"depthUpdate","E":1790299056814,"s":"BTCUSDT","U":100639378280,"u":100639378292,"b":[["84732.64000000","0.00000000"],["84727.63000000","0.00200000"],["84718.77000000","0.00377000"],["84543.94000000","0.00000000"],["76261.86000000","0.00330000"],["67788.32000000","0.00232000"],["67788.00000000","0.00600000"]],"a":[["84739.03000000","0.00020000"],["84934.70000000","0.00000000"],["89076.24000000","0.00010000"]]}}
{"stream":"dogeusdt@depth@100ms","data":{"e":"depthUpdate","E":1790299056874,"s":"DOGEUSDT","U":25516668613,"u":25516668613,"b":[["0.09671000","159853.00000000"]],"a":[]}}
{"stream":"btcusdt@depth@100ms","data":{"e":"depthUpdate","E":1790299056914,"s":"BTCUSDT","U":100639378293,"u":100639378320,"b":[["84735.39000000","2.20466000"],["84734.11000000","0.00236000"],["83464.36000000","0.00024000"],["76261.86000000","0.00345000"],["67788.31000000","0.00000000"],["67788.00000000","0.00300000"]],"a":[["84735.40000000","0.87187000"],["84735.41000000","0.00081000"],["84738.94000000","0.00014000"],["84738.95000000","0.11104000"],["84738.96000000","0.18020000"],["84739.03000000","0.00006000"],["84739.04000000","0.00020000"],["84739.54000000","0.04000000"],["84740.62000000","0.00000000"],["84740.63000000","0.00000000"],["84757.71000000","0.01967000"]]}}
{"stream":"dogeusdt@depth@100ms","data":{"e":"depthUpdate","E":1790299056974,"s":"DOGEUSDT","U":25516668614,"u":25516668615,"b":[["0.09677000","181143.00000000"]],"a":[]}}
{"stream":"btcusdt@depth@100ms","data":{"e":"depthUpdate","E":1790299057014,"s":"BTCUSDT","U":100639378321,"u":100639378352,"b":[["84735.39000000","2.20480000"],["84735.38000000","0.00116000"],["84732.16000000","0.00200000"],["84727.03000000","0.00400000"],["84675.15000000","0.86020000"],["84674.11000000","0.00000000"],["84617.84000000","0.00000000"],["84544.97000000","4.20478000"],["83464.36000000","0.00016000"],["76261.86000000","0.00345000"],["67788.32000000","0.00319000"]],"a":[["84735.40000000","0.87187000"],["84735.41000000","0.00081000"],["84739.03000000","0.00000000"],["84739.04000000","0.00014000"],["84740.24000000","0.03025000"],["84757.71000000","0.00000000"],["84762.97000000","0.32916000"],["84809.14000000","0.65533000"],["84872.08000000","0.00000000"],["84935.24000000","4.20658000"],["86006.44000000","0.00030000"]]}}
{"stream":"dogeusdt@depth@100ms","data":{"e":"depthUpdate","E":1790299057074,"s":"DOGEUSDT","U":25516668616,"u":25516668642,"b":[["0.09677000","188143.00000000"],["0.09676000","93050.00000000"],["0.09665000","354331.00000000"],["0.09661000","333881.00000000"],["0.09659000","197124.00000000"],["0.09658000","385640.00000000"]],"a":[["0.09679000","51359.00000000"],["0.09681000","208456.00000000"],["0.09684000","196323.00000000"],["0.09685000","111629.00000000"],["0.09689000","182174.00000000"],["0.09691000","109489.00000000"],["0.09692000","150818.00000000"],["0.09694000","598438.00000000"],["0.09695000","330435.00000000"],["0.09699000","433421.00000000"],["0.09721000","114944.00000000"]]}}
{"stream":"btcusdt@depth@100ms","data":{"e":"depthUpdate","E":1790299057114,"s":"BTCUSDT","U":100639378353,"u":100639378369,"b":[["84735.39000000","2.20636000"],["84735.38000000","0.00123000"],["84735.14000000","0.00328000"],["84616.30000000","0.03660000"],["84526.01000000","0.00734000"],["84522.01000000","0.00000000"],["83464.36000000","0.00024000"]],"a":[["84735.40000000","0.87194000"],["84735.41000000","0.00088000"],["84739.54000000","0.04006000"],["84870.54000000","0.06797000"]]}}
{"stream":"dogeusdt@depth@100ms","data":{"e":"depthUpdate","E":1790299057174,"s":"DOGEUSDT","U":25516668643,"u":25516668646,"b":[],"a":[["0.09679000","51370.00000000"],["0.09682000","240739.00000000"],["0.09683000","182669.00000000"],["0.09707000","14601.00000000"]]}}
{"stream":"btcusdt@depth@100ms","data":{"e":"depthUpdate","E":1790299057214,"s":"BTCUSDT","U":100639378370,"u":100639378381,"b":[["84735.39000000","2.20629000"],["84721.77000000","0.01696000"],["84700.00000000","0.04571000"],["83464.36000000","0.00024000"],["76261.86000000","0.00345000"],["76261.85000000","0.00008000"],["67788.32000000","0.00290000"]],"a":[["84743.87000000","0.00000000"],["84743.88000000","0.00068000"],["84775.00000000","0.70000000"]]}}
{"stream":"dogeusdt@depth@100ms","data":{"e":"depthUpdate","E":1790299057274,"s":"DOGEUSDT","U":25516668647,"u":25516668654,"b":[["0.09675000","132861.00000000"]],"a":[["0.09678000","20942.00000000"],["0.09680000","52650.00000000"],["0.09682000","260195.00000000"],["0.09684000","183969.00000000"],["0.09697000","307770.00000000"],["0.09706000","1467187.00000000"]]}}
{"stream":"btcusdt@depth@100ms","data":{"e":"depthUpdate","E":1790299057314,"s":"BTCUSDT","U":100639378382,"u":100639378386,"b":[["84732.16000000","0.00000000"],["84721.04000000","0.00000000"]],"a":[["84735.40000000","0.87201000"],["84740.99000000","0.00596000"],["84742.39000000","0.16747000"],["84754.94000000","0.00000000"]]}}
{"stream":"dogeusdt@depth@100ms","data":{"e":"depthUpdate","E":1790299057374,"s":"DOGEUSDT","U":25516668655,"u":25516668660,"b":[["0.08850000","135150.00000000"]],"a":[["0.09682000","260195.00000000"],["0.09683000","182669.00000000"],["0.09685000","124188.00000000"]]}}
{"stream":"btcusdt@depth@100ms","data":{"e":"depthUpdate","E":1790299057414,"s":"BTCUSDT","U":100639378387,"u":100639378408,"b":[["84735.39000000","2.34221000"],["84731.02000000","0.00200000"],["84721.04000000","0.00006000"],["84720.81000000","0.08931000"],["84679.40000000","0.00030000"],["84598.23000000","0.01200000"],["83464.36000000","0.00024000"],["76261.86000000","0.00345000"],["67788.32000000","0.00261000"]],"a":[["84749.09000000","0.00800000"],["84754.94000000","0.00006000"]]}}
{"stream":"dogeusdt@depth@100ms","data":{"e":"depthUpdate","E":1790299057474,"s":"DOGEUSDT","U":25516668661,"u":25516668664,"b":[],"a":[["0.09682000","260195.00000000"],["0.09683000","182669.00000000"]]}}
{"stream":"btcusdt@depth@100ms","data":{"e":"depthUpdate","E":1790299057514,"s":"BTCUSDT","U":100639378409,"u":100639378412,"b":[["83464.36000000","0.00016000"],["76261.86000000","0.00330000"],["67788.31000000","0.00000000"]],"a":[]}}
{"stream":"dogeusdt@depth@100ms","data":{"e":"depthUpdate","E":1790299057574,"s":"DOGEUSDT","U":25516668665,"u":25516668669,"b":[["0.09677000","180143.00000000"]],"a":[["0.09681000","227002.00000000"],["0.09682000","245739.00000000"],["0.09683000","177669.00000000"]]}}
{"stream":"btcusdt@depth@100ms","data":{"e":"depthUpdate","E":1790299057614,"s":"BTCUSDT","U":100639378413,"u":100639378423,"b":[["84735.39000000","2.34228000"],["84467.90000000","0.01446000"],["83464.36000000","0.00024000"],["76261.86000000","0.00345000"],["67788.32000000","0.00232000"],["67788.00000000","0.00300000"]],"a":[["84749.10000000","0.00000000"],["84827.15000000","1.57950000"]]}}
{"stream":"dogeusdt@depth@100ms","data":{"e":"depthUpdate","E":1790299057674,"s":"DOGEUSDT","U":25516668670,"u":25516668673,"b":[["0.09675000","132873.00000000"],["0.09658000","488498.00000000"],["0.09645000","100.00000000"]],"a":[["0.09701000","94532.00000000"]]}}
{"stream":"btcusdt@depth@100ms","data":{"e":"depthUpdate","E":1790299057714,"s":"BTCUSDT","U":100639378424,"u":100639378456,"b":[["84735.39000000","2.34212000"],["84731.02000000","0.00000000"],["84707.91000000","0.00000000"],["84682.22000000","0.00000000"],["84383.44000000","0.00169000"],["83464.36000000","0.00024000"],["83464.35000000","0.00030000"],["76261.86000000","0.00345000"],["76261.85000000","0.00000000"],["76261.84000000","0.00008000"],["76261.00000000","0.00020000"]],"a":[["84735.40000000","1.16588000"],["84738.64000000","0.00325000"],["84738.67000000","0.00014000"],["84738.68000000","0.01625000"],["84738.95000000","0.06611000"],["84738.96000000","0.00019000"],["84743.87000000","0.00000000"],["84743.88000000","0.00068000"],["84770.42000000","0.00000000"],["84770.81000000","0.00000000"],["84796.52000000","0.00000000"]]}}
{"stream":"dogeusdt@depth@100ms","data":{"e":"depthUpdate","E":1790299057774,"s":"DOGEUSDT","U":25516668674,"u":25516668691,"b":[["0.09677000","114791.00000000"],["0.09676000","85050.00000000"],["0.09672000","46834.00000000"],["0.09671000","275653.00000000"],["0.09665000","238454.00000000"]],"a":[["0.09678000","60633.00000000"],["0.09679000","39870.00000000"],["0.09680000","72033.00000000"],["0.09681000","208456.00000000"]]}}
{"stream":"btcusdt@depth@100ms","data":{"e":"depthUpdate","E":1790299057814,"s":"BTCUSDT","U":100639378457,"u":100639378466,"b":[["84735.39000000","2.34205000"],["84734.11000000","0.00000000"],["84732.75000000","0.00236000"],["84732.52000000","0.00236000"],["84730.65000000","0.00200000"],["84598.23000000","0.00000000"],["84592.78000000","0.01848000"],["84585.85000000","0.00000000"],["84341.24000000","0.01701000"],["76261.00000000","0.00000000"],["67788.32000000","0.00203000"]],"a":[]}}
{"stream":"dogeusdt@depth@100ms","data":{"e":"depthUpdate","E":1790299057874,"s":"DOGEUSDT","U":25516668692,"u":25516668697,"b":[["0.09672000","77252.00000000"]],"a":[["0.09683000","177695.00000000"],["0.09684000","183943.00000000"],["0.09692000","221886.00000000"],["0.09693000","553580.00000000"]]}}
{"stream":"btcusdt@depth@100ms","data":{"e":"depthUpdate","E":1790299057914,"s":"BTCUSDT","U":100639378467,"u":100639378481,"b":[["84735.39000000","2.34198000"],["84735.38000000","0.00116000"],["84732.52000000","0.00000000"],["84732.51000000","0.00236000"],["84682.57000000","0.00000000"],["83464.36000000","0.00024000"],["76261.86000000","0.00345000"]],"a":[["84735.40000000","1.16595000"],["84735.41000000","0.00095000"]]}}
{"stream":"btcusdt@depth@100ms","data":{"e":"depthUpdate","E":1790299058014,"s":"BTCUSDT","U":100639378482,"u":100639378507,"b":[["84735.39000000","2.34226000"],["84732.51000000","0.00000000"],["84732.50000000","0.00236000"],["84707.23000000","0.21906000"],["84682.57000000","0.00354000"],["84680.84000000","0.43733000"],["84676.41000000","0.00377000"],["83464.36000000","0.00016000"],["67788.32000000","0.00290000"],["67788.31000000","0.00000000"]],"a":[["84735.40000000","1.16608000"],["84757.71000000","0.01967000"],["84770.83000000","0.44252000"],["84771.44000000","0.22366000"],["84797.84000000","0.44458000"],["84825.55000000","1.16771000"],["86006.44000000","0.00030000"]]}}
{"stream":"dogeusdt@depth@100ms","data":{"e":"depthUpdate","E":1790299058074,"s":"DOGEUSDT","U":25516668698,"u":25516668699,"b":[],"a":[["0.09694000","679166.00000000"],["0.09721000","34216.00000000"]]}}
{"stream":"btcusdt@depth@100ms","data":{"e":"depthUpdate","E":1790299058114,"s":"BTCUSDT","U":100639378508,"u":100639378521,"b":[["84735.39000000","2.34226000"],["84735.38000000","0.00116000"],["84735.14000000","0.00000000"],["83464.36000000","0.00024000"],["81796.37000000","0.00611000"],["76261.86000000","0.00345000"]],"a":[["84735.40000000","0.87214000"],["84749.08000000","0.17934000"],["84757.71000000","0.00000000"]]}}
{"stream":"dogeusdt@depth@100ms","data":{"e":"depthUpdate","E":1790299058174,"s":"DOGEUSDT","U":25516668700,"u":25516668727,"b":[["0.09677000","114780.00000000"],["0.09676000","111733.00000000"],["0.09672000","69252.00000000"],["0.09647000","145.00000000"]],"a":[["0.09678000","19692.00000000"],["0.09679000","32758.00000000"],["0.09680000","52628.00000000"],["0.09681000","200456.00000000"],["0.09682000","245739.00000000"],["0.09683000","177695.00000000"],["0.09685000","132188.00000000"],["0.09694000","717210.00000000"],["0.09697000","250010.00000000"],["0.09713000","16779.00000000"]]}}
{"stream":"btcusdt@depth@100ms","data":{"e":"depthUpdate","E":1790299058214,"s":"BTCUSDT","U":100639378522,"u":100639378535,"b":[["84735.39000000","2.35260000"],["84732.50000000","0.00000000"],["84732.49000000","0.00236000"],["83464.36000000","0.00024000"],["67788.32000000","0.00261000"],["67788.00000000","0.00300000"]],"a":[["84738.94000000","0.16603000"],["84740.63000000","0.18001000"],["84757.71000000","0.01967000"]]}}
{"stream":"dogeusdt@depth@100ms","data":{"e":"depthUpdate","E":1790299058274,"s":"DOGEUSDT","U":25516668728,"u":25516668751,"b":[["0.09677000","114780.00000000"],["0.09676000","111733.00000000"],["0.09672000","69252.00000000"],["0.09666000","354763.00000000"],["0.09658000","456799.00000000"]],"a":[["0.09678000","19692.00000000"],["0.09680000","52650.00000000"],["0.09682000","238739.00000000"],["0.09683000","184695.00000000"],["0.09695000","309687.00000000"],["0.09696000","202272.00000000"]]}}
{"stream":"btcusdt@depth@100ms","data":{"e":"depthUpdate","E":1790299058314,"s":"BTCUSDT","U":100639378536,"u":100639378588,"b":[["84735.39000000","2.35274000"],["84735.38000000","0.00123000"],["84735.14000000","0.00328000"],["84732.49000000","0.00000000"],["84732.48000000","0.00249000"],["76261.86000000","0.00345000"]],"a":[["84735.40000000","0.87208000"],["84735.41000000","0.00095000"],["84738.68000000","0.01631000"],["84738.92000000","0.00014000"],["84738.93000000","0.06607000"],["84738.94000000","0.00000000"],["84738.95000000","0.00000000"],["84739.53000000","0.00007000"],["84740.24000000","0.03025000"],["84740.63000000","0.16576000"],["84740.99000000","0.00590000"],["84742.39000000","0.18001000"],["84744.93000000","0.18013000"],["84746.67000000","0.01289000"],["84749.08000000","0.00000000"],["84757.71000000","0.00000000"]]}}
{"stream":"dogeusdt@depth@100ms","data":{"e":"depthUpdate","E":1790299058374,"s":"DOGEUSDT","U":25516668752,"u":25516668759,"b":[["0.09677000","122780.00000000"]],"a":[["0.09678000","19681.00000000"],["0.09682000","240739.00000000"],["0.09683000","182695.00000000"]]}}
{"stream":"btcusdt@depth@100ms","data":{"e":"depthUpdate","E":1790299058414,"s":"BTCUSDT","U":100639378589,"u":100639378623,"b":[["84735.39000000","2.36803000"],["84733.67000000","0.00000000"],["84733.19000000","0.00200000"],["84730.65000000","0.00000000"],["84729.00000000","0.10652000"],["84727.03000000","0.00000000"],["84726.74000000","0.01000000"],["84721.04000000","0.00006000"],["83464.36000000","0.00024000"],["76261.86000000","0.00345000"],["67788.32000000","0.00232000"]],"a":[["84735.40000000","0.87215000"],["84738.93000000","0.10713000"],["84740.24000000","0.03031000"],["84741.72000000","0.01092000"],["84744.93000000","0.00012000"],["84754.94000000","0.00006000"],["84759.50000000","0.10652000"]]}}
{"stream":"dogeusdt@depth@100ms","data":{"e":"depthUpdate","E":1790299058474,"s":"DOGEUSDT","U":25516668760,"u":25516668774,"b":[["0.09677000","134573.00000000"],["0.09676000","94733.00000000"],["0.09675000","141235.00000000"],["0.09674000","355292.00000000"],["0.09670000","190787.00000000"],["0.09634000","244.00000000"],["0.09629000","124861.00000000"]],"a":[["0.09678000","39538.00000000"],["0.09680000","71257.00000000"],["0.09681000","218478.00000000"],["0.09682000","245739.00000000"],["0.09683000","177695.00000000"]]}}
{"stream":"btcusdt@depth@100ms","data":{"e":"depthUpdate","E":1790299058514,"s":"BTCUSDT","U":100639378624,"u":100639378637,"b":[["84735.39000000","2.36803000"],["84735.38000000","0.00123000"],["84734.03000000","0.01687000"],["84732.48000000","0.00013000"],["84732.47000000","0.00236000"],["84731.33000000","0.05716000"],["83464.36000000","0.00016000"],["67788.31000000","0.00000000"]],"a":[["84870.54000000","0.00000000"]]}}
{"stream":"dogeusdt@depth@100ms","data":{"e":"depthUpdate","E":1790299058574,"s":"DOGEUSDT","U":25516668775,"u":25516668775,"b":[["0.09658000","455101.00000000"]],"a":[]}}
{"stream":"btcusdt@depth@100ms","data":{"e":"depthUpdate","E":1790299058614,"s":"BTCUSDT","U":100639378638,"u":100639378649,"b":[["84735.39000000","2.36803000"],["84732.47000000","0.00000000"],["84732.46000000","0.00236000"],["83464.36000000","0.00024000"],["76261.86000000","0.00345000"],["67788.32000000","0.00203000"]],"a":[["84738.92000000","0.17030000"],["84866.24000000","0.03935000"]]}}
{"stream":"dogeusdt@depth@100ms","data":{"e":"depthUpdate","E":1790299058674,"s":"DOGEUSDT","U":25516668776,"u":25516668778,"b":[["0.09676000","86733.00000000"],["0.09672000","77252.00000000"]],"a":[["0.09695000","327687.00000000"]]}}
{"stream":"btcusdt@depth@100ms","data":{"e":"depthUpdate","E":1790299058714,"s":"BTCUSDT","U":100639378650,"u":100639378679,"b":[["84735.39000000","2.36796000"],["84732.46000000","0.00000000"],["84731.53000000","0.00200000"],["83464.36000000","0.00024000"],["83464.35000000","0.00030000"]],"a":[["84735.40000000","0.87208000"],["84738.68000000","0.01637000"],["84738.90000000","0.00014000"],["84738.91000000","0.11705000"],["84738.92000000","0.17016000"],["84738.93000000","0.00000000"],["84739.53000000","0.00000000"],["84740.24000000","0.03025000"],["84740.63000000","0.00000000"],["84740.99000000","0.00596000"],["84742.39000000","0.00000000"],["84749.08000000","0.18001000"]]}}
{"stream":"dogeusdt@depth@100ms","data":{"e":"depthUpdate","E":1790299058774,"s":"DOGEUSDT","U":25516668779,"u":25516668779,"b":[],"a":[["0.09702000","321148.00000000"]]}}
{"stream":"btcusdt@depth@100ms","data":{"e":"depthUpdate","E":1790299058814,"s":"BTCUSDT","U":100639378680,"u":100639378688,"b":[["76261.86000000","0.00360000"],["67788.32000000","0.00174000"]],"a":[["84735.40000000","0.87215000"],["84735.41000000","0.00102000"],["84799.12000000","0.00377000"]]}}
{"stream":"dogeusdt@depth@100ms","data":{"e":"depthUpdate","E":1790299058874,"s":"DOGEUSDT","U":25516668780,"u":25516668788,"b":[["0.09677000","134573.00000000"]],"a":[["0.09678000","20931.00000000"],["0.09680000","71257.00000000"],["0.09688000","291547.00000000"]]}}
{"stream":"btcusdt@depth@100ms","data":{"e":"depthUpdate","E":1790299058914,"s":"BTCUSDT","U":100639378689,"u":100639378691,"b":[["83464.36000000","0.00024000"],["76261.00000000","0.00020000"]],"a":[]}}
{"stream":"btcusdt@depth@100ms","data":{"e":"depthUpdate","E":1790299059014,"s":"BTCUSDT","U":100639378692,"u":100639378726,"b":[["84735.39000000","2.36786000"],["84731.53000000","0.00000000"],["84726.74000000","0.00800000"],["84725.18000000","0.00200000"],["83464.36000000","0.00016000"],["76261.86000000","0.00360000"],["76261.84000000","0.00000000"],["76261.00000000","0.00000000"],["67788.32000000","0.00261000"],["67788.31000000","0.00000000"]],"a":[["84735.40000000","1.16589000"],["84735.41000000","0.00095000"],["84738.68000000","0.01631000"],["84738.91000000","0.06607000"],["84738.92000000","0.00000000"],["84739.53000000","0.00007000"],["84759.16000000","0.15629000"],["84783.20000000","0.77806000"],["84866.24000000","0.06797000"],["86006.44000000","0.00030000"]]}}
{"stream":"btcusdt@depth@100ms","data":{"e":"depthUpdate","E":1790299059114,"s":"BTCUSDT","U":100639378727,"u":100639378732,"b":[["84735.39000000","2.36772000"],["84735.14000000","0.00000000"],["84730.36000000","0.00200000"],["83464.36000000","0.00024000"],["76261.86000000","0.00345000"]],"a":[]}}
{"stream":"dogeusdt@depth@100ms","data":{"e":"depthUpdate","E":1790299059174,"s":"DOGEUSDT","U":25516668789,"u":25516668805,"b":[["0.09677000","134573.00000000"],["0.09674000","355304.00000000"],["0.09646000","154.00000000"]],"a":[["0.09678000","20942.00000000"],["0.09679000","51365.00000000"],["0.09680000","52650.00000000"],["0.09682000","238739.00000000"],["0.09683000","184695.00000000"],["0.09702000","321160.00000000"],["0.09707000","12039.00000000"]]}}
{"stream":"btcusdt@depth@100ms","data":{"e":"depthUpdate","E":1790299059214,"s":"BTCUSDT","U":100639378733,"u":100639378743,"b":[["84735.39000000","2.36776000"],["84735.38000000","0.00116000"],["83464.36000000","0.00024000"],["76261.86000000","0.00360000"],["67788.32000000","0.00232000"]],"a":[["84742.39000000","0.17008000"]]}}
{"stream":"btcusdt@depth@100ms","data":{"e":"depthUpdate","E":1790299059314,"s":"BTCUSDT","U":100639378744,"u":100639378745,"b":[["76261.86000000","0.00360000"]],"a":[]}}
{"stream":"dogeusdt@depth@100ms","data":{"e":"depthUpdate","E":1790299059374,"s":"DOGEUSDT","U":25516668806,"u":25516668810,"b":[],"a":[["0.09678000","20931.00000000"],["0.09682000","245739.00000000"],["0.09683000","177695.00000000"]]}}
{"stream":"btcusdt@depth@100ms","data":{"e":"depthUpdate","E":1790299059414,"s":"BTCUSDT","U":100639378746,"u":100639378752,"b":[["84721.04000000","0.00006000"],["84593.93000000","0.01200000"],["83464.36000000","0.00024000"],["67788.32000000","0.00203000"]],"a":[["84754.94000000","0.00006000"]]}}
{"stream":"dogeusdt@depth@100ms","data":{"e":"depthUpdate","E":1790299059474,"s":"DOGEUSDT","U":25516668811,"u":25516668812,"b":[],"a":[["0.09678000","41559.00000000"],["0.09713000","19341.00000000"]]}}
{"stream":"btcusdt@depth@100ms","data":{"e":"depthUpdate","E":1790299059514,"s":"BTCUSDT","U":100639378753,"u":100639378774,"b":[["84735.39000000","2.47238000"],["84727.63000000","0.00000000"],["84726.74000000","0.00400000"],["84724.85000000","0.00200000"],["83464.36000000","0.00016000"],["76261.86000000","0.00360000"],["67788.32000000","0.00319000"],["67788.31000000","0.00000000"]],"a":[["84735.40000000","1.16602000"],["84757.71000000","0.01967000"]]}}
{"stream":"dogeusdt@depth@100ms","data":{"e":"depthUpdate","E":1790299059574,"s":"DOGEUSDT","U":25516668813,"u":25516668816,"b":[["0.09674000","373911.00000000"],["0.09633000","223434.00000000"],["0.09629000","446.00000000"]],"a":[["0.09679000","32758.00000000"],["0.09680000","71257.00000000"]]}}
{"stream":"btcusdt@depth@100ms","data":{"e":"depthUpdate","E":1790299059614,"s":"BTCUSDT","U":100639378775,"u":100639378807,"b":[["84735.39000000","2.46961000"],["84735.38000000","0.00123000"],["84734.11000000","0.00236000"],["84730.36000000","0.00000000"],["84729.35000000","0.00200000"],["84726.74000000","0.00200000"],["84725.18000000","0.00000000"],["84724.28000000","0.00200000"],["84724.25000000","0.00200000"],["84721.78000000","0.88514000"],["84708.94000000","0.00000000"],["84706.87000000","0.00200000"],["83464.36000000","0.00024000"],["67788.32000000","0.00290000"],["64000.00000000","56.35235000"]],"a":[["84735.40000000","1.64912000"],["84735.41000000","0.00081000"],["84738.64000000","0.00000000"],["84738.67000000","0.00000000"],["84738.68000000","0.00006000"],["84739.53000000","0.00014000"],["84740.23000000","0.00007000"],["84742.39000000","0.00000000"],["84746.67000000","0.01089000"],["84749.08000000","0.00000000"],["84757.71000000","0.00000000"]]}}
{"stream":"dogeusdt@depth@100ms","data":{"e":"depthUpdate","E":1790299059674,"s":"DOGEUSDT","U":25516668817,"u":25516668821,"b":[],"a":[["0.09678000","62125.00000000"],["0.09679000","39638.00000000"],["0.09680000","71235.00000000"]]}}
{"stream":"btcusdt@depth@100ms","data":{"e":"depthUpdate","E":1790299059714,"s":"BTCUSDT","U":100639378808,"u":100639378887,"b":[["84735.39000000","1.78925000"],["84735.38000000","0.00116000"],["84735.37000000","0.95287000"],["84734.34000000","0.00000000"],["84734.11000000","0.00000000"],["84734.03000000","0.01693000"],["84732.76000000","0.00236000"],["84732.75000000","0.00014000"],["84732.74000000","0.34492000"],["84732.67000000","0.02042000"],["84732.36000000","0.02000000"],["84731.06000000","0.00236000"],["84730.41000000","0.00000000"],["84730.12000000","0.00236000"],["84729.35000000","0.00000000"],["84728.47000000","0.01129000"],["84726.74000000","0.00000000"],["84725.60000000","0.00048000"],["84724.85000000","0.00000000"],["84724.25000000","0.00000000"],["84723.22000000","0.00400000"],["84706.87000000","0.00000000"],["84526.01000000","0.00000000"],["84524.01000000","0.00734000"],["83464.36000000","0.00024000"],["83464.35000000","0.00000000"],["76261.86000000","0.00360000"]],"a":[["84735.40000000","2.01870000"],["84735.41000000","0.00074000"],["84736.73000000","0.00000000"],["84736.76000000","0.00014000"],["84736.77000000","0.00006000"],["84738.47000000","0.00007000"],["84738.81000000","0.00012000"],["84738.91000000","0.03320000"],["84738.96000000","0.00013000"],["84739.04000000","0.00000000"],["84739.05000000","0.00000000"],["84740.65000000","0.11780000"],["84740.99000000","0.00006000"],["84742.39000000","0.00000000"],["84743.87000000","0.01871000"],["84743.88000000","0.00000000"],["84746.21000000","0.00236000"],["84748.60000000","0.00000000"],["84749.00000000","0.00034000"],["84749.08000000","0.18001000"]]}}
{"stream":"btcusdt@depth@100ms","data":{"e":"depthUpdate","E":1790299059814,"s":"BTCUSDT","U":100639378888,"u":100639378906,"b":[["84731.19000000","0.00000000"],["84728.65000000","0.00590000"],["84720.81000000","0.00000000"],["83464.35000000","0.00030000"],["76261.86000000","0.00345000"],["67788.32000000","0.00261000"],["67788.00000000","0.00300000"]],"a":[["84735.40000000","2.01858000"],["84736.76000000","0.00000000"],["84740.23000000","0.00014000"],["84740.64000000","0.00407000"],["84756.62000000","0.11999000"],["84760.74000000","0.00000000"],["84866.24000000","0.00000000"]]}}
{"stream":"btcusdt@depth@100ms","data":{"e":"depthUpdate","E":1790299059914,"s":"BTCUSDT","U":100639378907,"u":100639378924,"b":[["84735.39000000","1.78918000"],["84735.38000000","0.00116000"],["84731.24000000","0.01135000"],["84730.12000000","0.00000000"],["84730.11000000","0.00236000"],["84723.22000000","0.00800000"],["83464.36000000","0.00024000"]],"a":[["84735.40000000","2.01851000"],["84735.41000000","0.00067000"],["84869.70000000","0.00031000"]]}}
{"stream":"btcusdt@depth@100ms","data":{"e":"depthUpdate","E":1790299060014,"s":"BTCUSDT","U":100639378925,"u":100639378953,"b":[["84735.39000000","1.78911000"],["84735.38000000","0.00116000"],["84733.19000000","0.00000000"],["84730.11000000","0.00000000"],["84730.09000000","0.00236000"],["84728.85000000","0.00200000"],["84728.23000000","0.00200000"],["84722.55000000","0.00200000"],["84705.12000000","0.00200000"],["84682.57000000","0.00354000"],["83464.36000000","0.00016000"],["77944.04000000","0.00013000"],["76261.86000000","0.00345000"],["67788.32000000","0.00232000"],["67788.31000000","0.00000000"],["67788.00000000","0.00400000"]],"a":[["84735.40000000","2.01864000"],["84738.49000000","0.00014000"],["84738.50000000","0.01109000"],["84740.64000000","0.00400000"],["84869.67000000","0.06797000"],["86006.44000000","0.00030000"]]}}
{"stream":"dogeusdt@depth@100ms","data":{"e":"depthUpdate","E":1790299060074,"s":"DOGEUSDT","U":25516668822,"u":25516668828,"b":[["0.09677000","134584.00000000"],["0.09676000","86744.00000000"],["0.09674000","373922.00000000"]],"a":[["0.09679000","39649.00000000"],["0.09680000","93170.00000000"],["0.09681000","200456.00000000"],["0.09700000","1414298.00000000"]]}}
{"stream":"btcusdt@depth@100ms","data":{"e":"depthUpdate","E":1790299060114,"s":"BTCUSDT","U":100639378954,"u":100639378972,"b":[["84735.39000000","1.78918000"],["84735.38000000","0.00123000"],["84735.14000000","0.00328000"],["84730.09000000","0.00000000"],["84730.08000000","0.00236000"],["83464.36000000","0.00024000"],["76261.00000000","0.00000000"],["67788.00000000","0.00300000"]],"a":[["84735.40000000","2.01864000"],["84735.41000000","0.00074000"],["84742.39000000","0.17483000"],["84772.44000000","0.00400000"],["84774.56000000","0.00000000"],["84824.36000000","1.57930000"],["84825.55000000","0.79836000"],["84827.15000000","0.00020000"],["84869.67000000","0.00000000"]]}}
{"stream":"dogeusdt@depth@100ms","data":{"e":"depthUpdate","E":1790299060174,"s":"DOGEUSDT","U":25516668829,"u":25516668829,"b":[],"a":[["0.09679000","45311.00000000"]]}}
{"stream":"btcusdt@depth@100ms","data":{"e":"depthUpdate","E":1790299060214,"s":"BTCUSDT","U":100639378973,"u":100639379010,"b":[["84735.39000000","1.60215000"],["84735.38000000","0.00116000"],["84735.37000000","0.95281000"],["84735.17000000","0.00000000"],["84731.18000000","0.00000000"],["84730.08000000","0.00000000"],["84729.25000000","0.00006000"],["84728.23000000","0.00000000"],["84727.03000000","0.00590000"],["84724.28000000","0.00000000"],["84723.23000000","0.00200000"],["84723.22000000","0.00200000"],["84722.41000000","0.00200000"],["84720.83000000","0.03694000"],["83464.36000000","0.00024000"],["76261.86000000","0.00345000"],["76261.85000000","0.00008000"],["67788.32000000","0.00203000"]],"a":[["84735.40000000","1.93855000"],["84740.65000000","0.11561000"],["84742.39000000","0.00000000"],["84744.15000000","0.18001000"],["84749.08000000","0.18001000"],["84749.09000000","0.00400000"],["84756.74000000","0.00383000"],["84866.20000000","0.03666000"]]}}
{"stream":"btcusdt@depth@100ms","data":{"e":"depthUpdate","E":1790299060314,"s":"BTCUSDT","U":100639379011,"u":100639379020,"b":[["84735.37000000","0.95287000"],["84734.12000000","0.01083000"],["84723.23000000","0.00000000"],["84722.15000000","0.00200000"],["67788.00000000","0.00300000"]],"a":[["84747.24000000","0.00200000"],["84749.11000000","0.00200000"],["84750.45000000","0.02000000"],["84758.98000000","0.00000000"]]}}
{"stream":"dogeusdt@depth@100ms","data":{"e":"depthUpdate","E":1790299060374,"s":"DOGEUSDT","U":25516668830,"u":25516668834,"b":[["0.09677000","134573.00000000"],["0.09638000","118523.00000000"]],"a":[["0.09678000","60633.00000000"],["0.09679000","39649.00000000"],["0.09680000","71235.00000000"]]}}
{"stream":"btcusdt@depth@100ms","data":{"e":"depthUpdate","E":1790299060414,"s":"BTCUSDT","U":100639379021,"u":100639379066,"b":[["84735.39000000","1.65642000"],["84735.38000000","0.00123000"],["84731.06000000","0.00000000"],["84729.26000000","0.00236000"],["84728.16000000","0.00200000"],["84723.22000000","0.00600000"],["84721.04000000","0.00006000"],["84719.02000000","0.30217000"],["84709.15000000","0.00000000"],["84593.93000000","0.00000000"],["83464.36000000","0.00024000"],["76261.86000000","0.00345000"],["67788.32000000","0.00174000"]],"a":[["84735.40000000","1.93876000"],["84735.41000000","0.00067000"],["84738.49000000","0.00000000"],["84738.50000000","0.00000000"],["84740.64000000","0.00407000"],["84740.65000000","0.07095000"],["84744.15000000","0.00000000"],["84747.24000000","0.00000000"],["84747.59000000","0.00000000"],["84748.56000000","0.00790000"],["84749.08000000","0.16977000"],["84754.94000000","0.00006000"]]}}
{"stream":"btcusdt@depth@100ms","data":{"e":"depthUpdate","E":1790299060514,"s":"BTCUSDT","U":100639379067,"u":100639379092,"b":[["84735.39000000","1.60239000"],["84732.76000000","0.00000000"],["84731.36000000","0.00236000"],["84728.16000000","0.00000000"],["84723.22000000","0.00200000"],["84722.51000000","0.00944000"],["84711.76000000","0.00000000"],["83464.36000000","0.00016000"],["77944.04000000","0.00000000"],["76261.86000000","0.00330000"],["67788.32000000","0.00290000"]],"a":[["84735.40000000","1.93876000"],["84740.65000000","0.11561000"],["84744.15000000","0.18001000"],["84744.93000000","0.00012000"],["84745.59000000","0.00010000"]]}}
{"stream":"dogeusdt@depth@100ms","data":{"e":"depthUpdate","E":1790299060574,"s":"DOGEUSDT","U":25516668835,"u":25516668835,"b":[["0.09633000","99070.00000000"],["0.09629000","124861.00000000"]],"a":[]}}
{"stream":"btcusdt@depth@100ms","data":{"e":"depthUpdate","E":1790299060614,"s":"BTCUSDT","U":100639379093,"u":100639379101,"b":[["84735.39000000","1.65989000"],["83464.36000000","0.00024000"],["76261.86000000","0.00345000"],["67788.32000000","0.00261000"],["67788.31000000","0.00000000"],["67788.00000000","0.00300000"]],"a":[["84745.59000000","0.00000000"]]}}
{"stream":"btcusdt@depth@100ms","data":{"e":"depthUpdate","E":1790299060714,"s":"BTCUSDT","U":100639379102,"u":100639379111,"b":[["83464.36000000","0.00024000"],["76261.86000000","0.00345000"]],"a":[["84735.40000000","1.93876000"],["84745.59000000","0.00010000"],["84866.20000000","0.06805000"]]}}
{"stream":"dogeusdt@depth@100ms","data":{"e":"depthUpdate","E":1790299060774,"s":"DOGEUSDT","U":25516668836,"u":25516668836,"b":[],"a":[["0.09681000","220885.00000000"]]}}
{"stream":"btcusdt@depth@100ms","data":{"e":"depthUpdate","E":1790299060814,"s":"BTCUSDT","U":100639379112,"u":100639379119,"b":[["84735.39000000","1.65982000"],["84735.38000000","0.00116000"],["84722.66000000","0.00400000"],["83464.35000000","0.00030000"],["67788.32000000","0.00232000"]],"a":[["84749.08000000","0.00000000"]]}}
{"stream":"btcusdt@depth@100ms","data":{"e":"depthUpdate","E":1790299060914,"s":"BTCUSDT","U":100639379120,"u":100639379143,"b":[["84735.39000000","1.60232000"],["84727.55000000","0.00000000"],["84722.66000000","0.00000000"],["83464.36000000","0.00024000"],["76261.86000000","0.00345000"]],"a":[["84735.40000000","1.93883000"],["84740.65000000","0.11567000"],["84741.37000000","0.00590000"],["84742.39000000","0.00000000"],["84747.59000000","0.00400000"],["84749.08000000","0.18001000"],["84749.09000000","0.00000000"],["84756.74000000","0.00006000"],["84762.50000000","0.00200000"],["84766.05000000","0.00000000"],["84799.12000000","0.00000000"],["84833.03000000","0.00000000"]]}}
{"stream":"btcusdt@depth@100ms","data":{"e":"depthUpdate","E":1790299061014,"s":"BTCUSDT","U":100639379144,"u":100639379157,"b":[["84735.39000000","1.60083000"],["83464.36000000","0.00016000"],["67788.32000000","0.00319000"],["67788.31000000","0.00000000"]],"a":[["84770.83000000","0.66166000"],["84774.00000000","0.72000000"],["84775.00000000","0.00000000"],["86006.44000000","0.00030000"]]}}
{"stream":"btcusdt@depth@100ms","data":{"e":"depthUpdate","E":1790299061114,"s":"BTCUSDT","U":100639379158,"u":100639379204,"b":[["84735.39000000","1.78720000"],["84735.38000000","0.00116000"],["84735.14000000","0.00000000"],["84726.74000000","0.35516000"],["84725.60000000","0.00000000"],["84723.21000000","0.00000000"],["84716.73000000","0.35516000"],["84714.72000000","0.00000000"],["84490.43000000","0.01848000"],["84482.99000000","0.00000000"],["83464.36000000","0.00024000"],["76261.86000000","0.00345000"]],"a":[["84735.40000000","2.06370000"],["84735.41000000","0.00074000"],["84738.55000000","0.00190000"],["84740.47000000","0.00000000"],["84740.65000000","0.07101000"],["84743.87000000","0.01871000"],["84743.88000000","0.00000000"],["84744.15000000","0.00000000"],["84747.59000000","0.00200000"],["84748.55000000","0.00000000"],["84749.07000000","0.00000000"],["84749.08000000","0.00000000"],["84749.10000000","0.18001000"],["84762.50000000","0.00000000"]]}}
{"stream":"dogeusdt@depth@100ms","data":{"e":"depthUpdate","E":1790299061174,"s":"DOGEUSDT","U":25516668837,"u":25516668842,"b":[["0.09675000","141236.00000000"],["0.09667000","98558.00000000"],["0.09663000","286544.00000000"]],"a":[]}}
{"stream":"btcusdt@depth@100ms","data":{"e":"depthUpdate","E":1790299061214,"s":"BTCUSDT","U":100639379205,"u":100639379214,"b":[["84735.39000000","1.78705000"],["84722.41000000","0.00600000"],["83464.36000000","0.00024000"],["76261.86000000","0.00330000"],["67788.32000000","0.00290000"]],"a":[["84735.40000000","2.06383000"],["84749.92000000","0.02000000"],["84828.55000000","0.00377000"]]}}
{"stream":"dogeusdt@depth@100ms","data":{"e":"depthUpdate","E":1790299061274,"s":"DOGEUSDT","U":25516668843,"u":25516668846,"b":[],"a":[["0.09679000","31649.00000000"],["0.09680000","79235.00000000"],["0.09685000","144500.00000000"],["0.09707000","82512.00000000"]]}}
{"stream":"btcusdt@depth@100ms","data":{"e":"depthUpdate","E":1790299061314,"s":"BTCUSDT","U":100639379215,"u":100639379219,"b":[["84730.79000000","0.00236000"],["84727.42000000","0.00200000"],["76261.86000000","0.00345000"]],"a":[["84740.45000000","0.00024000"],["84758.94000000","0.00000000"]]}}
{"stream":"btcusdt@depth@100ms","data":{"e":"depthUpdate","E":1790299061414,"s":"BTCUSDT","U":100639379220,"u":100639379235,"b":[["84730.79000000","0.00000000"],["84730.77000000","0.00236000"],["84598.23000000","0.01200000"],["83464.36000000","0.00024000"],["76261.86000000","0.00345000"],["76261.85000000","0.00000000"],["76261.84000000","0.00008000"],["76261.00000000","0.00000000"],["67788.32000000","0.00261000"]],"a":[["84735.40000000","2.06059000"],["84747.59000000","0.00400000"],["84760.21000000","0.01967000"],["84762.65000000","0.00200000"],["84794.65000000","0.00377000"]]}}
{"stream":"dogeusdt@depth@100ms","data":{"e":"depthUpdate","E":1790299061475,"s":"DOGEUSDT","U":25516668847,"u":25516668848,"b":[["0.09677000","134584.00000000"]],"a":[["0.09678000","41559.00000000"]]}}
{"stream":"btcusdt@depth@100ms","data":{"e":"depthUpdate","E":1790299061514,"s":"BTCUSDT","U":100639379236,"u":100639379251,"b":[["84735.39000000","1.78846000"],["84730.77000000","0.00000000"],["84730.75000000","0.00248000"],["84721.04000000","0.00006000"],["84223.55000000","0.00000000"],["83464.36000000","0.00016000"],["67788.00000000","0.00300000"]],"a":[["84735.40000000","2.05376000"],["84738.55000000","0.00000000"],["84754.94000000","0.00006000"],["84760.21000000","0.00000000"],["88123.00000000","0.14444000"]]}}
{"stream":"btcusdt@depth@100ms","data":{"e":"depthUpdate","E":1790299061614,"s":"BTCUSDT","U":100639379252,"u":100639379261,"b":[["84735.39000000","1.60249000"],["84727.42000000","0.00000000"],["83464.36000000","0.00024000"],["76261.86000000","0.00345000"],["67788.32000000","0.00232000"],["67788.31000000","0.00000000"]],"a":[["84735.40000000","2.05369000"],["84735.41000000","0.00067000"]]}}
{"stream":"btcusdt@depth@100ms","data":{"e":"depthUpdate","E":1790299061714,"s":"BTCUSDT","U":100639379262,"u":100639379279,"b":[["84735.39000000","1.67004000"],["84730.75000000","0.00012000"],["84730.73000000","0.00000000"],["84730.71000000","0.00236000"],["84728.07000000","0.00200000"],["83842.83000000","0.00597000"],["83464.36000000","0.00024000"]],"a":[["84747.24000000","0.00000000"]]}}
{"stream":"btcusdt@depth@100ms","data":{"e":"depthUpdate","E":1790299061814,"s":"BTCUSDT","U":100639379280,"u":100639379357,"b":[["84735.39000000","2.03468000"],["84735.38000000","0.00095000"],["84734.62000000","0.02994000"],["84732.74000000","0.00000000"],["84732.36000000","0.00000000"],["84730.71000000","0.00000000"],["84729.84000000","0.00236000"],["84728.07000000","0.00000000"],["84726.75000000","0.00600000"],["84722.55000000","0.00000000"],["84722.41000000","0.00000000"],["84722.15000000","0.00000000"],["84707.45000000","0.00200000"],["84705.12000000","0.00000000"],["83464.35000000","0.00030000"],["76261.86000000","0.00345000"],["67788.32000000","0.00203000"]],"a":[["84735.40000000","1.20052000"],["84738.81000000","0.00006000"],["84738.91000000","0.00000000"],["84740.45000000","0.00000000"],["84740.56000000","0.00316000"],["84740.60000000","0.01580000"],["84740.65000000","0.00006000"],["84742.39000000","0.00000000"],["84742.84000000","0.00006000"],["84743.87000000","0.00000000"],["84743.88000000","0.00068000"],["84744.15000000","0.18001000"],["84744.93000000","0.18013000"],["84745.59000000","0.00000000"],["84746.21000000","0.00000000"],["84746.87000000","0.00006000"],["84747.59000000","0.00200000"],["84747.86000000","0.16377000"],["84748.56000000","0.00000000"],["84749.00000000","0.00024000"],["84749.11000000","0.00000000"],["84749.12000000","0.00407000"],["84750.15000000","0.00000000"],["84750.90000000","0.00006000"],["84754.93000000","0.00006000"],["84756.30000000","0.35516000"],["84756.62000000","0.11799000"],["84759.50000000","0.00000000"],["84760.43000000","0.00000000"],["84764.79000000","0.35516000"],["84766.38000000","0.00000000"],["84824.36000000","0.00000000"],["84827.15000000","1.57950000"]]}}
{"stream":"dogeusdt@depth@100ms","data":{"e":"depthUpdate","E":1790299061874,"s":"DOGEUSDT","U":25516668849,"u":25516668889,"b":[["0.09677000","137761.00000000"],["0.09676000","99449.00000000"],["0.09675000","137891.00000000"],["0.09672000","69252.00000000"]],"a":[["0.09678000","18121.00000000"],["0.09679000","24769.00000000"],["0.09680000","60650.00000000"],["0.09681000","200456.00000000"],["0.09682000","240739.00000000"],["0.09683000","182695.00000000"],["0.09684000","197459.00000000"],["0.09685000","163107.00000000"]]}}
{"stream":"btcusdt@depth@100ms","data":{"e":"depthUpdate","E":1790299061914,"s":"BTCUSDT","U":100639379358,"u":100639379457,"b":[["84735.39000000","1.69031000"],["84735.38000000","0.00102000"],["84735.37000000","0.95293000"],["84734.03000000","0.01693000"],["84732.75000000","0.00014000"],["84732.74000000","0.34492000"],["84732.67000000","0.02036000"],["84731.24000000","0.01141000"],["84726.75000000","0.00400000"],["84725.52000000","0.00000000"],["84724.14000000","0.00000000"],["84707.45000000","0.00000000"],["83464.36000000","0.00024000"],["76261.86000000","0.00330000"]],"a":[["84735.40000000","0.91514000"],["84735.41000000","0.00067000"],["84737.68000000","0.00000000"],["84738.68000000","0.00000000"],["84738.90000000","0.00000000"],["84739.13000000","0.00014000"],["84739.14000000","0.03885000"],["84739.75000000","0.00006000"],["84740.24000000","0.03031000"],["84740.59000000","0.00014000"],["84740.64000000","0.00400000"],["84742.37000000","0.18001000"],["84742.38000000","0.11465000"],["84742.39000000","0.00000000"],["84744.92000000","0.00590000"],["84744.93000000","0.00012000"],["84744.94000000","0.11432000"],["84745.59000000","0.00190000"],["84745.93000000","0.00236000"],["84747.59000000","0.00000000"],["84747.86000000","0.00000000"],["84748.98000000","0.00200000"],["84749.08000000","0.18001000"],["84749.09000000","0.00600000"],["84749.10000000","0.00000000"],["84749.12000000","0.05992000"],["84759.16000000","0.08325000"],["84762.65000000","0.00000000"],["84825.55000000","1.16883000"]]}}
{"stream":"dogeusdt@depth@100ms","data":{"e":"depthUpdate","E":1790299061974,"s":"DOGEUSDT","U":25516668890,"u":25516668898,"b":[["0.09677000","145761.00000000"]],"a":[["0.09678000","97.00000000"],["0.09679000","24707.00000000"],["0.09682000","238739.00000000"],["0.09683000","184695.00000000"],["0.09706000","1461496.00000000"],["0.09712000","181889.00000000"]]}}
{"stream":"btcusdt@depth@100ms","data":{"e":"depthUpdate","E":1790299062014,"s":"BTCUSDT","U":100639379458,"u":100639379557,"b":[["84735.39000000","2.03759000"],["84734.03000000","0.01687000"],["84733.30000000","0.00236000"],["84732.75000000","0.00000000"],["84732.74000000","0.00014000"],["84731.36000000","0.00000000"],["84729.26000000","0.00000000"],["84725.34000000","0.00188000"],["84725.17000000","0.00000000"],["84721.32000000","0.00013000"],["83464.36000000","0.00016000"],["82386.87000000","0.00000000"],["76261.86000000","0.00345000"],["67788.32000000","0.00290000"],["67788.31000000","0.00000000"]],"a":[["84735.40000000","0.91478000"],["84735.41000000","0.00074000"],["84738.26000000","0.00204000"],["84738.27000000","0.05384000"],["84738.28000000","0.10462000"],["84738.81000000","0.00012000"],["84739.13000000","0.00000000"],["84739.14000000","0.00014000"],["84739.15000000","0.03540000"],["84739.53000000","0.00000000"],["84739.54000000","0.00006000"],["84740.24000000","0.03025000"],["84740.48000000","0.00024000"],["84740.56000000","0.00000000"],["84740.59000000","0.00000000"],["84740.60000000","0.00000000"],["84740.65000000","0.00000000"],["84740.99000000","0.00000000"],["84741.37000000","0.00000000"],["84741.71000000","0.00000000"],["84741.72000000","0.00006000"],["84742.36000000","0.00007000"],["84742.84000000","0.00012000"],["84744.54000000","0.00000000"],["84744.92000000","0.00000000"],["84744.94000000","0.15894000"],["84745.65000000","0.00047000"],["84745.93000000","0.00000000"],["84746.75000000","0.00236000"],["84746.87000000","0.00012000"],["84747.24000000","0.00590000"],["84747.44000000","0.00590000"],["84749.07000000","0.00200000"],["84750.90000000","0.00012000"],["84754.93000000","0.00012000"],["84759.50000000","0.10652000"],["84774.00000000","0.02000000"],["84984.99000000","0.00000000"],["86006.44000000","0.00030000"],["89076.24000000","0.00000000"]]}}
{"stream":"dogeusdt@depth@100ms","data":{"e":"depthUpdate","E":1790299062074,"s":"DOGEUSDT","U":25516668899,"u":25516668998,"b":[["0.09678000","110005.00000000"],["0.09677000","112558.00000000"],["0.09676000","87553.00000000"],["0.09675000","133310.00000000"],["0.09673000","323376.00000000"],["0.09666000","577048.00000000"],["0.09662000","300119.00000000"],["0.09659000","197113.00000000"],["0.09657000","517091.00000000"],["0.09649000","296210.00000000"],["0.09648000","122429.00000000"],["0.09647000","134.00000000"]],"a":[["0.09678000","0.00000000"],["0.09679000","23383.00000000"],["0.09680000","338.00000000"],["0.09681000","39942.00000000"],["0.09682000","154980.00000000"],["0.09683000","169654.00000000"],["0.09684000","204459.00000000"],["0.09685000","163211.00000000"],["0.09686000","154073.00000000"],["0.09687000","228182.00000000"],["0.09688000","261633.00000000"],["0.09694000","200218.00000000"],["0.09697000","250021.00000000"],["0.09703000","106426.00000000"],["0.09718000","118049.00000000"]]}}
{"stream":"btcusdt@depth@100ms","data":{"e":"depthUpdate","E":1790299062114,"s":"BTCUSDT","U":100639379558,"u":100639380695,"b":[["84742.38000000","3.92971000"],["84742.37000000","0.09266000"],["84742.36000000","0.00012000"],["84741.95000000","0.00000000"],["84741.94000000","0.00000000"],["84741.53000000","0.00000000"],["84741.00000000","0.02994000"],["84740.24000000","0.00000000"],["84740.23000000","0.00006000"],["84740.22000000","0.00000000"],["84739.14000000","0.00000000"],["84739.13000000","0.00000000"],["84738.81000000","0.00012000"],["84738.59000000","0.00000000"],["84738.52000000","0.00400000"],["84738.51000000","0.00000000"],["84738.45000000","0.00000000"],["84738.27000000","0.00000000"],["84738.26000000","0.19339000"],["84738.25000000","0.29136000"],["84738.24000000","0.00000000"],["84738.23000000","0.00000000"],["84738.16000000","0.00000000"],["84738.15000000","0.00006000"],["84738.14000000","0.15012000"],["84737.87000000","0.00024000"],["84737.09000000","0.00012000"],["84736.40000000","0.00400000"],["84736.36000000","0.00000000"],["84735.71000000","0.00000000"],["84735.61000000","0.11801000"],["84735.41000000","1.28842000"],["84735.40000000","1.31530000"],["84735.39000000","0.32587000"],["84735.38000000","0.00041000"],["84735.37000000","0.00012000"],["84734.97000000","0.00012000"],["84734.28000000","0.00400000"],["84734.03000000","0.00006000"],["84733.90000000","0.02461000"],["84733.60000000","0.03540000"],["84733.34000000","0.00006000"],["84733.30000000","0.00000000"],["84732.96000000","0.00012000"],["84732.74000000","0.00000000"],["84732.73000000","0.00000000"],["84732.72000000","0.00590000"],["84732.71000000","0.00021000"],["84732.70000000","0.00000000"],["84732.67000000","0.00006000"],["84732.16000000","0.00400000"],["84731.80000000","0.03006000"],["84731.62000000","0.00006000"],["84731.59000000","0.00000000"],["84731.36000000","0.00013000"],["84731.33000000","0.14333000"],["84731.32000000","0.00000000"],["84731.30000000","0.00000000"],["84731.24000000","0.01135000"],["84731.05000000","0.00000000"],["84730.98000000","0.00000000"],["84730.80000000","0.00008000"],["84730.21000000","0.00000000"],["84730.07000000","0.00166000"],["84729.84000000","0.00000000"],["84729.67000000","0.00000000"],["84729.25000000","0.00000000"],["84728.85000000","0.00000000"],["84728.72000000","0.00000000"],["84728.65000000","0.00000000"],["84728.64000000","0.00000000"],["84728.44000000","0.00000000"],["84728.23000000","0.00006000"],["84728.08000000","0.00007000"],["84727.99000000","0.29510000"],["84727.68000000","0.00000000"],["84727.57000000","1.21698000"],["84727.56000000","2.12425000"],["84727.03000000","0.00000000"],["84726.92000000","0.00000000"],["84726.76000000","0.00000000"],["84726.75000000","0.00000000"],["84726.73000000","0.00000000"],["84726.60000000","0.00012000"],["84726.14000000","0.00000000"],["84725.55000000","0.08893000"],["84725.30000000","0.00000000"],["84724.49000000","0.35418000"],["84724.45000000","0.00000000"],["84724.27000000","0.00000000"],["84724.24000000","0.00000000"],["84724.22000000","0.11803000"],["84723.22000000","0.00000000"],["84723.21000000","0.00000000"],["84723.20000000","0.12000000"],["84723.18000000","0.00006000"],["84722.65000000","0.00000000"],["84722.02000000","0.31877000"],["84721.63000000","0.00000000"],["84721.49000000","0.00000000"],["84721.45000000","0.00000000"],["84721.32000000","0.00000000"],["84721.19000000","0.00007000"],["84720.13000000","0.00000000"],["84719.45000000","0.00171000"],["84718.95000000","0.00000000"],["84718.65000000","0.00006000"],["84718.06000000","0.00000000"],["84717.86000000","0.00000000"],["84716.96000000","0.00007000"],["84715.59000000","0.00000000"],["84714.48000000","0.00000000"],["84713.09000000","0.00000000"],["84712.91000000","0.58119000"],["84712.72000000","0.00007000"],["84712.45000000","0.58081000"],["84711.48000000","0.00000000"],["84711.36000000","0.00000000"],["84708.48000000","0.00007000"],["84707.12000000","0.00000000"],["84706.72000000","0.00400000"],["84706.60000000","0.00000000"],["84704.60000000","0.00000000"],["84704.40000000","0.00000000"],["84704.25000000","0.00012000"],["84704.24000000","0.00007000"],["84702.88000000","0.00000000"],["84702.48000000","0.00000000"],["84702.28000000","0.86792000"],["84702.20000000","0.00000000"],["84700.36000000","0.00000000"],["84700.01000000","0.00007000"],["84698.98000000","0.59859000"],["84698.65000000","0.00000000"],["84698.59000000","0.00000000"],["84698.51000000","0.00000000"],["84698.35000000","0.02336000"],["84698.24000000","0.00158000"],["84698.05000000","0.00000000"],["84696.33000000","0.00000000"],["84696.26000000","0.00012000"],["84695.77000000","0.00007000"],["84694.48000000","0.00000000"],["84694.41000000","0.00000000"],["84694.08000000","0.00000000"],["84693.73000000","0.00000000"],["84693.00000000","0.00000000"],["84691.53000000","0.00018000"],["84690.17000000","0.00000000"],["84690.12000000","0.00000000"],["84684.57000000","0.73701000"],["84684.46000000","0.00000000"],["84683.65000000","0.00000000"],["84682.57000000","0.00000000"],["84676.81000000","0.00006000"],["84675.66000000","0.28485000"],["84675.65000000","0.00000000"],["84675.15000000","0.00000000"],["84675.14000000","0.00000000"],["84674.67000000","0.15000000"],["84673.46000000","0.00000000"],["84670.94000000","0.00000000"],["84670.16000000","0.73714000"],["84670.13000000","3.87405000"],["84669.45000000","0.00294000"],["84668.96000000","0.00294000"],["84666.81000000","1.31647000"],["84665.62000000","2.35711000"],["84662.22000000","0.00000000"],["84662.01000000","0.00000000"],["84654.07000000","0.00000000"],["84649.08000000","0.00000000"],["84646.31000000","0.00000000"],["84639.75000000","0.00000000"],["84638.01000000","0.39353000"],["84637.36000000","0.00000000"],["84635.11000000","0.00000000"],["84634.26000000","0.00000000"],["84630.32000000","0.94159000"],["84626.67000000","0.00000000"],["84621.88000000","0.04566000"],["84613.09000000","0.41643000"],["84611.98000000","0.00000000"],["84598.23000000","0.00000000"],["84593.45000000","0.00000000"],["84570.28000000","0.00000000"],["84564.42000000","1.20000000"],["84543.86000000","0.00000000"],["84470.25000000","0.00000000"],["84466.02000000","0.00000000"],["84397.80000000","0.00000000"],["84388.47000000","0.00009000"],["84380.68000000","0.02380000"],["84380.32000000","0.00501000"],["84318.63000000","0.00000000"],["84307.01000000","0.00000000"],["84305.33000000","0.00000000"],["84305.17000000","0.00000000"],["83464.36000000","0.00000000"],["83464.35000000","0.00000000"],["76268.15000000","0.00015000"],["76261.86000000","0.00000000"],["76261.84000000","0.00000000"]],"a":[["84735.40000000","0.00000000"],["84735.41000000","0.00000000"],["84735.42000000","0.00000000"],["84735.72000000","0.00000000"],["84736.53000000","0.00000000"],["84736.77000000","0.00000000"],["84737.34000000","0.00000000"],["84738.07000000","0.00000000"],["84738.15000000","0.00000000"],["84738.26000000","0.00000000"],["84738.27000000","0.00000000"],["84738.28000000","0.00000000"],["84738.47000000","0.00000000"],["84738.52000000","0.00000000"],["84738.60000000","0.00000000"],["84738.81000000","0.00000000"],["84738.96000000","0.00000000"],["84739.14000000","0.00000000"],["84739.15000000","0.00000000"],["84739.20000000","0.00000000"],["84739.54000000","0.00000000"],["84739.75000000","0.00000000"],["84739.77000000","0.00000000"],["84740.11000000","0.00000000"],["84740.23000000","0.00000000"],["84740.24000000","0.00000000"],["84740.48000000","0.00000000"],["84740.58000000","0.00000000"],["84740.64000000","0.00000000"],["84740.69000000","0.00000000"],["84740.74000000","0.00000000"],["84741.07000000","0.00000000"],["84741.39000000","0.00000000"],["84741.54000000","0.00000000"],["84741.72000000","0.00000000"],["84741.79000000","0.00000000"],["84741.95000000","0.00000000"],["84742.20000000","0.00000000"],["84742.33000000","0.00000000"],["84742.36000000","0.00000000"],["84742.37000000","0.00000000"],["84742.38000000","0.00000000"],["84742.39000000","0.15043000"],["84742.40000000","0.04270000"],["84742.76000000","0.00000000"],["84742.81000000","0.00000000"],["84742.84000000","0.00006000"],["84742.90000000","0.00000000"],["84743.01000000","0.00000000"],["84743.19000000","0.00000000"],["84743.30000000","0.00000000"],["84743.31000000","0.00000000"],["84743.50000000","0.00000000"],["84743.86000000","0.00007000"],["84743.88000000","0.00000000"],["84744.15000000","0.00000000"],["84744.16000000","0.00000000"],["84744.26000000","0.00006000"],["84744.31000000","0.00000000"],["84744.61000000","0.00000000"],["84744.84000000","0.00014000"],["84744.85000000","0.04000000"],["84744.93000000","0.00000000"],["84744.94000000","0.00000000"],["84745.07000000","0.00014000"],["84745.08000000","0.08806000"],["84745.15000000","0.00000000"],["84745.18000000","0.00000000"],["84745.22000000","0.00000000"],["84745.24000000","0.00000000"],["84745.59000000","0.00000000"],["84745.60000000","0.00000000"],["84745.61000000","0.00006000"],["84745.65000000","0.00000000"],["84745.86000000","0.00000000"],["84745.95000000","0.00000000"],["84746.19000000","0.00000000"],["84746.30000000","0.00000000"],["84746.62000000","0.00000000"],["84746.63000000","0.00000000"],["84746.67000000","0.00000000"],["84746.73000000","0.00000000"],["84746.74000000","0.00000000"],["84746.75000000","0.00000000"],["84746.87000000","0.00006000"],["84746.94000000","0.00006000"],["84747.16000000","0.00000000"],["84747.24000000","0.00000000"],["84747.44000000","0.00000000"],["84747.48000000","0.00000000"],["84747.72000000","0.00014000"],["84747.73000000","0.18005000"],["84747.86000000","0.00000000"],["84747.99000000","0.00000000"],["84748.93000000","0.00007000"],["84748.94000000","0.18000000"],["84748.98000000","0.00000000"],["84749.07000000","0.00000000"],["84749.08000000","0.00000000"],["84749.09000000","0.00000000"],["84749.11000000","0.00000000"],["84749.12000000","0.00407000"],["84749.13000000","0.16269000"],["84749.46000000","0.00000000"],["84749.47000000","0.00000000"],["84749.67000000","0.00000000"],["84749.92000000","0.00000000"],["84750.02000000","0.00000000"],["84750.23000000","0.00000000"],["84750.27000000","0.00000000"],["84750.34000000","0.02006000"],["84750.36000000","0.02006000"],["84750.45000000","0.00000000"],["84750.86000000","0.02007000"],["84750.87000000","0.00068000"],["84750.90000000","0.00006000"],["84751.18000000","0.00000000"],["84751.36000000","0.00000000"],["84751.96000000","0.00006000"],["84752.28000000","0.06127000"],["84752.93000000","0.00000000"],["84753.16000000","0.00000000"],["84753.27000000","0.00152000"],["84753.53000000","0.00000000"],["84753.66000000","0.00000000"],["84753.75000000","0.00000000"],["84753.90000000","0.00000000"],["84753.95000000","0.00000000"],["84754.14000000","0.00012000"],["84754.54000000","0.00000000"],["84755.09000000","0.00000000"],["84755.21000000","0.00007000"],["84755.35000000","0.00006000"],["84755.38000000","0.00000000"],["84755.42000000","0.01088000"],["84755.73000000","0.02000000"],["84755.82000000","0.00000000"],["84755.87000000","0.00000000"],["84755.90000000","0.00000000"],["84756.00000000","0.00008000"],["84756.08000000","0.00000000"],["84756.16000000","0.00012000"],["84756.29000000","0.00000000"],["84756.30000000","0.00000000"],["84756.58000000","0.00000000"],["84756.62000000","0.00000000"],["84756.67000000","0.00000000"],["84756.75000000","0.00000000"],["84756.77000000","0.00000000"],["84756.92000000","0.00000000"],["84757.05000000","0.00000000"],["84757.13000000","0.00000000"],["84757.19000000","0.00000000"],["84757.30000000","0.00236000"],["84757.61000000","0.00000000"],["84757.66000000","0.00590000"],["84757.96000000","0.00000000"],["84758.05000000","0.00000000"],["84758.06000000","0.00000000"],["84758.14000000","0.00000000"],["84758.26000000","0.00000000"],["84758.27000000","0.00012000"],["84758.59000000","0.00000000"],["84758.63000000","0.00000000"],["84758.76000000","0.00000000"],["84759.16000000","0.04776000"],["84759.18000000","0.00000000"],["84759.43000000","0.00000000"],["84759.44000000","0.00007000"],["84759.66000000","0.01084000"],["84759.71000000","0.00590000"],["84760.44000000","0.00200000"],["84760.81000000","0.00000000"],["84761.11000000","0.00000000"],["84761.31000000","0.00200000"],["84762.38000000","0.00000000"],["84762.39000000","0.00200000"],["84762.93000000","0.12000000"],["84762.97000000","0.11359000"],["84762.98000000","0.00000000"],["84763.20000000","0.00000000"],["84763.47000000","0.00000000"],["84763.68000000","0.00007000"],["84763.90000000","0.01112000"],["84764.11000000","0.00000000"],["84764.14000000","0.00000000"],["84766.61000000","0.00000000"],["84766.86000000","0.11797000"],["84767.92000000","0.00007000"],["84768.25000000","0.00000000"],["84768.91000000","0.29510000"],["84769.07000000","0.00000000"],["84769.24000000","0.05585000"],["84769.95000000","0.00000000"],["84770.35000000","0.00118000"],["84770.83000000","0.44252000"],["84770.84000000","0.00000000"],["84770.85000000","0.00000000"],["84771.43000000","0.29510000"],["84772.15000000","0.11797000"],["84772.16000000","0.00007000"],["84772.26000000","0.00000000"],["84773.99000000","0.00000000"],["84774.56000000","0.00400000"],["84774.86000000","0.00000000"],["84775.09000000","0.00000000"],["84775.93000000","0.00000000"],["84776.39000000","0.00007000"],["84776.68000000","0.00400000"],["84777.99000000","0.29510000"],["84778.00000000","0.00000000"],["84779.11000000","0.00012000"],["84780.17000000","0.00000000"],["84780.24000000","0.58992000"],["84780.43000000","0.00000000"],["84780.58000000","0.00000000"],["84780.63000000","0.00007000"],["84780.92000000","0.00400000"],["84781.00000000","0.00000000"],["84781.68000000","0.29510000"],["84782.01000000","0.00000000"],["84783.04000000","0.00400000"],["84783.14000000","0.00012000"],["84783.20000000","0.40770000"],["84783.61000000","0.00000000"],["84785.00000000","0.01000000"],["84786.59000000","0.38315000"],["84787.17000000","0.00006000"],["84787.65000000","0.92241000"],["84787.94000000","0.00000000"],["84788.45000000","0.31853000"],["84792.54000000","0.00425000"],["84796.92000000","0.00000000"],["84797.89000000","0.31849000"],["84798.38000000","0.00000000"],["84799.74000000","0.00000000"],["84803.28000000","0.01452000"],["84803.85000000","0.00268000"],["84804.53000000","0.00000000"],["84805.40000000","0.00000000"],["84807.27000000","0.00000000"],["84807.99000000","0.00000000"],["84811.99000000","0.00587000"],["84820.37000000","0.15000000"],["84825.55000000","0.79836000"],["84827.15000000","0.00020000"],["84839.17000000","0.00009000"],["84841.86000000","0.00006000"],["84851.04000000","0.00000000"],["84870.10000000","0.00007000"],["84871.58000000","2.12425000"],["84881.99000000","0.00000000"],["84891.98000000","0.00107000"],["84891.99000000","0.00000000"],["84897.87000000","0.00236000"],["84981.38000000","0.00006000"],["84985.61000000","0.00006000"],["85017.62000000","0.00000000"],["85081.50000000","0.00000000"],["85088.04000000","0.00009000"],["85162.53000000","0.00000000"],["85243.56000000","0.00000000"],["86006.44000000","0.00000000"]]}}
{"stream":"dogeusdt@depth@100ms","data":{"e":"depthUpdate","E":1790299062174,"s":"DOGEUSDT","U":25516668999,"u":25516669042,"b":[["0.09677000","112674.00000000"],["0.09674000","355315.00000000"],["0.09671000","275664.00000000"],["0.09667000","162092.00000000"],["0.09666000","579476.00000000"],["0.09664000","79155.00000000"],["0.09663000","212100.00000000"],["0.09662000","297687.00000000"],["0.09660000","161388.00000000"],["0.09659000","646643.00000000"],["0.09658000","339276.00000000"],["0.09657000","31542.00000000"],["0.09656000","342098.00000000"],["0.09642000","31762.00000000"],["0.09637000","543.00000000"],["0.09614000","41197.00000000"],["0.09608000","6550.00000000"],["0.09604000","647.00000000"],["0.09602000","598.00000000"],["0.09599000","74.00000000"]],"a":[["0.09679000","23372.00000000"],["0.09684000","197459.00000000"],["0.09685000","170211.00000000"],["0.09692000","169556.00000000"],["0.09693000","433533.00000000"],["0.09699000","565643.00000000"],["0.09716000","1946.00000000"],["0.09718000","118126.00000000"],["0.09754000","1475.00000000"]]}}
{"stream":"btcusdt@depth@100ms","data":{"e":"depthUpdate","E":1790299062214,"s":"BTCUSDT","U":100639380696,"u":100639381024,"b":[["84742.38000000","4.98632000"],["84742.37000000","0.09272000"],["84741.02000000","0.01713000"],["84741.00000000","0.03006000"],["84740.64000000","0.00400000"],["84740.54000000","0.00000000"],["84739.66000000","0.02056000"],["84738.82000000","0.00006000"],["84738.48000000","0.00007000"],["84738.31000000","0.02056000"],["84738.27000000","0.00400000"],["84738.26000000","0.11839000"],["84738.25000000","0.15136000"],["84738.14000000","0.16100000"],["84736.41000000","0.00200000"],["84735.42000000","0.00200000"],["84735.39000000","0.10917000"],["84732.72000000","0.00000000"],["84732.71000000","0.00009000"],["84732.31000000","0.35415000"],["84732.21000000","0.04183000"],["84731.73000000","0.00000000"],["84729.00000000","0.00000000"],["84717.07000000","0.35339000"],["84706.72000000","0.00000000"],["84706.17000000","0.00000000"],["84700.48000000","0.00000000"],["84700.00000000","0.05571000"],["84695.00000000","0.00000000"],["84689.07000000","0.00427000"],["84687.09000000","0.00618000"],["84685.27000000","0.91048000"],["84685.07000000","0.00354000"],["84683.57000000","1.19032000"],["84677.53000000","0.01142000"],["84677.40000000","0.00000000"],["84675.12000000","0.00000000"],["84672.01000000","2.08776000"],["84652.56000000","1.18042000"],["84643.05000000","0.67456000"],["84637.02000000","0.00000000"],["84380.49000000","0.07610000"],["83661.71000000","0.00000000"],["83471.25000000","0.00008000"],["67788.32000000","0.00261000"]],"a":[["84742.39000000","0.01612000"],["84742.40000000","0.04270000"],["84744.26000000","0.00000000"],["84745.07000000","0.00006000"],["84745.08000000","0.00006000"],["84745.46000000","0.00014000"],["84745.47000000","0.03540000"],["84745.61000000","0.00000000"],["84746.98000000","0.00000000"],["84746.99000000","0.00000000"],["84747.00000000","0.00000000"],["84747.72000000","0.00000000"],["84747.73000000","0.00000000"],["84748.38000000","0.00000000"],["84748.82000000","0.00387000"],["84748.93000000","0.00000000"],["84748.94000000","0.00000000"],["84749.00000000","0.00000000"],["84749.11000000","0.17999000"],["84749.12000000","0.00027000"],["84749.13000000","0.00006000"],["84749.44000000","0.00007000"],["84750.18000000","0.00645000"],["84750.33000000","0.00007000"],["84750.86000000","0.02013000"],["84750.90000000","0.00006000"],["84751.11000000","0.26002000"],["84751.12000000","0.02006000"],["84751.24000000","0.00000000"],["84751.50000000","0.00000000"],["84751.54000000","0.00775000"],["84751.58000000","0.03000000"],["84752.00000000","0.00000000"],["84752.28000000","0.00000000"],["84752.30000000","0.00000000"],["84752.40000000","0.00000000"],["84752.53000000","0.17999000"],["84752.84000000","0.00000000"],["84752.89000000","0.00775000"],["84752.99000000","0.00000000"],["84753.98000000","0.11870000"],["84753.99000000","0.17999000"],["84754.00000000","0.00000000"],["84754.01000000","0.00000000"],["84754.80000000","0.00000000"],["84754.93000000","0.00006000"],["84755.42000000","0.00000000"],["84756.21000000","0.00000000"],["84756.24000000","0.00000000"],["84756.63000000","0.00000000"],["84757.06000000","0.00006000"],["84757.20000000","0.00000000"],["84757.30000000","0.00000000"],["84758.00000000","0.03000000"],["84758.96000000","0.00016000"],["84759.16000000","0.02193000"],["84759.50000000","0.02000000"],["84759.71000000","0.00000000"],["84761.00000000","0.00200000"],["84761.31000000","0.00200000"],["84761.97000000","0.17999000"],["84762.00000000","0.00000000"],["84762.18000000","2.12425000"],["84762.39000000","0.00000000"],["84762.92000000","0.00400000"],["84762.93000000","0.00000000"],["84762.97000000","0.02515000"],["84762.99000000","0.00006000"],["84763.09000000","0.05800000"],["84763.75000000","0.17999000"],["84764.79000000","0.00000000"],["84765.43000000","0.17999000"],["84765.44000000","0.06024000"],["84766.39000000","0.35516000"],["84768.91000000","0.00000000"],["84769.24000000","0.00000000"],["84769.51000000","0.12000000"],["84771.43000000","0.00000000"],["84772.15000000","0.00000000"],["84772.61000000","0.00000000"],["84774.75000000","0.10652000"],["84777.99000000","0.00000000"],["84778.13000000","0.00000000"],["84778.73000000","0.00000000"],["84781.68000000","0.00000000"],["84784.16000000","0.00730000"],["84785.16000000","0.00400000"],["84787.28000000","0.00400000"],["84787.65000000","0.57566000"],["84787.95000000","0.00000000"],["84789.16000000","0.00627000"],["84789.94000000","0.00000000"],["84791.20000000","0.00013000"],["84792.05000000","1.18880000"],["84792.15000000","0.00436000"],["84795.23000000","0.00006000"],["84810.22000000","0.01140000"],["84822.55000000","0.02000000"],["84823.05000000","0.00000000"],["84823.93000000","1.16745000"],["84840.38000000","0.00000000"],["84847.87000000","0.04620000"],["84855.96000000","1.18042000"],["84866.20000000","0.00008000"],["84869.31000000","0.01888000"],["84878.52000000","0.02832000"],["84884.30000000","2.12425000"],["84944.87000000","0.00010000"]]}}
{"stream":"dogeusdt@depth@100ms","data":{"e":"depthUpdate","E":1790299062274,"s":"DOGEUSDT","U":25516669043,"u":25516669055,"b":[["0.09678000","112072.00000000"],["0.09669000","253510.00000000"],["0.09667000","154748.00000000"],["0.09665000","245800.00000000"],["0.09662000","290339.00000000"],["0.09633000","223434.00000000"],["0.09629000","446.00000000"]],"a":[["0.09679000","3788.00000000"],["0.09680000","327.00000000"],["0.09685000","156618.00000000"],["0.09686000","155106.00000000"],["0.09689000","174847.00000000"]]}}
{"stream":"btcusdt@depth@100ms","data":{"e":"depthUpdate","E":1790299062314,"s":"BTCUSDT","U":100639381025,"u":100639382042,"b":[["84745.97000000","4.22702000"],["84745.96000000","0.00012000"],["84745.95000000","0.00012000"],["84745.07000000","0.00000000"],["84745.06000000","0.00000000"],["84744.88000000","0.00400000"],["84744.20000000","0.00000000"],["84743.86000000","0.07506000"],["84743.85000000","3.17784000"],["84743.52000000","0.00000000"],["84743.20000000","0.93783000"],["84743.19000000","0.33734000"],["84743.18000000","0.35006000"],["84742.84000000","0.00012000"],["84742.83000000","0.00000000"],["84742.76000000","0.00400000"],["84742.40000000","0.00000000"],["84742.39000000","0.23215000"],["84742.38000000","2.44694000"],["84742.37000000","0.00018000"],["84742.36000000","0.00000000"],["84741.31000000","0.15000000"],["84741.00000000","0.03000000"],["84739.84000000","0.00166000"],["84739.67000000","0.00000000"],["84739.66000000","0.02062000"],["84739.20000000","0.00008000"],["84739.02000000","0.00944000"],["84738.82000000","0.00006000"],["84738.56000000","0.00012000"],["84738.32000000","0.04282000"],["84738.28000000","0.00000000"],["84738.27000000","0.00000000"],["84738.25000000","0.01136000"],["84738.14000000","0.01100000"],["84737.50000000","0.00007000"],["84736.42000000","0.00000000"],["84736.41000000","0.00000000"],["84735.80000000","0.00000000"],["84735.42000000","0.00000000"],["84735.40000000","1.31536000"],["84735.39000000","0.01911000"],["84735.01000000","0.00006000"],["84734.97000000","0.00000000"],["84734.03000000","0.00000000"],["84733.90000000","0.02442000"],["84733.60000000","0.00000000"],["84733.30000000","0.18709000"],["84732.67000000","0.00000000"],["84732.21000000","0.00000000"],["84731.80000000","0.00006000"],["84731.33000000","0.22079000"],["84731.12000000","0.08892000"],["84730.43000000","0.00000000"],["84730.07000000","0.00000000"],["84728.09000000","0.29505000"],["84727.98000000","0.00000000"],["84726.60000000","0.00000000"],["84725.55000000","0.00000000"],["84725.44000000","0.00007000"],["84725.34000000","0.00000000"],["84724.94000000","0.00060000"],["84724.84000000","0.00000000"],["84723.20000000","0.00000000"],["84722.03000000","0.61016000"],["84721.79000000","0.00000000"],["84721.20000000","0.00007000"],["84721.19000000","0.00000000"],["84720.62000000","0.00000000"],["84720.60000000","0.31878000"],["84720.55000000","0.00118000"],["84719.18000000","0.00000000"],["84719.05000000","0.00000000"],["84716.97000000","0.00007000"],["84716.96000000","0.00000000"],["84715.26000000","0.08988000"],["84714.39000000","0.00236000"],["84712.91000000","0.00000000"],["84712.73000000","0.00007000"],["84712.72000000","0.00000000"],["84712.55000000","0.00000000"],["84711.72000000","0.00000000"],["84711.40000000","0.00000000"],["84708.96000000","0.00000000"],["84708.71000000","0.00000000"],["84708.49000000","0.00007000"],["84708.48000000","0.00000000"],["84705.22000000","0.02351000"],["84704.26000000","0.00007000"],["84704.24000000","0.00000000"],["84703.34000000","0.00000000"],["84702.94000000","0.00000000"],["84702.56000000","0.00000000"],["84702.54000000","0.00000000"],["84700.02000000","0.00007000"],["84700.01000000","0.00000000"],["84698.35000000","0.00000000"],["84695.77000000","0.00000000"],["84695.35000000","1.01754000"],["84692.00000000","0.02800000"],["84687.88000000","0.00100000"],["84685.27000000","0.52794000"],["84685.10000000","0.00427000"],["84684.89000000","0.00431000"],["84683.57000000","0.00000000"],["84680.00000000","0.02806000"],["84676.81000000","0.00000000"],["84672.44000000","0.00000000"],["84671.55000000","0.00000000"],["84669.47000000","0.00110000"],["84669.39000000","0.01693000"],["84667.97000000","0.00539000"],["84661.22000000","0.00007000"],["84657.41000000","0.00335000"],["84655.15000000","0.76815000"],["84655.14000000","0.00000000"],["84650.87000000","0.00000000"],["84650.75000000","0.00000000"],["84650.65000000","0.00000000"],["84650.58000000","0.00000000"],["84647.26000000","0.04497000"],["84643.44000000","0.00000000"],["84639.57000000","0.00118000"],["84638.50000000","0.00000000"],["84638.01000000","0.04092000"],["84635.25000000","0.04653000"],["84630.32000000","0.05276000"],["84630.31000000","0.00000000"],["84620.51000000","0.05373000"],["84617.18000000","0.15940000"],["84617.17000000","0.00000000"],["84616.30000000","0.00000000"],["84609.82000000","0.00000000"],["84576.48000000","0.00007000"],["84565.92000000","0.00000000"],["84542.38000000","0.00000000"],["84491.73000000","0.00007000"],["84482.90000000","0.02953000"],["84481.18000000","0.00000000"],["84468.91000000","0.00006000"],["84450.55000000","0.00000000"],["84439.86000000","0.00000000"],["84408.24000000","0.00100000"],["84406.99000000","0.00007000"],["84396.45000000","0.00000000"],["84322.24000000","0.00007000"],["84311.71000000","0.00000000"],["84281.75000000","0.00000000"],["84237.49000000","0.00007000"],["84226.98000000","0.00000000"],["84152.75000000","0.00007000"],["84142.24000000","0.00000000"],["84068.00000000","0.00007000"],["84057.51000000","0.00000000"],["83471.25000000","0.00000000"],["76268.15000000","0.00000000"]],"a":[["84742.39000000","0.00000000"],["84742.40000000","0.00000000"],["84742.84000000","0.00000000"],["84743.86000000","0.00000000"],["84744.84000000","0.00000000"],["84744.85000000","0.00000000"],["84745.07000000","0.00000000"],["84745.08000000","0.00000000"],["84745.46000000","0.00000000"],["84745.47000000","0.00000000"],["84745.97000000","0.00000000"],["84745.98000000","0.07619000"],["84745.99000000","0.00055000"],["84746.89000000","0.00000000"],["84746.94000000","0.00000000"],["84747.05000000","0.00000000"],["84747.60000000","0.00000000"],["84748.31000000","0.00000000"],["84748.57000000","0.00000000"],["84749.10000000","0.00000000"],["84749.11000000","0.00006000"],["84749.12000000","0.00013000"],["84749.13000000","0.00000000"],["84749.16000000","0.00000000"],["84749.47000000","0.00000000"],["84749.71000000","0.00000000"],["84750.00000000","0.00000000"],["84750.28000000","0.00000000"],["84750.33000000","0.00000000"],["84750.34000000","0.00000000"],["84750.35000000","0.00000000"],["84750.36000000","0.00006000"],["84750.60000000","0.00000000"],["84750.85000000","0.00000000"],["84750.86000000","0.00000000"],["84750.87000000","0.00000000"],["84750.88000000","0.00000000"],["84751.08000000","0.00000000"],["84751.10000000","0.00000000"],["84751.11000000","0.00006000"],["84751.12000000","0.00000000"],["84751.20000000","0.00000000"],["84751.24000000","0.00006000"],["84751.28000000","0.00012000"],["84751.35000000","0.00000000"],["84751.54000000","0.00781000"],["84751.58000000","0.00000000"],["84751.64000000","0.00000000"],["84752.06000000","0.00000000"],["84752.13000000","0.00000000"],["84752.53000000","0.00000000"],["84752.54000000","0.00000000"],["84752.57000000","0.00000000"],["84752.58000000","0.00000000"],["84752.64000000","0.00000000"],["84752.89000000","0.00781000"],["84753.00000000","0.00014000"],["84753.01000000","0.16277000"],["84753.27000000","0.00000000"],["84753.54000000","0.00007000"],["84753.97000000","0.00014000"],["84753.98000000","0.00000000"],["84753.99000000","0.00000000"],["84754.14000000","0.00000000"],["84754.46000000","0.00068000"],["84754.51000000","0.00000000"],["84754.62000000","0.00000000"],["84754.76000000","0.00000000"],["84754.77000000","0.00000000"],["84754.78000000","0.00000000"],["84754.82000000","0.03539000"],["84754.86000000","0.00048000"],["84754.91000000","0.00048000"],["84754.93000000","0.00006000"],["84754.97000000","0.00000000"],["84754.99000000","0.08237000"],["84755.08000000","0.00014000"],["84755.09000000","0.03000000"],["84755.10000000","0.00000000"],["84755.21000000","0.00000000"],["84755.23000000","0.00047000"],["84755.42000000","0.00000000"],["84755.53000000","0.00000000"],["84755.59000000","0.00000000"],["84755.70000000","0.00189000"],["84755.73000000","0.00000000"],["84756.54000000","0.00000000"],["84756.55000000","0.00000000"],["84756.60000000","0.17892000"],["84756.66000000","0.00000000"],["84756.84000000","0.00190000"],["84757.12000000","0.00000000"],["84757.13000000","0.11798000"],["84757.44000000","0.00000000"],["84757.50000000","0.00000000"],["84757.66000000","0.00000000"],["84758.00000000","0.00000000"],["84758.30000000","0.17892000"],["84758.31000000","0.08589000"],["84758.32000000","0.00000000"],["84758.74000000","0.00006000"],["84758.96000000","0.00012000"],["84759.00000000","0.00000000"],["84759.16000000","0.00000000"],["84759.44000000","0.00000000"],["84759.63000000","0.00000000"],["84760.09000000","0.17893000"],["84760.23000000","0.00000000"],["84760.44000000","0.00000000"],["84760.81000000","0.00007000"],["84761.00000000","0.00000000"],["84761.31000000","0.00590000"],["84761.49000000","0.00000000"],["84761.50000000","0.03000000"],["84761.86000000","0.17905000"],["84761.87000000","0.00152000"],["84761.96000000","0.00000000"],["84761.97000000","0.00000000"],["84762.16000000","0.17892000"],["84762.17000000","0.78521000"],["84762.18000000","2.12425000"],["84762.31000000","0.00000000"],["84762.34000000","0.00000000"],["84762.47000000","0.00000000"],["84762.92000000","0.00000000"],["84762.97000000","0.00000000"],["84762.99000000","0.00012000"],["84763.35000000","0.00000000"],["84763.68000000","0.00000000"],["84763.75000000","0.00000000"],["84763.83000000","0.00590000"],["84764.41000000","0.02000000"],["84764.84000000","0.00000000"],["84765.05000000","0.00007000"],["84765.18000000","0.00236000"],["84765.33000000","0.00200000"],["84765.43000000","0.00000000"],["84765.84000000","0.02000000"],["84766.38000000","0.00000000"],["84766.39000000","0.00000000"],["84767.92000000","0.00000000"],["84768.40000000","0.00400000"],["84769.13000000","0.00000000"],["84769.28000000","0.00007000"],["84769.89000000","0.00200000"],["84770.35000000","0.00000000"],["84770.42000000","0.39675000"],["84770.83000000","0.12000000"],["84771.44000000","0.00000000"],["84771.73000000","0.08888000"],["84771.77000000","0.00000000"],["84772.16000000","0.00000000"],["84772.94000000","0.00000000"],["84773.36000000","0.00000000"],["84773.52000000","0.00007000"],["84773.99000000","0.29506000"],["84774.39000000","0.00000000"],["84775.18000000","0.51572000"],["84776.21000000","0.15488000"],["84776.38000000","0.00000000"],["84776.39000000","0.00000000"],["84777.76000000","0.00007000"],["84777.98000000","0.00000000"],["84778.25000000","0.29506000"],["84778.33000000","0.00000000"],["84780.07000000","0.00000000"],["84780.18000000","0.00000000"],["84780.63000000","0.00000000"],["84781.99000000","0.00007000"],["84782.59000000","0.34838000"],["84783.20000000","0.63318000"],["84785.00000000","0.00000000"],["84786.23000000","0.00007000"],["84786.58000000","0.29506000"],["84787.00000000","0.00000000"],["84787.17000000","0.00012000"],["84787.65000000","0.34684000"],["84787.66000000","0.00000000"],["84787.88000000","0.00000000"],["84788.22000000","0.00000000"],["84789.00000000","0.01000000"],["84789.16000000","0.00000000"],["84789.40000000","0.00400000"],["84791.52000000","1.37810000"],["84792.05000000","0.00000000"],["84797.84000000","0.00000000"],["84800.30000000","0.00435000"],["84804.37000000","0.00000000"],["84805.47000000","0.00000000"],["84805.61000000","0.00000000"],["84806.51000000","0.12230000"],["84807.02000000","0.01154000"],["84820.13000000","0.00000000"],["84821.56000000","0.75403000"],["84821.72000000","0.00536000"],["84822.59000000","0.02000000"],["84822.81000000","0.01693000"],["84822.90000000","0.00205000"],["84823.50000000","0.00000000"],["84826.50000000","0.00000000"],["84830.73000000","0.00014000"],["84840.37000000","0.00000000"],["84842.79000000","0.85230000"],["84848.56000000","0.09376000"],["84878.00000000","0.06797000"],["84904.86000000","0.00000000"],["84913.35000000","0.00007000"],["84989.60000000","0.00000000"],["84996.74000000","0.00000000"],["84998.09000000","0.00007000"],["85013.07000000","0.00000000"],["85019.64000000","0.00000000"],["85051.06000000","1.19998000"],["85058.81000000","0.02387000"],["85074.33000000","0.00000000"],["85076.55000000","0.00100000"],["85082.84000000","0.00007000"],["85159.07000000","0.00000000"],["85169.71000000","0.00007000"],["85243.80000000","0.00000000"],["85254.46000000","0.00007000"],["85328.54000000","0.00000000"],["85339.20000000","0.00007000"]]}}
{"stream":"dogeusdt@depth@100ms","data":{"e":"depthUpdate","E":1790299062374,"s":"DOGEUSDT","U":25516669056,"u":25516669198,"b":[["0.09679000","174605.00000000"],["0.09678000","76712.00000000"],["0.09677000","72363.00000000"],["0.09676000","144805.00000000"],["0.09675000","136260.00000000"],["0.09674000","347252.00000000"],["0.09669000","233289.00000000"],["0.09668000","170758.00000000"],["0.09667000","154759.00000000"],["0.09666000","548036.00000000"],["0.09665000","126116.00000000"],["0.09663000","212089.00000000"],["0.09660000","255765.00000000"],["0.09659000","669400.00000000"],["0.09658000","339260.00000000"],["0.09650000","16694.00000000"],["0.09647000","122.00000000"],["0.09628000","497.00000000"],["0.09603000","1828.00000000"]],"a":[["0.09679000","0.00000000"],["0.09680000","19639.00000000"],["0.09681000","21151.00000000"],["0.09682000","132398.00000000"],["0.09683000","80458.00000000"],["0.09684000","217001.00000000"],["0.09685000","144306.00000000"],["0.09687000","228244.00000000"],["0.09688000","269633.00000000"],["0.09689000","142808.00000000"],["0.09690000","185796.00000000"],["0.09697000","216609.00000000"],["0.09698000","327839.00000000"],["0.09700000","1442516.00000000"],["0.09702000","241906.00000000"],["0.09705000","217519.00000000"],["0.09707000","12039.00000000"],["0.09714000","53499.00000000"],["0.09720000","53583.00000000"],["0.09728000","2310.00000000"],["0.09755000","1392.00000000"]]}}
{"stream":"btcusdt@depth@100ms","data":{"e":"depthUpdate","E":1790299062414,"s":"BTCUSDT","U":100639382043,"u":100639382571,"b":[["84753.00000000","4.66254000"],["84752.99000000","0.00012000"],["84752.98000000","0.00012000"],["84752.93000000","0.00000000"],["84752.88000000","0.00000000"],["84752.77000000","0.00200000"],["84751.53000000","0.00000000"],["84751.28000000","0.00000000"],["84751.27000000","0.00000000"],["84751.23000000","0.00000000"],["84750.90000000","0.00012000"],["84750.89000000","0.00000000"],["84750.63000000","0.00000000"],["84750.17000000","0.00000000"],["84749.46000000","0.00000000"],["84749.29000000","0.00024000"],["84748.81000000","0.00000000"],["84747.69000000","0.00000000"],["84746.87000000","0.00012000"],["84745.98000000","2.25570000"],["84745.97000000","2.27466000"],["84745.96000000","0.00000000"],["84745.95000000","0.00000000"],["84744.89000000","0.00000000"],["84744.52000000","0.00007000"],["84744.25000000","0.10462000"],["84743.87000000","0.00000000"],["84743.86000000","0.07512000"],["84743.85000000","3.12784000"],["84743.20000000","0.69873000"],["84743.19000000","0.00000000"],["84743.18000000","0.30006000"],["84742.84000000","0.30012000"],["84742.43000000","0.00006000"],["84742.38000000","2.17792000"],["84742.37000000","0.00012000"],["84741.79000000","0.00006000"],["84741.31000000","0.15006000"],["84741.25000000","0.00944000"],["84741.06000000","0.00009000"],["84741.02000000","0.00000000"],["84741.00000000","0.02994000"],["84739.85000000","0.00013000"],["84739.66000000","0.00006000"],["84739.02000000","0.00950000"],["84738.82000000","0.00000000"],["84738.60000000","0.00007000"],["84738.40000000","0.00006000"],["84738.31000000","0.00000000"],["84738.20000000","0.00006000"],["84737.50000000","0.00000000"],["84736.05000000","0.00007000"],["84735.40000000","1.24036000"],["84735.39000000","0.00778000"],["84735.37000000","0.00000000"],["84735.23000000","0.13803000"],["84733.30000000","0.00000000"],["84732.96000000","0.00000000"],["84731.81000000","0.00007000"],["84731.62000000","0.00000000"],["84730.10000000","0.00000000"],["84728.23000000","0.00000000"],["84727.57000000","1.21705000"],["84727.33000000","0.00012000"],["84727.18000000","0.00190000"],["84725.44000000","0.00000000"],["84723.34000000","0.00007000"],["84722.51000000","0.00000000"],["84721.20000000","0.00000000"],["84721.04000000","0.00000000"],["84719.10000000","0.00007000"],["84719.06000000","1.14736000"],["84718.61000000","0.00000000"],["84716.97000000","0.00000000"],["84716.63000000","0.58119000"],["84714.86000000","0.00007000"],["84714.39000000","0.00000000"],["84712.73000000","0.00000000"],["84710.62000000","0.00007000"],["84710.60000000","0.00000000"],["84709.87000000","0.00000000"],["84708.49000000","0.00000000"],["84707.66000000","0.00024000"],["84706.57000000","0.00000000"],["84704.26000000","0.00000000"],["84703.00000000","0.01000000"],["84700.02000000","0.00000000"],["84700.00000000","0.04571000"],["84696.51000000","0.01157000"],["84687.97000000","0.11974000"],["84680.01000000","0.00294000"],["84679.58000000","0.00294000"],["84674.11000000","0.00294000"],["84672.77000000","0.00000000"],["84669.45000000","0.00000000"],["84668.96000000","0.00000000"],["84658.17000000","0.00000000"],["84654.08000000","0.00000000"],["84647.42000000","0.00000000"],["84645.27000000","0.00000000"],["84628.00000000","0.06459000"],["84575.54000000","0.00000000"],["84516.77000000","0.00000000"],["84468.91000000","0.00000000"],["84387.28000000","0.00000000"],["83474.79000000","0.00000000"],["76271.38000000","0.00008000"],["67788.32000000","0.00232000"]],"a":[["84745.98000000","0.00000000"],["84745.99000000","0.00000000"],["84746.87000000","0.00000000"],["84747.25000000","0.00000000"],["84748.82000000","0.00000000"],["84749.11000000","0.00000000"],["84749.12000000","0.00000000"],["84749.23000000","0.00000000"],["84749.42000000","0.00000000"],["84749.44000000","0.00000000"],["84750.18000000","0.00000000"],["84750.36000000","0.00000000"],["84750.64000000","0.00000000"],["84750.90000000","0.00000000"],["84751.11000000","0.00000000"],["84751.24000000","0.00000000"],["84751.28000000","0.00000000"],["84751.29000000","0.00000000"],["84751.54000000","0.00000000"],["84751.96000000","0.00000000"],["84752.27000000","0.00000000"],["84752.35000000","0.00000000"],["84752.89000000","0.00000000"],["84752.94000000","0.00000000"],["84753.00000000","0.00000000"],["84753.01000000","0.30783000"],["84753.02000000","0.00055000"],["84753.54000000","0.00000000"],["84753.67000000","0.00000000"],["84753.97000000","0.00000000"],["84753.98000000","0.00006000"],["84754.31000000","0.00000000"],["84754.46000000","0.00000000"],["84754.78000000","0.00014000"],["84754.79000000","0.00014000"],["84754.80000000","0.09320000"],["84754.81000000","0.00014000"],["84754.82000000","0.03539000"],["84754.94000000","0.00000000"],["84754.98000000","0.00000000"],["84754.99000000","0.00014000"],["84755.00000000","0.11886000"],["84755.08000000","0.00007000"],["84755.09000000","0.03006000"],["84755.35000000","0.00000000"],["84755.58000000","0.00000000"],["84756.16000000","0.00000000"],["84756.60000000","0.00000000"],["84756.74000000","0.00000000"],["84757.06000000","0.00000000"],["84757.13000000","0.00006000"],["84757.52000000","0.10462000"],["84758.25000000","0.13834000"],["84758.26000000","0.00006000"],["84758.27000000","0.00006000"],["84758.28000000","0.00000000"],["84758.29000000","0.00000000"],["84758.30000000","0.00000000"],["84758.31000000","0.00000000"],["84759.17000000","0.00006000"],["84760.09000000","0.00000000"],["84760.14000000","0.17892000"],["84760.81000000","0.00000000"],["84761.31000000","0.00000000"],["84761.49000000","0.00075000"],["84761.85000000","0.00000000"],["84761.86000000","0.00000000"],["84762.13000000","0.00006000"],["84762.16000000","0.00000000"],["84765.05000000","0.00000000"],["84765.18000000","0.00000000"],["84765.33000000","0.00000000"],["84765.52000000","0.00006000"],["84766.06000000","0.00236000"],["84766.85000000","0.00590000"],["84767.91000000","0.00000000"],["84768.13000000","0.00200000"],["84768.14000000","0.00000000"],["84768.16000000","0.00000000"],["84768.40000000","0.00200000"],["84768.77000000","0.00000000"],["84768.92000000","0.00000000"],["84769.27000000","0.00000000"],["84769.28000000","0.00000000"],["84769.50000000","0.00000000"],["84769.89000000","0.00400000"],["84769.96000000","0.00007000"],["84770.27000000","0.00000000"],["84770.42000000","0.19030000"],["84770.43000000","0.00000000"],["84770.44000000","0.00000000"],["84773.52000000","0.00000000"],["84773.99000000","0.00000000"],["84774.20000000","0.00007000"],["84777.76000000","0.00000000"],["84777.78000000","0.00943000"],["84778.44000000","0.00007000"],["84779.60000000","0.29504000"],["84779.67000000","0.00000000"],["84780.24000000","0.00000000"],["84781.69000000","0.00000000"],["84781.78000000","0.11795000"],["84781.99000000","0.00000000"],["84782.67000000","0.00007000"],["84783.20000000","0.63378000"],["84784.07000000","0.00000000"],["84785.29000000","0.00189000"],["84785.46000000","0.00012000"],["84786.23000000","0.00000000"],["84786.91000000","0.00007000"],["84787.65000000","0.12750000"],["84789.00000000","0.00000000"],["84791.15000000","0.00007000"],["84791.20000000","0.00019000"],["84791.59000000","0.58984000"],["84792.15000000","0.00000000"],["84792.54000000","0.00000000"],["84792.87000000","0.02310000"],["84793.64000000","0.00400000"],["84794.65000000","0.00000000"],["84794.77000000","0.30217000"],["84795.23000000","0.00012000"],["84795.39000000","0.00007000"],["84796.00000000","0.01000000"],["84796.80000000","0.31849000"],["84800.01000000","0.00789000"],["84803.63000000","0.00433000"],["84803.85000000","0.00000000"],["84804.14000000","0.00430000"],["84806.41000000","0.03541000"],["84811.99000000","0.00000000"],["84817.14000000","0.00269000"],["84818.15000000","0.01452000"],["84820.37000000","0.00000000"],["84822.55000000","0.00000000"],["84822.58000000","0.00587000"],["84828.55000000","0.00000000"],["84830.97000000","1.04496000"],["84833.91000000","0.00000000"],["84875.36000000","0.00007000"],["84897.87000000","0.00000000"],["84906.96000000","0.00117000"],["84907.51000000","0.00118000"],["84913.35000000","0.00000000"],["84922.52000000","0.00007000"],["84959.86000000","0.00272000"],["84965.46000000","3.53185000"],["84977.31000000","0.00373000"],["84979.16000000","0.00006000"],["84985.61000000","0.00000000"],["84998.09000000","0.00000000"],["85001.79000000","0.00022000"],["85001.89000000","0.00000000"],["85007.27000000","0.00007000"],["85013.58000000","0.11572000"],["85023.91000000","0.00025000"],["85033.89000000","0.01917000"],["85063.13000000","0.00488000"],["85063.17000000","0.07646000"],["85082.84000000","0.00000000"],["85092.02000000","0.00007000"]]}}
{"stream":"dogeusdt@depth@100ms","data":{"e":"depthUpdate","E":1790299062474,"s":"DOGEUSDT","U":25516669199,"u":25516669221,"b":[["0.09679000","177793.00000000"],["0.09678000","105448.00000000"],["0.09677000","166843.00000000"],["0.09676000","138428.00000000"],["0.09674000","310566.00000000"],["0.09673000","323387.00000000"],["0.09669000","266751.00000000"],["0.09668000","273899.00000000"]],"a":[["0.09683000","59505.00000000"],["0.09688000","290642.00000000"],["0.09692000","250198.00000000"],["0.09693000","536407.00000000"]]}}
{"stream":"btcusdt@depth@100ms","data":{"e":"depthUpdate","E":1790299062514,"s":"BTCUSDT","U":100639382572,"u":100639382788,"b":[["84753.00000000","5.02091000"],["84751.99000000","0.00007000"],["84751.65000000","0.01397000"],["84751.64000000","0.01823000"],["84750.29000000","0.00014000"],["84750.28000000","0.02186000"],["84749.30000000","0.00200000"],["84749.12000000","0.00400000"],["84748.94000000","0.00014000"],["84748.93000000","0.02180000"],["84747.00000000","0.00400000"],["84746.88000000","0.01006000"],["84745.99000000","0.45892000"],["84745.98000000","0.43016000"],["84745.97000000","2.20369000"],["84743.86000000","0.07506000"],["84743.18000000","0.30012000"],["84742.39000000","0.11715000"],["84742.37000000","0.00006000"],["84740.23000000","0.00000000"],["84739.02000000","0.00944000"],["84738.65000000","0.00006000"],["84738.25000000","0.01130000"],["84738.15000000","0.00000000"],["84738.14000000","0.01088000"],["84736.18000000","0.08892000"],["84735.39000000","0.00766000"],["84734.26000000","0.00000000"],["84733.41000000","0.00000000"],["84731.12000000","0.00000000"],["84729.02000000","0.00007000"],["84727.05000000","0.00236000"],["84723.15000000","0.58119000"],["84718.77000000","0.00000000"],["84717.32000000","0.00400000"],["84716.63000000","0.00000000"],["84716.10000000","0.00007000"],["84715.76000000","0.00000000"],["84714.75000000","0.00000000"],["84713.08000000","0.00000000"],["84710.00000000","0.01000000"],["84709.61000000","0.59851000"],["84703.00000000","0.00000000"],["84702.28000000","0.48181000"],["84698.98000000","0.00000000"],["84691.46000000","0.78496000"],["84691.45000000","1.19021000"],["84691.42000000","0.00000000"],["84680.84000000","0.00000000"],["84676.41000000","0.00000000"],["84651.58000000","1.55963000"],["84647.50000000","2.97706000"],["84642.52000000","0.00000000"],["84526.01000000","0.00734000"],["84524.01000000","0.00000000"],["84479.69000000","0.00000000"],["84476.61000000","0.00000000"],["84472.38000000","0.00000000"],["84398.04000000","0.00024000"],["83142.69000000","0.00000000"],["76277.70000000","0.00015000"],["67802.00000000","0.00000000"]],"a":[["84753.01000000","0.32611000"],["84753.02000000","0.00055000"],["84754.78000000","0.00000000"],["84754.86000000","0.00000000"],["84754.91000000","0.00000000"],["84755.08000000","0.00014000"],["84755.09000000","0.03006000"],["84755.16000000","0.00013000"],["84755.23000000","0.00000000"],["84755.70000000","0.00000000"],["84755.97000000","0.00013000"],["84756.78000000","0.00013000"],["84757.13000000","0.00000000"],["84757.51000000","0.00007000"],["84757.52000000","0.10474000"],["84758.23000000","0.13496000"],["84758.24000000","0.17600000"],["84758.25000000","0.00000000"],["84758.26000000","0.00000000"],["84758.27000000","0.00000000"],["84759.50000000","0.02006000"],["84759.66000000","0.01090000"],["84759.72000000","0.01098000"],["84759.94000000","0.00590000"],["84760.09000000","0.17890000"],["84760.14000000","0.00006000"],["84760.56000000","0.00325000"],["84761.86000000","0.16300000"],["84761.92000000","0.00542000"],["84762.16000000","0.17890000"],["84762.78000000","0.00048000"],["84762.99000000","0.00022000"],["84763.09000000","0.05800000"],["84763.15000000","0.00048000"],["84763.27000000","0.00187000"],["84763.28000000","0.00651000"],["84764.63000000","0.00651000"],["84766.39000000","0.35526000"],["84769.89000000","0.00600000"],["84769.96000000","0.00014000"],["84770.42000000","0.07571000"],["84771.73000000","0.00000000"],["84772.56000000","0.00006000"],["84781.83000000","0.21821000"],["84792.63000000","0.59792000"],["84802.06000000","0.00000000"],["84804.72000000","1.18862000"],["84804.82000000","1.20803000"],["84807.04000000","0.73595000"],["84807.57000000","0.01161000"],["84808.24000000","0.43391000"],["84848.70000000","1.06450000"],["84848.71000000","2.97000000"],["84849.99000000","0.00117000"],["84855.95000000","0.99845000"],["84860.41000000","0.03276000"],["84860.58000000","0.15000000"],["84869.31000000","0.00000000"],["84871.23000000","0.01887000"],["84878.00000000","0.00000000"],["84878.52000000","0.00000000"],["84880.87000000","0.02831000"],["84983.54000000","0.00006000"],["84987.77000000","0.00006000"],["84992.00000000","0.00006000"],["84996.23000000","0.00000000"]]}}
{"stream":"dogeusdt@depth@100ms","data":{"e":"depthUpdate","E":1790299062574,"s":"DOGEUSDT","U":25516669222,"u":25516669248,"b":[["0.09679000","202188.00000000"],["0.09678000","176205.00000000"],["0.09676000","119826.00000000"],["0.09671000","283005.00000000"],["0.09669000","259408.00000000"],["0.09667000","162620.00000000"],["0.09665000","118770.00000000"],["0.09664000","97006.00000000"],["0.09662000","289822.00000000"],["0.09657000","9309.00000000"],["0.09648000","41793.00000000"],["0.09642000","31780.00000000"],["0.09640000","32002.00000000"],["0.09638000","116836.00000000"]],"a":[["0.09680000","44.00000000"],["0.09681000","39753.00000000"],["0.09686000","147776.00000000"],["0.09693000","543731.00000000"],["0.09694000","150616.00000000"],["0.09695000","154397.00000000"],["0.09701000","166741.00000000"]]}}
{"stream":"btcusdt@depth@100ms","data":{"e":"depthUpdate","E":1790299062614,"s":"BTCUSDT","U":100639382789,"u":100639382826,"b":[["84753.00000000","5.02089000"],["84751.66000000","0.00014000"],["84751.39000000","0.00200000"],["84745.97000000","2.05369000"],["84742.84000000","0.30018000"],["84742.76000000","0.30406000"],["84742.43000000","0.30006000"],["84742.38000000","2.17786000"],["84720.83000000","0.00000000"],["84706.58000000","0.00011000"],["84704.04000000","0.00017000"],["84686.30000000","0.00000000"],["84683.76000000","0.00000000"],["84679.57000000","0.04600000"],["83481.71000000","0.00008000"],["67802.40000000","0.00000000"],["67802.00000000","0.00100000"],["67788.32000000","0.00203000"]],"a":[["84753.01000000","0.32658000"],["84754.79000000","0.00020000"],["84757.59000000","0.00013000"],["84758.40000000","0.00013000"],["84759.21000000","0.00013000"],["84760.02000000","0.00013000"],["84762.16000000","0.00000000"],["84762.78000000","0.00000000"],["84790.42000000","0.00000000"],["84796.59000000","0.00000000"],["84797.34000000","0.00616000"],["84812.95000000","0.00000000"],["84816.90000000","0.00017000"],["84888.34000000","0.06797000"],["85081.50000000","2.00000000"],["85162.53000000","2.00000000"]]}}
{"stream":"btcusdt@depth@100ms","data":{"e":"depthUpdate","E":1790299062714,"s":"BTCUSDT","U":100639382827,"u":100639382862,"b":[["84753.00000000","4.45969000"],["84750.30000000","0.00007000"],["84746.89000000","0.00207000"],["84745.99000000","0.33747000"],["84743.86000000","2.11104000"],["84743.20000000","0.00000000"],["84738.48000000","0.00000000"],["84728.87000000","0.00200000"],["84699.85000000","0.00029000"],["83481.71000000","0.00016000"],["82676.47000000","0.00000000"],["76277.70000000","0.00030000"],["67802.00000000","0.00000000"]],"a":[["84753.01000000","0.32847000"],["84754.78000000","0.00007000"],["84754.79000000","0.17900000"],["84755.09000000","0.03012000"],["84756.57000000","0.17880000"],["84757.51000000","0.00000000"],["84758.24000000","0.00000000"],["84760.09000000","0.00000000"],["84760.83000000","0.00013000"],["84761.64000000","0.00013000"],["84762.45000000","0.00013000"],["84763.15000000","0.00000000"],["84763.27000000","0.00000000"],["84800.91000000","0.31848000"],["84810.73000000","0.00011000"],["84833.25000000","0.00029000"]]}}
{"stream":"dogeusdt@depth@100ms","data":{"e":"depthUpdate","E":1790299062774,"s":"DOGEUSDT","U":25516669249,"u":25516669251,"b":[["0.09679000","188265.00000000"]],"a":[["0.09682000","136398.00000000"],["0.09683000","55505.00000000"]]}}
{"stream":"btcusdt@depth@100ms","data":{"e":"depthUpdate","E":1790299062814,"s":"BTCUSDT","U":100639382863,"u":100639382920,"b":[["84751.39000000","0.00000000"],["84746.89000000","0.00400000"],["84746.88000000","0.00406000"],["84745.99000000","0.69955000"],["84743.12000000","0.00007000"],["84736.05000000","0.02607000"],["84733.34000000","0.00013000"],["84726.31000000","0.21803000"],["84698.67000000","0.00627000"],["84687.09000000","0.00000000"],["84655.66000000","0.00377000"],["83481.70000000","0.00030000"],["76277.70000000","0.00045000"],["76277.00000000","0.00272000"],["67802.00000000","0.00300000"],["67788.32000000","0.00174000"]],"a":[["84753.01000000","0.32611000"],["84753.02000000","0.00062000"],["84754.78000000","0.00014000"],["84755.09000000","0.03006000"],["84755.77000000","0.00000000"],["84756.57000000","0.00000000"],["84757.52000000","0.10468000"],["84758.23000000","0.07968000"],["84759.72000000","0.01092000"],["84759.94000000","0.00596000"],["84760.13000000","0.17880000"],["84762.16000000","0.17880000"],["84762.52000000","0.02000000"],["84762.62000000","0.00047000"],["84763.12000000","0.00188000"],["84763.53000000","0.00048000"],["84814.74000000","0.02000000"],["84880.62000000","0.00007000"],["84945.52000000","0.00000000"],["84975.60000000","0.00000000"],["84989.49000000","0.01848000"]]}}
{"stream":"dogeusdt@depth@100ms","data":{"e":"depthUpdate","E":1790299062874,"s":"DOGEUSDT","U":25516669252,"u":25516669252,"b":[],"a":[["0.09681000","20158.00000000"]]}}
{"stream":"btcusdt@depth@100ms","data":{"e":"depthUpdate","E":1790299062914,"s":"BTCUSDT","U":100639382921,"u":100639382939,"b":[["84753.00000000","4.46141000"],["84746.88000000","0.00806000"],["84744.25000000","0.10468000"],["84744.14000000","0.03539000"],["84721.31000000","0.00000000"],["83481.71000000","0.00024000"],["67802.00000000","0.00000000"]],"a":[["84753.01000000","0.32624000"],["84754.79000000","0.17900000"],["84754.99000000","0.00020000"],["84762.62000000","0.00000000"],["84772.33000000","0.00000000"],["84776.51000000","0.01967000"],["84860.00000000","0.71275000"]]}}
{"stream":"dogeusdt@depth@100ms","data":{"e":"depthUpdate","E":1790299062974,"s":"DOGEUSDT","U":25516669253,"u":25516669258,"b":[["0.09679000","174605.00000000"],["0.09675000","131242.00000000"]],"a":[["0.09683000","63505.00000000"],["0.09684000","209001.00000000"],["0.09688000","302898.00000000"]]}}
{"stream":"btcusdt@depth@100ms","data":{"e":"depthUpdate","E":1790299063014,"s":"BTCUSDT","U":100639382940,"u":100639382989,"b":[["84753.00000000","4.46731000"],["84751.19000000","0.00200000"],["84751.14000000","0.00007000"],["84745.97000000","2.04779000"],["84742.38000000","0.05361000"],["84738.32000000","0.06356000"],["84737.68000000","0.08628000"],["84736.89000000","0.03600000"],["84736.85000000","0.04600000"],["84736.06000000","0.04800000"],["84736.01000000","0.04800000"],["84736.00000000","0.04400000"],["84733.54000000","0.04800000"],["84732.69000000","0.08600000"],["84731.84000000","0.05000000"],["84731.82000000","0.04200000"],["84689.55000000","0.00377000"],["84655.16000000","2.12381000"],["84649.02000000","0.00000000"],["84589.71000000","0.00118000"],["84558.25000000","0.00000000"],["83481.71000000","0.00016000"],["82386.87000000","0.00010000"],["67802.40000000","0.00136000"],["67788.32000000","0.00145000"]],"a":[["84753.01000000","0.32862000"],["84761.73000000","0.02000000"],["84762.57000000","0.02000000"],["84763.12000000","0.00000000"],["84765.09000000","0.02000000"],["84765.91000000","0.02000000"],["84766.76000000","0.02000000"],["84776.51000000","0.00000000"],["84798.79000000","0.00616000"],["84811.66000000","0.02000000"],["84812.54000000","0.02000000"],["84812.61000000","0.02000000"],["84813.96000000","0.02000000"],["84814.82000000","0.02000000"],["84815.90000000","0.02000000"],["84816.81000000","0.02000000"],["84819.07000000","0.02000000"],["84827.09000000","0.02000000"],["84828.05000000","0.02000000"],["84891.98000000","0.00000000"],["84903.52000000","0.00108000"],["86024.31000000","0.00030000"]]}}
{"stream":"dogeusdt@depth@100ms","data":{"e":"depthUpdate","E":1790299063074,"s":"DOGEUSDT","U":25516669259,"u":25516669290,"b":[["0.09679000","140229.00000000"],["0.09663000","212026.00000000"]],"a":[["0.09680000","62675.00000000"],["0.09681000","20169.00000000"],["0.09682000","32866.00000000"],["0.09683000","85176.00000000"],["0.09684000","189448.00000000"],["0.09688000","418677.00000000"],["0.09692000","289102.00000000"],["0.09699000","611499.00000000"],["0.09700000","1414298.00000000"],["0.09701000","73135.00000000"],["0.09705000","94142.00000000"]]}}
{"stream":"btcusdt@depth@100ms","data":{"e":"depthUpdate","E":1790299063114,"s":"BTCUSDT","U":100639382990,"u":100639383041,"b":[["84753.00000000","4.44287000"],["84751.19000000","0.00000000"],["84749.74000000","0.00236000"],["84746.89000000","0.00000000"],["84746.88000000","0.00406000"],["84746.00000000","0.00200000"],["84745.59000000","0.00012000"],["84743.86000000","1.59498000"],["84743.47000000","0.00012000"],["84741.35000000","0.00012000"],["84740.12000000","0.00006000"],["84739.66000000","0.00000000"],["84736.73000000","0.00006000"],["84732.17000000","0.04200000"],["84728.87000000","0.00000000"],["84721.16000000","0.00000000"],["84658.37000000","0.00000000"],["84655.17000000","1.40123000"],["84655.15000000","0.00000000"],["84649.94000000","0.00000000"],["84640.66000000","0.00000000"],["84630.34000000","0.00000000"],["83481.71000000","0.00024000"],["76271.38000000","0.00000000"],["76271.37000000","0.00008000"],["67802.40000000","0.00116000"]],"a":[["84753.01000000","0.62058000"],["84754.79000000","0.00020000"],["84757.51000000","0.00006000"],["84763.13000000","0.00188000"],["84769.89000000","0.00800000"],["84772.04000000","0.11796000"],["84772.41000000","0.00000000"],["84773.67000000","0.00118000"],["84776.67000000","0.00000000"],["84776.74000000","0.00008000"],["84786.45000000","0.00200000"],["84791.15000000","0.00016000"],["84795.70000000","0.58982000"],["84803.86000000","0.01258000"],["84813.96000000","0.00000000"],["84816.41000000","0.02000000"],["84827.09000000","0.00000000"],["85243.56000000","2.00000000"]]}}
{"stream":"dogeusdt@depth@100ms","data":{"e":"depthUpdate","E":1790299063174,"s":"DOGEUSDT","U":25516669291,"u":25516669301,"b":[["0.09674000","317387.00000000"],["0.09669000","258431.00000000"]],"a":[["0.09681000","20185.00000000"],["0.09682000","17787.00000000"],["0.09683000","73564.00000000"],["0.09687000","266049.00000000"],["0.09696000","719107.00000000"]]}}
{"stream":"btcusdt@depth@100ms","data":{"e":"depthUpdate","E":1790299063214,"s":"BTCUSDT","U":100639383042,"u":100639383080,"b":[["84750.30000000","0.00000000"],["84743.85000000","3.13896000"],["84731.82000000","0.09200000"],["84725.46000000","0.00000000"],["84721.99000000","0.00000000"],["84704.81000000","0.00000000"],["84647.26000000","0.03122000"],["84646.53000000","0.00000000"],["84643.13000000","0.00000000"],["84616.76000000","0.00000000"],["83481.71000000","0.00024000"],["76277.70000000","0.00060000"],["67788.32000000","0.00116000"]],"a":[["84753.01000000","0.62263000"],["84753.02000000","0.00055000"],["84754.78000000","0.00000000"],["84757.04000000","0.00007000"],["84757.51000000","0.00013000"],["84757.52000000","0.10474000"],["84758.21000000","0.14290000"],["84758.22000000","0.17880000"],["84758.23000000","0.00000000"],["84762.16000000","0.00000000"],["84763.12000000","0.00000000"],["84763.13000000","0.00000000"],["84771.54000000","0.00000000"],["84808.35000000","0.00616000"]]}}
{"stream":"dogeusdt@depth@100ms","data":{"e":"depthUpdate","E":1790299063274,"s":"DOGEUSDT","U":25516669302,"u":25516669305,"b":[["0.09679000","148229.00000000"],["0.09678000","168205.00000000"]],"a":[["0.09681000","20169.00000000"],["0.09691000","121238.00000000"]]}}
{"stream":"btcusdt@depth@100ms","data":{"e":"depthUpdate","E":1790299063314,"s":"BTCUSDT","U":100639383081,"u":100639383238,"b":[["84753.00000000","4.44500000"],["84752.97000000","0.68295000"],["84752.77000000","0.00000000"],["84751.64000000","0.01829000"],["84751.33000000","0.02994000"],["84748.94000000","0.00000000"],["84748.93000000","0.02186000"],["84746.61000000","0.03539000"],["84745.97000000","2.05898000"],["84744.25000000","0.10462000"],["84744.14000000","0.00000000"],["84743.18000000","0.30018000"],["84743.12000000","0.30007000"],["84742.38000000","0.05348000"],["84736.79000000","0.00007000"],["84735.36000000","0.00000000"],["84731.83000000","0.05800000"],["84728.13000000","0.11802000"],["84724.22000000","0.00000000"],["84711.81000000","0.02283000"],["84705.22000000","0.00000000"],["84689.07000000","0.00000000"],["84647.26000000","0.01689000"],["84635.91000000","0.00000000"],["84630.29000000","0.00000000"],["84597.70000000","1.41413000"],["84582.01000000","0.01729000"],["84581.52000000","0.00000000"]],"a":[["84753.01000000","0.14582000"],["84754.79000000","0.00000000"],["84754.80000000","0.00000000"],["84754.81000000","0.00000000"],["84754.82000000","0.00000000"],["84754.99000000","0.00014000"],["84755.00000000","0.11880000"],["84755.08000000","0.00000000"],["84755.09000000","0.00006000"],["84755.16000000","0.00000000"],["84755.97000000","0.00000000"],["84756.78000000","0.00000000"],["84757.51000000","0.00020000"],["84757.52000000","0.10474000"],["84757.59000000","0.00000000"],["84757.67000000","0.00000000"],["84757.83000000","0.00000000"],["84758.19000000","0.18847000"],["84758.20000000","0.17894000"],["84758.21000000","0.00006000"],["84758.22000000","0.00000000"],["84758.40000000","0.00000000"],["84759.10000000","0.00000000"],["84759.17000000","0.00000000"],["84759.21000000","0.00000000"],["84759.50000000","0.00006000"],["84759.58000000","0.00007000"],["84759.59000000","0.03000000"],["84759.66000000","0.00006000"],["84759.67000000","0.01103000"],["84759.72000000","0.01092000"],["84759.94000000","0.00000000"],["84760.02000000","0.00000000"],["84760.12000000","0.17880000"],["84760.13000000","0.00000000"],["84760.78000000","0.00949000"],["84760.83000000","0.00000000"],["84761.50000000","0.00000000"],["84761.64000000","0.00000000"],["84761.73000000","0.02006000"],["84761.83000000","0.17880000"],["84761.86000000","0.00000000"],["84762.15000000","0.70782000"],["84762.16000000","2.12381000"],["84762.17000000","0.00000000"],["84762.18000000","0.00000000"],["84762.45000000","0.00000000"],["84762.99000000","0.00012000"],["84763.20000000","0.00187000"],["84763.83000000","0.00000000"],["84765.44000000","0.00000000"],["84766.01000000","0.03000000"],["84766.06000000","0.00000000"],["84766.36000000","0.00236000"],["84766.38000000","0.35516000"],["84766.39000000","0.00010000"],["84767.13000000","0.00200000"],["84767.68000000","0.00590000"],["84768.13000000","0.00000000"],["84769.89000000","0.00800000"],["84775.17000000","0.06013000"],["84776.74000000","0.00000000"],["84778.25000000","0.00000000"],["84780.78000000","0.11795000"],["84781.83000000","0.00000000"],["84782.59000000","0.05332000"],["84784.67000000","0.29503000"],["84787.65000000","0.19632000"],["84788.90000000","0.29503000"],["84799.26000000","0.00000000"],["84808.24000000","0.00000000"],["84828.05000000","0.00000000"],["84854.07000000","0.00000000"],["84860.00000000","0.01275000"],["84881.37000000","0.05447000"],["84897.02000000","2.12381000"],["84903.53000000","0.00000000"],["84919.77000000","1.41413000"],["85081.50000000","0.00000000"],["85162.53000000","0.00000000"],["85180.70000000","0.00000000"],["85243.56000000","0.00000000"],["89076.24000000","0.00010000"]]}}
{"stream":"dogeusdt@depth@100ms","data":{"e":"depthUpdate","E":1790299063374,"s":"DOGEUSDT","U":25516669306,"u":25516669317,"b":[["0.09636000","124590.00000000"],["0.09633000","99070.00000000"]],"a":[["0.09680000","44.00000000"],["0.09682000","19956.00000000"],["0.09683000","64363.00000000"]]}}
{"stream":"btcusdt@depth@100ms","data":{"e":"depthUpdate","E":1790299063414,"s":"BTCUSDT","U":100639383239,"u":100639383377,"b":[["84753.00000000","4.44506000"],["84752.99000000","0.00026000"],["84752.98000000","0.22781000"],["84751.66000000","0.00000000"],["84751.65000000","0.00000000"],["84751.34000000","0.00000000"],["84751.24000000","0.00400000"],["84750.29000000","0.00000000"],["84748.94000000","0.00000000"],["84745.99000000","0.68743000"],["84742.38000000","0.01123000"],["84735.41000000","0.59423000"],["84731.35000000","0.00000000"],["84728.47000000","0.00000000"],["84717.32000000","0.00000000"],["84713.29000000","0.00000000"],["84701.02000000","0.00436000"],["84663.42000000","0.10113000"],["84663.41000000","0.00000000"],["84630.32000000","0.03681000"],["84629.32000000","0.00000000"],["84617.63000000","0.01200000"],["84598.59000000","0.53050000"],["83930.90000000","0.00306000"],["83913.46000000","0.00594000"],["83633.83000000","0.00596000"],["83481.71000000","0.00024000"],["83464.36000000","0.00598000"],["83040.68000000","0.00600000"],["82617.01000000","0.00604000"],["82193.33000000","0.00606000"],["76277.70000000","0.00075000"],["67788.32000000","0.00087000"]],"a":[["84753.01000000","0.35400000"],["84753.02000000","0.00067000"],["84753.03000000","0.00012000"],["84754.79000000","0.17882000"],["84754.99000000","0.00020000"],["84755.00000000","0.11886000"],["84756.56000000","0.00014000"],["84756.57000000","0.17880000"],["84757.52000000","0.10474000"],["84758.16000000","0.00000000"],["84758.17000000","0.00014000"],["84758.18000000","0.16118000"],["84758.19000000","0.18833000"],["84758.20000000","0.00006000"],["84758.47000000","0.00000000"],["84758.48000000","0.03539000"],["84759.50000000","0.00000000"],["84759.58000000","0.00000000"],["84759.59000000","0.03006000"],["84759.75000000","0.00000000"],["84761.83000000","0.17886000"],["84763.23000000","0.00048000"],["84763.55000000","0.00047000"],["84769.89000000","0.00800000"],["84778.80000000","0.00400000"],["84795.76000000","0.00400000"],["84797.88000000","0.00000000"],["84815.28000000","0.01200000"],["84854.02000000","0.00000000"],["84998.29000000","0.00006000"],["85002.52000000","0.00388000"]]}}
{"stream":"btcusdt@depth@100ms","data":{"e":"depthUpdate","E":1790299063514,"s":"BTCUSDT","U":100639383378,"u":100639383441,"b":[["84753.00000000","4.46767000"],["84751.74000000","0.00200000"],["84748.93000000","0.02192000"],["84748.76000000","0.01089000"],["84746.62000000","0.00200000"],["84738.65000000","0.00006000"],["84728.73000000","0.00200000"],["83930.90000000","0.00603000"],["83923.93000000","0.00297000"],["83651.21000000","0.00596000"],["83644.27000000","0.00298000"],["83481.71000000","0.00016000"],["83481.70000000","0.00626000"],["83474.78000000","0.00298000"],["83057.94000000","0.00300000"],["82634.17000000","0.00302000"],["82210.41000000","0.00303000"],["76277.70000000","0.00090000"],["67802.40000000","0.00232000"]],"a":[["84753.01000000","0.35419000"],["84753.02000000","0.00074000"],["84754.78000000","0.00020000"],["84756.57000000","0.00000000"],["84757.49000000","0.00024000"],["84757.52000000","0.10468000"],["84758.17000000","0.00000000"],["84758.18000000","0.00007000"],["84758.19000000","0.03766000"],["84759.72000000","0.01086000"],["84760.12000000","0.00000000"],["84760.13000000","0.17882000"],["84761.73000000","0.02000000"],["84761.83000000","0.00006000"],["84761.91000000","0.17882000"],["84762.14000000","0.17882000"],["84770.32000000","0.00400000"],["84772.56000000","0.00006000"],["84789.66000000","0.22000000"],["84795.76000000","0.00000000"],["84799.26000000","0.00006000"],["84816.10000000","0.44132000"],["84842.80000000","1.33550000"],["84843.89000000","1.57930000"],["85180.70000000","0.00006000"]]}}
{"stream":"dogeusdt@depth@100ms","data":{"e":"depthUpdate","E":1790299063574,"s":"DOGEUSDT","U":25516669318,"u":25516669320,"b":[],"a":[["0.09680000","20549.00000000"],["0.09684000","208677.00000000"]]}}
{"stream":"btcusdt@depth@100ms","data":{"e":"depthUpdate","E":1790299063614,"s":"BTCUSDT","U":100639383442,"u":100639383499,"b":[["84751.99000000","0.00000000"],["84751.74000000","0.00000000"],["83481.71000000","0.00024000"],["67802.40000000","0.00232000"],["67802.00000000","0.00000000"],["67788.32000000","0.00058000"]],"a":[["84753.01000000","0.35426000"],["84753.02000000","0.00074000"],["84754.79000000","0.00000000"],["84755.00000000","0.11880000"],["84755.16000000","0.00013000"],["84755.35000000","0.00007000"],["84755.97000000","0.00013000"],["84756.56000000","0.00000000"],["84756.78000000","0.00013000"],["84757.52000000","0.10474000"],["84757.59000000","0.00013000"],["84758.16000000","0.00014000"],["84758.17000000","0.14462000"],["84758.18000000","0.00000000"],["84758.19000000","0.00000000"],["84758.40000000","0.00013000"],["84758.47000000","0.00000000"],["84759.72000000","0.01092000"],["84760.13000000","0.00000000"],["84762.14000000","0.00000000"],["84792.87000000","0.00000000"],["84813.19000000","0.32768000"]]}}
{"stream":"dogeusdt@depth@100ms","data":{"e":"depthUpdate","E":1790299063674,"s":"DOGEUSDT","U":25516669321,"u":25516669325,"b":[],"a":[["0.09680000","20538.00000000"],["0.09682000","28872.00000000"],["0.09683000","85161.00000000"],["0.09684000","189448.00000000"],["0.09703000","185614.00000000"]]}}
{"stream":"btcusdt@depth@100ms","data":{"e":"depthUpdate","E":1790299063714,"s":"BTCUSDT","U":100639383500,"u":100639383587,"b":[["84735.40000000","1.24154000"],["84663.42000000","0.04313000"],["84546.20000000","0.00733000"],["84526.01000000","0.00000000"],["83481.71000000","0.00024000"],["76277.70000000","0.00105000"]],"a":[["84753.01000000","0.35413000"],["84753.02000000","0.00074000"],["84754.78000000","0.00000000"],["84755.00000000","0.11886000"],["84756.56000000","0.00020000"],["84756.57000000","0.16663000"],["84757.52000000","0.10468000"],["84758.14000000","0.00020000"],["84758.15000000","0.08814000"],["84758.16000000","0.00000000"],["84758.17000000","0.00000000"],["84758.47000000","0.00007000"],["84759.21000000","0.00013000"],["84759.58000000","0.00000000"],["84759.67000000","0.01693000"],["84759.72000000","0.01086000"],["84760.02000000","0.00013000"],["84760.13000000","0.17882000"],["84760.78000000","0.00943000"],["84760.83000000","0.00013000"],["84761.64000000","0.00013000"],["84761.83000000","0.00000000"],["84761.90000000","0.00400000"],["84762.14000000","0.17882000"],["84762.45000000","0.00013000"],["84769.89000000","0.00200000"]]}}
{"stream":"dogeusdt@depth@100ms","data":{"e":"depthUpdate","E":1790299063774,"s":"DOGEUSDT","U":25516669326,"u":25516669326,"b":[],"a":[["0.09681000","26126.00000000"]]}}
{"stream":"btcusdt@depth@100ms","data":{"e":"depthUpdate","E":1790299063814,"s":"BTCUSDT","U":100639383588,"u":100639383599,"b":[["84748.76000000","0.01095000"],["84746.62000000","0.00600000"],["83481.70000000","0.00626000"],["67788.32000000","0.00029000"]],"a":[["84761.90000000","0.00000000"],["84769.89000000","0.00600000"],["84783.92000000","0.08936000"],["85081.50000000","2.00000000"]]}}
