{"stream":"dogeusdt@depth@100ms","data":{"e":"depthUpdate","E":1790299063874,"s":"DOGEUSDT","U":25516669327,"u":25516669327,"b":[["0.09679000","140229.00000000"]],"a":[]}}
{"stream":"btcusdt@depth@100ms","data":{"e":"depthUpdate","E":1790299063914,"s":"BTCUSDT","U":100639383600,"u":100639383632,"b":[["84751.49000000","0.00000000"],["84748.76000000","0.01089000"],["84746.62000000","0.00200000"],["84698.86000000","0.00000000"],["83481.71000000","0.00024000"],["76277.70000000","0.00120000"]],"a":[["84753.01000000","0.35427000"],["84753.02000000","0.00088000"],["84756.57000000","0.00000000"],["84757.52000000","0.10474000"],["84757.93000000","0.00341000"],["84757.97000000","0.01705000"],["84760.12000000","0.17350000"],["84760.13000000","0.00000000"],["84761.90000000","0.17882000"],["84761.91000000","0.00000000"],["84762.14000000","0.00000000"],["84763.04000000","0.00000000"],["84766.38000000","0.00000000"],["84766.39000000","0.00000000"],["84768.44000000","0.00007000"],["84843.89000000","0.00000000"]]}}
{"stream":"btcusdt@depth@100ms","data":{"e":"depthUpdate","E":1790299064014,"s":"BTCUSDT","U":100639383633,"u":100639383674,"b":[["84753.00000000","4.46767000"],["84746.62000000","0.00000000"],["84745.97000000","2.05709000"],["84724.99000000","0.00442000"],["84658.37000000","0.04600000"],["83481.71000000","0.00016000"],["76277.00000000","0.00272000"],["67788.32000000","0.00000000"]],"a":[["84753.01000000","0.64828000"],["84753.02000000","0.00095000"],["84755.00000000","0.11892000"],["84756.56000000","0.00014000"],["84756.57000000","0.17882000"],["84757.50000000","0.00020000"],["84757.51000000","0.17902000"],["84757.96000000","0.00000000"],["84758.47000000","0.00000000"],["84759.67000000","0.00590000"],["84760.12000000","0.00000000"],["84766.39000000","0.35516000"],["84789.40000000","0.00842000"],["84813.96000000","0.02000000"],["84842.80000000","0.98418000"],["86024.31000000","0.00030000"]]}}
{"stream":"dogeusdt@depth@100ms","data":{"e":"depthUpdate","E":1790299064074,"s":"DOGEUSDT","U":25516669328,"u":25516669339,"b":[],"a":[["0.09680000","61732.00000000"],["0.09681000","20169.00000000"],["0.09682000","26228.00000000"],["0.09683000","76303.00000000"],["0.09695000","306371.00000000"],["0.09699000","498962.00000000"]]}}
{"stream":"btcusdt@depth@100ms","data":{"e":"depthUpdate","E":1790299064114,"s":"BTCUSDT","U":100639383675,"u":100639383699,"b":[["84753.00000000","4.46038000"],["84747.71000000","0.00012000"],["84746.90000000","0.00006000"],["84745.98000000","0.43022000"],["84744.53000000","0.02384000"],["84743.51000000","0.00006000"],["84742.76000000","0.30595000"],["84733.90000000","0.00000000"],["83481.71000000","0.00024000"],["76277.70000000","0.00135000"],["76271.37000000","0.00000000"],["67802.40000000","0.00232000"]],"a":[["84753.01000000","0.64815000"],["84758.15000000","0.03782000"],["84758.30000000","0.00012000"],["84759.69000000","0.01106000"],["84760.42000000","0.00012000"],["84762.54000000","0.00012000"],["84764.66000000","0.00012000"],["84766.78000000","0.00012000"],["84768.90000000","0.00012000"],["84840.46000000","0.00000000"],["84858.09000000","0.00022000"]]}}
{"stream":"dogeusdt@depth@100ms","data":{"e":"depthUpdate","E":1790299064174,"s":"DOGEUSDT","U":25516669340,"u":25516669342,"b":[],"a":[["0.09687000","287255.00000000"],["0.09688000","406421.00000000"]]}}
{"stream":"btcusdt@depth@100ms","data":{"e":"depthUpdate","E":1790299064214,"s":"BTCUSDT","U":100639383700,"u":100639383728,"b":[["84746.61000000","0.03545000"],["84746.00000000","0.00600000"],["84685.07000000","0.00000000"],["84634.35000000","0.00010000"],["83481.71000000","0.00024000"],["76277.70000000","0.00150000"],["67802.40000000","0.00203000"],["67802.00000000","0.00000000"]],"a":[["84753.01000000","0.64808000"],["84753.02000000","0.00088000"],["84756.57000000","0.17888000"],["84757.19000000","0.00590000"],["84757.50000000","0.00006000"],["84757.51000000","0.00020000"],["84758.47000000","0.00007000"],["84759.59000000","0.03000000"],["84759.67000000","0.00000000"],["84760.13000000","0.17882000"],["84762.14000000","0.17505000"],["84769.72000000","0.02000000"],["84822.55000000","0.02000000"]]}}
{"stream":"dogeusdt@depth@100ms","data":{"e":"depthUpdate","E":1790299064274,"s":"DOGEUSDT","U":25516669343,"u":25516669346,"b":[["0.09679000","140021.00000000"],["0.09675000","132137.00000000"]],"a":[["0.09699000","523477.00000000"],["0.09703000","106426.00000000"]]}}
{"stream":"btcusdt@depth@100ms","data":{"e":"depthUpdate","E":1790299064314,"s":"BTCUSDT","U":100639383729,"u":100639383754,"b":[["84750.84000000","0.00200000"],["84750.28000000","0.02192000"],["84749.68000000","0.03539000"],["84748.93000000","0.02186000"],["84746.61000000","0.00006000"],["84742.38000000","0.01117000"],["84721.41000000","0.04163000"],["84715.26000000","0.00000000"],["84710.27000000","0.00000000"],["84706.79000000","0.08950000"],["84704.97000000","0.00353000"]],"a":[["84753.01000000","0.64808000"],["84753.02000000","0.00081000"],["84757.50000000","0.00000000"],["84758.15000000","0.08644000"],["84758.20000000","0.00000000"],["84758.47000000","0.00000000"],["84758.48000000","0.00000000"],["84759.58000000","0.00007000"],["84760.14000000","0.00000000"],["84762.14000000","0.00000000"],["84780.14000000","0.00000000"],["84783.92000000","0.00000000"],["84792.00000000","0.70000000"],["85162.53000000","2.00000000"]]}}
{"stream":"dogeusdt@depth@100ms","data":{"e":"depthUpdate","E":1790299064374,"s":"DOGEUSDT","U":25516669347,"u":25516669349,"b":[],"a":[["0.09680000","60240.00000000"],["0.09682000","18627.00000000"],["0.09687000","275031.00000000"]]}}
{"stream":"btcusdt@depth@100ms","data":{"e":"depthUpdate","E":1790299064414,"s":"BTCUSDT","U":100639383755,"u":100639383776,"b":[["84750.28000000","0.02186000"],["84749.68000000","0.00000000"],["84748.76000000","0.01095000"],["84746.61000000","0.03545000"],["84746.00000000","0.00800000"],["84731.92000000","0.00000000"],["84717.68000000","0.00910000"],["84689.55000000","0.00000000"],["84655.66000000","0.00000000"],["84651.20000000","0.00000000"],["83481.71000000","0.00024000"],["76277.70000000","0.00165000"],["67802.40000000","0.00174000"]],"a":[["84753.01000000","0.64815000"],["84756.56000000","0.00020000"],["84758.15000000","0.08650000"],["84758.48000000","0.00007000"],["84758.49000000","0.03539000"],["84759.59000000","0.03006000"],["84871.65000000","0.00010000"]]}}
{"stream":"dogeusdt@depth@100ms","data":{"e":"depthUpdate","E":1790299064474,"s":"DOGEUSDT","U":25516669350,"u":25516669353,"b":[["0.09679000","148021.00000000"],["0.09636000","265.00000000"],["0.09634000","124595.00000000"]],"a":[["0.09680000","41166.00000000"],["0.09708000","4808.00000000"]]}}
{"stream":"btcusdt@depth@100ms","data":{"e":"depthUpdate","E":1790299064514,"s":"BTCUSDT","U":100639383777,"u":100639383785,"b":[["84738.65000000","0.00006000"],["83481.71000000","0.00016000"],["67802.40000000","0.00290000"]],"a":[["84772.56000000","0.00006000"],["84774.77000000","0.00007000"]]}}
{"stream":"dogeusdt@depth@100ms","data":{"e":"depthUpdate","E":1790299064574,"s":"DOGEUSDT","U":25516669354,"u":25516669355,"b":[],"a":[["0.09701000","10136.00000000"],["0.09725000","301785.00000000"]]}}
{"stream":"btcusdt@depth@100ms","data":{"e":"depthUpdate","E":1790299064614,"s":"BTCUSDT","U":100639383786,"u":100639383794,"b":[["83481.71000000","0.00024000"],["76277.70000000","0.00180000"],["67802.40000000","0.00261000"]],"a":[["84754.99000000","0.00014000"],["84769.89000000","0.01000000"],["84775.84000000","0.00377000"]]}}
{"stream":"btcusdt@depth@100ms","data":{"e":"depthUpdate","E":1790299064714,"s":"BTCUSDT","U":100639383795,"u":100639383798,"b":[["83481.71000000","0.00024000"]],"a":[["84754.99000000","0.00020000"],["84766.12000000","0.00209000"]]}}
{"stream":"dogeusdt@depth@100ms","data":{"e":"depthUpdate","E":1790299064774,"s":"DOGEUSDT","U":25516669356,"u":25516669356,"b":[],"a":[["0.09700000","1447615.00000000"]]}}
{"stream":"btcusdt@depth@100ms","data":{"e":"depthUpdate","E":1790299064814,"s":"BTCUSDT","U":100639383799,"u":100639383806,"b":[["83481.70000000","0.00626000"],["76277.70000000","0.00210000"],["67802.40000000","0.00232000"]],"a":[["84769.88000000","0.00200000"],["84818.23000000","0.00377000"],["85243.56000000","2.00000000"]]}}
{"stream":"dogeusdt@depth@100ms","data":{"e":"depthUpdate","E":1790299064874,"s":"DOGEUSDT","U":25516669357,"u":25516669361,"b":[["0.09679000","140021.00000000"],["0.09678000","180922.00000000"],["0.09677000","185445.00000000"],["0.09670000","172180.00000000"]],"a":[["0.09682000","30200.00000000"]]}}
{"stream":"btcusdt@depth@100ms","data":{"e":"depthUpdate","E":1790299064914,"s":"BTCUSDT","U":100639383807,"u":100639383869,"b":[["84753.00000000","4.45448000"],["84750.84000000","0.00000000"],["84749.29000000","0.00000000"],["84748.93000000","0.02192000"],["84748.77000000","0.00590000"],["84747.55000000","0.00024000"],["84746.61000000","0.03551000"],["84746.02000000","0.00014000"],["84746.01000000","0.35516000"],["84746.00000000","0.00814000"],["84745.99000000","0.68743000"],["84745.98000000","0.07506000"],["84728.73000000","0.00000000"],["84727.55000000","0.00000000"],["83481.71000000","0.00024000"],["76277.70000000","0.00210000"]],"a":[["84753.01000000","1.43331000"],["84753.02000000","0.00074000"],["84754.79000000","0.00000000"],["84754.99000000","0.06964000"],["84755.00000000","0.11886000"],["84756.56000000","0.00000000"],["84756.57000000","0.00006000"],["84757.51000000","0.00014000"],["84757.96000000","0.00014000"],["84758.14000000","0.00014000"],["84761.89000000","0.00200000"],["84762.14000000","0.85230000"],["84766.12000000","0.00009000"],["84769.89000000","0.00200000"],["84786.45000000","0.00000000"],["84799.26000000","0.00000000"],["85180.70000000","0.00000000"]]}}
{"stream":"dogeusdt@depth@100ms","data":{"e":"depthUpdate","E":1790299064974,"s":"DOGEUSDT","U":25516669362,"u":25516669368,"b":[],"a":[["0.09680000","61732.00000000"],["0.09681000","32880.00000000"],["0.09682000","45642.00000000"],["0.09683000","55505.00000000"]]}}
{"stream":"btcusdt@depth@100ms","data":{"e":"depthUpdate","E":1790299065014,"s":"BTCUSDT","U":100639383870,"u":100639383894,"b":[["84753.00000000","4.45212000"],["84751.34000000","0.00236000"],["84741.31000000","0.15000000"],["83481.71000000","0.00016000"],["76277.00000000","0.00272000"],["67802.40000000","0.00319000"]],"a":[["84753.01000000","1.43330000"],["84754.98000000","0.00020000"],["84758.15000000","0.03788000"],["84758.48000000","0.00000000"],["84759.58000000","0.00000000"],["84760.13000000","0.00000000"],["84761.89000000","0.00000000"],["84769.71000000","0.00400000"],["84852.14000000","0.00377000"],["86024.31000000","0.00030000"]]}}
{"stream":"btcusdt@depth@100ms","data":{"e":"depthUpdate","E":1790299065114,"s":"BTCUSDT","U":100639383895,"u":100639383924,"b":[["84753.00000000","4.43021000"],["84745.99000000","0.68737000"],["84745.98000000","0.00006000"],["84724.35000000","0.76719000"],["83481.71000000","0.00024000"],["76277.70000000","0.00225000"],["67802.40000000","0.00319000"]],"a":[["84753.01000000","1.80380000"],["84753.02000000","0.00081000"],["84761.89000000","0.00400000"],["84763.23000000","0.00000000"],["84769.50000000","0.00000000"],["84769.71000000","0.00000000"],["84769.88000000","0.00000000"],["84777.76000000","0.11796000"],["84781.78000000","0.00000000"],["84797.69000000","0.02346000"],["84803.05000000","0.76648000"],["84852.04000000","0.00006000"],["84855.43000000","0.00006000"]]}}
{"stream":"dogeusdt@depth@100ms","data":{"e":"depthUpdate","E":1790299065174,"s":"DOGEUSDT","U":25516669369,"u":25516669375,"b":[["0.09678000","172922.00000000"],["0.09677000","166843.00000000"],["0.09674000","325387.00000000"],["0.09670000","190782.00000000"]],"a":[["0.09682000","34047.00000000"]]}}
{"stream":"btcusdt@depth@100ms","data":{"e":"depthUpdate","E":1790299065214,"s":"BTCUSDT","U":100639383925,"u":100639383933,"b":[["84753.00000000","4.42821000"],["84748.63000000","0.00200000"],["84748.14000000","0.00200000"],["84742.37000000","0.00000000"],["84738.42000000","0.00377000"],["83481.71000000","0.00024000"],["67802.40000000","0.00290000"]],"a":[["84761.89000000","0.00600000"]]}}
{"stream":"dogeusdt@depth@100ms","data":{"e":"depthUpdate","E":1790299065274,"s":"DOGEUSDT","U":25516669376,"u":25516669377,"b":[],"a":[["0.09697000","261799.00000000"],["0.09698000","501074.00000000"]]}}
{"stream":"btcusdt@depth@100ms","data":{"e":"depthUpdate","E":1790299065314,"s":"BTCUSDT","U":100639383934,"u":100639383957,"b":[["84753.00000000","4.42919000"],["84752.99000000","0.00075000"],["84725.87000000","0.00200000"],["84546.20000000","0.00000000"],["84544.98000000","0.00733000"],["76277.70000000","0.00240000"]],"a":[]}}
{"stream":"dogeusdt@depth@100ms","data":{"e":"depthUpdate","E":1790299065374,"s":"DOGEUSDT","U":25516669378,"u":25516669391,"b":[["0.09679000","148021.00000000"],["0.09678000","180922.00000000"],["0.09674000","317387.00000000"],["0.09663000","222305.00000000"]],"a":[["0.09680000","41166.00000000"],["0.09681000","20169.00000000"],["0.09682000","12333.00000000"],["0.09683000","64247.00000000"]]}}
{"stream":"btcusdt@depth@100ms","data":{"e":"depthUpdate","E":1790299065414,"s":"BTCUSDT","U":100639383958,"u":100639384112,"b":[["84753.00000000","4.43126000"],["84752.99000000","0.00068000"],["84752.94000000","0.00200000"],["84751.34000000","0.00000000"],["84748.63000000","0.00000000"],["84748.14000000","0.00000000"],["84746.02000000","0.00000000"],["84746.00000000","0.00400000"],["84740.28000000","0.25301000"],["84740.27000000","0.35412000"],["84738.32000000","0.00000000"],["84737.44000000","0.16051000"],["84735.23000000","0.00000000"],["84731.29000000","0.31874000"],["84702.96000000","0.00000000"],["84683.74000000","0.00000000"],["84662.15000000","0.00377000"],["83481.71000000","0.00024000"],["67802.40000000","0.00261000"]],"a":[["84753.01000000","0.56725000"],["84753.02000000","0.00067000"],["84754.98000000","0.00000000"],["84754.99000000","0.00020000"],["84756.57000000","0.00000000"],["84757.19000000","0.00000000"],["84757.49000000","0.00000000"],["84757.51000000","0.00020000"],["84757.52000000","0.10462000"],["84757.93000000","0.00000000"],["84757.96000000","0.00000000"],["84757.97000000","0.00006000"],["84758.14000000","0.00000000"],["84758.15000000","0.00006000"],["84758.34000000","0.00014000"],["84758.35000000","0.16836000"],["84758.48000000","0.00014000"],["84758.90000000","0.00000000"],["84759.58000000","0.00007000"],["84759.59000000","0.03000000"],["84759.69000000","0.00000000"],["84759.72000000","0.01092000"],["84759.78000000","0.01123000"],["84760.13000000","0.17882000"],["84760.71000000","0.00000000"],["84761.88000000","0.17882000"],["84761.89000000","0.79201000"],["84761.90000000","0.00000000"],["84762.13000000","2.12387000"],["84762.14000000","0.00000000"],["84762.15000000","0.00000000"],["84762.16000000","0.00000000"],["84763.84000000","0.00016000"],["84763.96000000","0.00448000"],["84765.21000000","0.00000000"],["84766.24000000","0.00236000"],["84766.36000000","0.00000000"],["84767.68000000","0.00600000"],["84769.89000000","0.00600000"],["84792.00000000","0.00000000"],["84799.26000000","0.00006000"],["85180.70000000","0.00006000"]]}}
{"stream":"dogeusdt@depth@100ms","data":{"e":"depthUpdate","E":1790299065474,"s":"DOGEUSDT","U":25516669392,"u":25516669395,"b":[["0.09666000","721838.00000000"],["0.09662000","240661.00000000"],["0.09661000","159995.00000000"]],"a":[["0.09680000","60240.00000000"]]}}
{"stream":"btcusdt@depth@100ms","data":{"e":"depthUpdate","E":1790299065514,"s":"BTCUSDT","U":100639384113,"u":100639384174,"b":[["84753.00000000","4.49441000"],["84752.99000000","0.00026000"],["84752.94000000","0.00000000"],["84749.74000000","0.00000000"],["84746.62000000","0.00400000"],["84742.76000000","0.30406000"],["84741.32000000","0.00013000"],["84739.85000000","0.00000000"],["84738.65000000","0.00006000"],["84725.87000000","0.00000000"],["83481.71000000","0.00016000"],["77944.04000000","0.00013000"],["76277.70000000","0.00263000"]],"a":[["84753.01000000","0.19714000"],["84753.02000000","0.00074000"],["84756.84000000","0.00095000"],["84757.52000000","0.10468000"],["84758.33000000","0.00014000"],["84758.34000000","0.14175000"],["84759.58000000","0.00000000"],["84766.24000000","0.00000000"],["84766.25000000","0.00000000"],["84766.83000000","0.00590000"],["84767.92000000","0.00236000"],["84772.56000000","0.00006000"],["84782.59000000","0.00000000"],["84787.65000000","0.00000000"],["84788.44000000","0.29552000"],["84790.96000000","0.05332000"],["84846.67000000","1.61352000"],["84846.68000000","1.57930000"],["84848.70000000","0.00000000"]]}}
{"stream":"dogeusdt@depth@100ms","data":{"e":"depthUpdate","E":1790299065574,"s":"DOGEUSDT","U":25516669396,"u":25516669397,"b":[["0.09677000","185445.00000000"]],"a":[["0.09683000","85832.00000000"]]}}
{"stream":"btcusdt@depth@100ms","data":{"e":"depthUpdate","E":1790299065614,"s":"BTCUSDT","U":100639384175,"u":100639384198,"b":[["84751.34000000","0.00590000"],["84751.33000000","0.03194000"],["84745.97000000","2.05119000"],["84736.79000000","0.00000000"],["84730.46000000","0.00007000"],["84696.05000000","0.00377000"],["84594.97000000","0.00117000"],["84594.60000000","0.00117000"],["84577.58000000","0.00000000"],["84576.02000000","0.00000000"],["83481.71000000","0.00024000"],["67802.40000000","0.00232000"]],"a":[["84753.01000000","0.19707000"],["84753.02000000","0.00067000"],["84754.99000000","0.00014000"],["84756.84000000","0.00000000"],["84757.66000000","0.00024000"],["84760.24000000","0.00095000"],["84766.75000000","0.00590000"],["84767.68000000","0.00010000"],["84768.40000000","0.00000000"],["84769.89000000","0.01000000"],["84775.84000000","0.00000000"],["84818.23000000","0.00000000"],["84852.14000000","0.00000000"]]}}
{"stream":"dogeusdt@depth@100ms","data":{"e":"depthUpdate","E":1790299065674,"s":"DOGEUSDT","U":25516669398,"u":25516669400,"b":[],"a":[["0.09682000","21449.00000000"],["0.09699000","521468.00000000"],["0.09715000","750896.00000000"]]}}
{"stream":"btcusdt@depth@100ms","data":{"e":"depthUpdate","E":1790299065714,"s":"BTCUSDT","U":100639384199,"u":100639384211,"b":[["84751.64000000","0.01835000"],["84735.38000000","0.00000000"],["84729.22000000","0.00200000"],["83481.71000000","0.00024000"],["76277.70000000","0.00278000"]],"a":[["84755.00000000","0.11892000"],["84756.56000000","0.00014000"],["84756.57000000","0.17038000"],["84758.33000000","0.00020000"],["84758.48000000","0.00000000"]]}}
{"stream":"dogeusdt@depth@100ms","data":{"e":"depthUpdate","E":1790299065774,"s":"DOGEUSDT","U":25516669401,"u":25516669404,"b":[],"a":[["0.09682000","18840.00000000"],["0.09683000","77090.00000000"],["0.09709000","320449.00000000"]]}}
{"stream":"btcusdt@depth@100ms","data":{"e":"depthUpdate","E":1790299065814,"s":"BTCUSDT","U":100639384212,"u":100639384241,"b":[["84751.33000000","0.02994000"],["84746.62000000","0.00000000"],["83481.70000000","0.00626000"],["76277.70000000","0.00293000"],["67802.40000000","0.00203000"],["67802.00000000","0.00200000"]],"a":[["84753.01000000","0.38219000"],["84753.02000000","0.00074000"],["84758.35000000","0.00000000"],["84762.13000000","0.00006000"],["84766.39000000","0.00000000"],["84767.13000000","0.00000000"],["84767.42000000","0.00000000"],["84769.88000000","0.00000000"],["84769.89000000","0.00600000"]]}}
{"stream":"dogeusdt@depth@100ms","data":{"e":"depthUpdate","E":1790299065874,"s":"DOGEUSDT","U":25516669405,"u":25516669405,"b":[["0.09679000","140021.00000000"]],"a":[]}}
{"stream":"btcusdt@depth@100ms","data":{"e":"depthUpdate","E":1790299065914,"s":"BTCUSDT","U":100639384242,"u":100639384282,"b":[["84753.00000000","4.50031000"],["84748.93000000","0.02186000"],["84748.77000000","0.00000000"],["84746.62000000","0.00400000"],["84735.39000000","0.00756000"],["83481.71000000","0.00024000"],["67802.00000000","0.00000000"]],"a":[["84753.01000000","0.38212000"],["84753.02000000","0.00067000"],["84756.56000000","0.00020000"],["84757.97000000","0.00000000"],["84758.34000000","0.09152000"],["84758.48000000","0.00007000"],["84760.24000000","0.00000000"],["84761.87000000","0.12950000"],["84761.89000000","0.00000000"],["84762.40000000","0.00010000"],["84762.44000000","0.00000000"],["84765.47000000","0.17882000"],["84766.39000000","0.17882000"],["84766.85000000","0.00000000"],["84767.25000000","0.00000000"],["84767.26000000","0.00200000"],["84768.40000000","0.00590000"],["84769.88000000","0.00000000"],["84769.89000000","0.01000000"]]}}
{"stream":"btcusdt@depth@100ms","data":{"e":"depthUpdate","E":1790299066014,"s":"BTCUSDT","U":100639384283,"u":100639384303,"b":[["84753.00000000","4.49441000"],["84751.65000000","0.00590000"],["84751.34000000","0.00000000"],["84751.22000000","0.00200000"],["84750.91000000","0.00590000"],["84746.62000000","0.00000000"],["83481.71000000","0.00016000"],["76277.70000000","0.00308000"],["67802.40000000","0.00290000"],["67802.00000000","0.00100000"]],"a":[["84753.01000000","0.38615000"],["84759.58000000","0.00095000"],["84763.50000000","0.00000000"],["84766.83000000","0.00000000"],["86024.31000000","0.00030000"]]}}
{"stream":"dogeusdt@depth@100ms","data":{"e":"depthUpdate","E":1790299066074,"s":"DOGEUSDT","U":25516669406,"u":25516669406,"b":[],"a":[["0.09749000","1044018.00000000"]]}}
{"stream":"btcusdt@depth@100ms","data":{"e":"depthUpdate","E":1790299066114,"s":"BTCUSDT","U":100639384304,"u":100639384316,"b":[["84752.97000000","0.68301000"],["84751.64000000","0.01829000"],["84751.33000000","0.03000000"],["84651.02000000","0.00006000"],["83481.71000000","0.00024000"],["77944.04000000","0.00000000"],["76277.00000000","0.00272000"],["67802.40000000","0.00290000"],["67802.00000000","0.00000000"]],"a":[["84780.21000000","0.02439000"],["84786.38000000","0.00200000"]]}}
{"stream":"dogeusdt@depth@100ms","data":{"e":"depthUpdate","E":1790299066174,"s":"DOGEUSDT","U":25516669407,"u":25516669414,"b":[["0.09678000","171722.00000000"],["0.09674000","325387.00000000"],["0.09659000","698441.00000000"]],"a":[["0.09680000","61732.00000000"],["0.09682000","52182.00000000"],["0.09683000","55505.00000000"]]}}
{"stream":"btcusdt@depth@100ms","data":{"e":"depthUpdate","E":1790299066214,"s":"BTCUSDT","U":100639384317,"u":100639384347,"b":[["84753.00000000","4.49504000"],["84752.99000000","0.00075000"],["84751.22000000","0.00000000"],["84750.91000000","0.00000000"],["84750.29000000","0.00590000"],["83481.71000000","0.00024000"],["76277.70000000","0.00323000"],["67802.40000000","0.00261000"]],"a":[["84753.01000000","0.68022000"],["84765.46000000","0.85230000"],["84766.37000000","0.17882000"],["84766.38000000","0.35516000"],["84766.39000000","0.00000000"],["84780.21000000","0.00472000"],["84869.41000000","0.00000000"],["84904.97000000","0.00099000"]]}}
{"stream":"dogeusdt@depth@100ms","data":{"e":"depthUpdate","E":1790299066274,"s":"DOGEUSDT","U":25516669415,"u":25516669442,"b":[["0.09679000","79289.00000000"],["0.09678000","90005.00000000"],["0.09677000","73647.00000000"],["0.09663000","212026.00000000"],["0.09647000","80833.00000000"]],"a":[["0.09680000","68997.00000000"],["0.09681000","29379.00000000"],["0.09682000","45675.00000000"],["0.09683000","155701.00000000"],["0.09685000","137306.00000000"]]}}
{"stream":"btcusdt@depth@100ms","data":{"e":"depthUpdate","E":1790299066314,"s":"BTCUSDT","U":100639384348,"u":100639384370,"b":[["84753.00000000","4.49511000"],["84751.33000000","0.03000000"],["84746.02000000","0.00400000"],["84732.50000000","0.00293000"],["84714.90000000","0.00000000"],["84704.97000000","0.00000000"],["67802.00000000","0.00000000"]],"a":[["84761.86000000","0.17819000"],["84761.87000000","0.42093000"],["84761.88000000","0.00000000"],["84765.45000000","0.00600000"],["84765.47000000","0.00000000"],["84766.37000000","0.00000000"],["84769.89000000","0.00400000"]]}}
{"stream":"dogeusdt@depth@100ms","data":{"e":"depthUpdate","E":1790299066374,"s":"DOGEUSDT","U":25516669443,"u":25516669482,"b":[["0.09679000","42328.00000000"],["0.09678000","59350.00000000"],["0.09677000","77647.00000000"],["0.09675000","129187.00000000"],["0.09674000","318566.00000000"],["0.09673000","331439.00000000"],["0.09669000","261506.00000000"],["0.09668000","225105.00000000"],["0.09654000","195654.00000000"]],"a":[["0.09680000","77023.00000000"],["0.09681000","30777.00000000"],["0.09682000","71647.00000000"],["0.09683000","163701.00000000"],["0.09684000","189526.00000000"],["0.09685000","137202.00000000"],["0.09686000","139776.00000000"],["0.09687000","267031.00000000"],["0.09688000","398421.00000000"],["0.09690000","205132.00000000"],["0.09693000","717069.00000000"],["0.09698000","327839.00000000"],["0.09699000","451097.00000000"]]}}
{"stream":"btcusdt@depth@100ms","data":{"e":"depthUpdate","E":1790299066414,"s":"BTCUSDT","U":100639384371,"u":100639384457,"b":[["84753.00000000","4.43515000"],["84752.99000000","0.00068000"],["84752.97000000","0.68295000"],["84751.65000000","0.00000000"],["84751.33000000","0.02994000"],["84750.29000000","0.00000000"],["84750.28000000","0.02192000"],["84749.31000000","0.01180000"],["84746.02000000","0.00414000"],["84746.00000000","0.00414000"],["84745.98000000","0.00013000"],["84704.97000000","0.00353000"],["84546.68000000","0.00733000"],["84544.98000000","0.00000000"],["83481.71000000","0.00024000"],["76277.70000000","0.00338000"],["67802.40000000","0.00232000"]],"a":[["84753.01000000","0.68028000"],["84753.02000000","0.00074000"],["84754.78000000","0.00014000"],["84754.79000000","0.17882000"],["84754.99000000","0.00020000"],["84757.51000000","0.00014000"],["84757.52000000","0.10468000"],["84758.31000000","0.00007000"],["84758.32000000","0.09152000"],["84758.33000000","0.00000000"],["84758.34000000","0.00000000"],["84758.48000000","0.00000000"],["84758.96000000","0.00012000"],["84760.13000000","0.17253000"],["84761.83000000","0.17882000"],["84761.84000000","1.02238000"],["84761.85000000","2.12381000"],["84761.86000000","0.00000000"],["84761.87000000","0.00152000"],["84765.45000000","0.00590000"],["84766.75000000","0.00000000"],["84767.92000000","0.00000000"],["84768.13000000","0.00236000"],["84769.18000000","0.00000000"],["84769.89000000","0.00800000"]]}}
{"stream":"dogeusdt@depth@100ms","data":{"e":"depthUpdate","E":1790299066474,"s":"DOGEUSDT","U":25516669483,"u":25516669484,"b":[],"a":[["0.09687000","258049.00000000"],["0.09697000","216609.00000000"]]}}
{"stream":"btcusdt@depth@100ms","data":{"e":"depthUpdate","E":1790299066514,"s":"BTCUSDT","U":100639384458,"u":100639384479,"b":[["84753.00000000","4.43126000"],["84750.86000000","0.00000000"],["84750.78000000","0.00200000"],["84738.65000000","0.00000000"],["84716.72000000","0.00000000"],["84663.42000000","1.09678000"],["84661.47000000","3.54453000"],["83481.71000000","0.00016000"],["76277.70000000","0.00353000"]],"a":[["84753.01000000","0.68035000"],["84754.78000000","0.00020000"],["84758.32000000","0.13132000"],["84761.61000000","0.00000000"],["84761.82000000","0.00600000"],["84769.89000000","0.00200000"],["84772.56000000","0.00000000"]]}}
{"stream":"dogeusdt@depth@100ms","data":{"e":"depthUpdate","E":1790299066574,"s":"DOGEUSDT","U":25516669485,"u":25516669491,"b":[["0.09679000","69910.00000000"],["0.09678000","80051.00000000"],["0.09674000","318618.00000000"],["0.09673000","331387.00000000"]],"a":[["0.09680000","69023.00000000"],["0.09682000","60074.00000000"],["0.09684000","197526.00000000"]]}}
{"stream":"btcusdt@depth@100ms","data":{"e":"depthUpdate","E":1790299066614,"s":"BTCUSDT","U":100639384480,"u":100639384490,"b":[["84751.27000000","0.00236000"],["84742.74000000","0.00188000"],["84738.65000000","0.00006000"],["83481.71000000","0.00024000"],["67802.40000000","0.00203000"],["67802.00000000","0.00000000"]],"a":[["84772.56000000","0.00006000"],["84814.14000000","0.00377000"],["84891.87000000","0.01848000"],["84939.13000000","0.00000000"]]}}
{"stream":"dogeusdt@depth@100ms","data":{"e":"depthUpdate","E":1790299066674,"s":"DOGEUSDT","U":25516669492,"u":25516669493,"b":[["0.09679000","42328.00000000"]],"a":[["0.09686000","147970.00000000"]]}}
{"stream":"btcusdt@depth@100ms","data":{"e":"depthUpdate","E":1790299066714,"s":"BTCUSDT","U":100639384491,"u":100639384502,"b":[["84729.22000000","0.00000000"],["84727.62000000","0.00213000"],["83481.71000000","0.00024000"],["76277.70000000","0.00353000"],["67802.40000000","0.00203000"]],"a":[["84753.01000000","0.86619000"],["84756.56000000","0.00014000"],["84761.81000000","0.00200000"]]}}
{"stream":"dogeusdt@depth@100ms","data":{"e":"depthUpdate","E":1790299066774,"s":"DOGEUSDT","U":25516669494,"u":25516669495,"b":[],"a":[["0.09680000","77023.00000000"],["0.09685000","129202.00000000"]]}}
{"stream":"btcusdt@depth@100ms","data":{"e":"depthUpdate","E":1790299066814,"s":"BTCUSDT","U":100639384503,"u":100639384690,"b":[["84753.00000000","3.58259000"],["84752.99000000","0.00082000"],["84751.64000000","0.01823000"],["84751.48000000","0.01098000"],["84751.33000000","0.00000000"],["84751.27000000","0.00000000"],["84751.15000000","0.00236000"],["84750.96000000","0.00000000"],["84750.91000000","0.00000000"],["84750.78000000","0.00000000"],["84750.28000000","0.02192000"],["84749.32000000","0.00236000"],["84749.31000000","0.00000000"],["84749.06000000","0.02000000"],["84748.84000000","0.00000000"],["84748.76000000","0.01101000"],["84747.94000000","0.00000000"],["84747.72000000","0.00596000"],["84747.43000000","0.00000000"],["84747.01000000","0.00590000"],["84746.88000000","0.00206000"],["84746.81000000","0.00236000"],["84746.61000000","0.03551000"],["84746.03000000","0.00007000"],["84746.02000000","0.34685000"],["84746.01000000","0.00000000"],["84745.98000000","0.00020000"],["84745.57000000","0.00000000"],["84745.12000000","0.00000000"],["84744.14000000","0.00000000"],["84744.02000000","0.00200000"],["84743.87000000","0.00000000"],["84743.86000000","0.51897000"],["84743.85000000","1.01471000"],["84743.18000000","0.00018000"],["84743.12000000","0.00007000"],["84742.84000000","0.00018000"],["84742.76000000","0.00400000"],["84742.43000000","0.00006000"],["84742.39000000","0.04215000"],["84741.32000000","0.00000000"],["84740.28000000","0.14728000"],["84740.27000000","0.00000000"],["84738.61000000","0.00013000"],["84731.36000000","0.00000000"],["84727.62000000","0.00013000"],["84710.44000000","1.17487000"],["84709.79000000","1.16902000"],["84639.17000000","2.12381000"],["84617.63000000","0.00000000"],["83481.70000000","0.00626000"],["67802.40000000","0.00174000"]],"a":[["84753.01000000","2.07142000"],["84753.02000000","0.00039000"],["84754.69000000","0.00095000"],["84754.77000000","0.00014000"],["84754.78000000","0.06713000"],["84754.79000000","0.00000000"],["84754.93000000","0.00012000"],["84754.99000000","0.00014000"],["84755.00000000","0.11886000"],["84756.56000000","0.00000000"],["84756.57000000","0.00000000"],["84756.77000000","0.00000000"],["84757.52000000","0.00006000"],["84757.62000000","0.01112000"],["84758.31000000","0.00014000"],["84758.32000000","0.08856000"],["84758.48000000","0.00007000"],["84759.13000000","0.00200000"],["84759.58000000","0.00000000"],["84760.13000000","0.00000000"],["84761.72000000","0.17882000"],["84761.81000000","0.00600000"],["84761.82000000","0.00000000"],["84761.83000000","0.00000000"],["84762.39000000","0.00590000"],["84763.75000000","0.00236000"],["84763.96000000","0.00400000"],["84764.88000000","0.00000000"],["84767.26000000","0.00000000"],["84768.13000000","0.00000000"],["84768.40000000","0.00000000"],["84769.89000000","0.00200000"],["84770.42000000","0.13131000"],["84773.98000000","0.15955000"],["84776.21000000","0.00000000"],["84786.38000000","0.00000000"],["84799.26000000","0.00000000"],["85180.70000000","0.00000000"]]}}
{"stream":"btcusdt@depth@100ms","data":{"e":"depthUpdate","E":1790299066914,"s":"BTCUSDT","U":100639384691,"u":100639384740,"b":[["84753.00000000","3.58259000"],["84752.99000000","0.00075000"],["84751.64000000","0.01829000"],["84746.91000000","0.00200000"],["84746.03000000","0.00014000"],["84743.18000000","0.00012000"],["84742.39000000","0.04209000"],["83481.71000000","0.00024000"],["76277.70000000","0.00353000"]],"a":[["84753.01000000","2.07486000"],["84753.02000000","0.00032000"],["84754.73000000","0.01136000"],["84754.78000000","0.03586000"],["84755.00000000","0.11886000"],["84755.09000000","0.00000000"],["84755.44000000","0.00000000"],["84757.51000000","0.00000000"],["84758.48000000","0.00014000"],["84763.20000000","0.00000000"],["84763.53000000","0.00000000"],["84763.55000000","0.00000000"],["84774.64000000","0.11796000"],["84777.76000000","0.00000000"]]}}
{"stream":"btcusdt@depth@100ms","data":{"e":"depthUpdate","E":1790299067014,"s":"BTCUSDT","U":100639384741,"u":100639384774,"b":[["84753.00000000","3.92689000"],["84752.98000000","0.22781000"],["84747.72000000","0.00006000"],["84747.02000000","0.00590000"],["84747.01000000","0.00000000"],["84746.81000000","0.00000000"],["84746.03000000","0.00000000"],["84746.02000000","0.00200000"],["84745.91000000","0.00236000"],["84744.89000000","0.00590000"],["84743.87000000","0.00007000"],["84742.56000000","0.00048000"],["84628.00000000","0.02800000"],["83481.71000000","0.00016000"],["76277.70000000","0.00338000"],["67802.40000000","0.00261000"]],"a":[["84753.01000000","2.07493000"],["84753.02000000","0.00039000"],["84754.72000000","0.00007000"],["84759.13000000","0.00000000"],["84759.72000000","0.01492000"],["84761.31000000","0.00200000"],["84762.84000000","0.00590000"],["84762.85000000","0.00236000"],["84763.75000000","0.00000000"],["84765.45000000","0.00000000"],["84793.64000000","0.00000000"],["84848.05000000","0.00377000"],["84888.34000000","0.00000000"],["86024.31000000","0.00030000"]]}}
{"stream":"dogeusdt@depth@100ms","data":{"e":"depthUpdate","E":1790299067074,"s":"DOGEUSDT","U":25516669496,"u":25516669497,"b":[["0.09673000","336834.00000000"],["0.09672000","87311.00000000"]],"a":[]}}
{"stream":"btcusdt@depth@100ms","data":{"e":"depthUpdate","E":1790299067114,"s":"BTCUSDT","U":100639384775,"u":100639384810,"b":[["84753.00000000","3.58221000"],["84749.06000000","0.00000000"],["84748.76000000","0.01101000"],["84747.72000000","0.00000000"],["84747.04000000","0.02000000"],["84747.02000000","0.00000000"],["84746.91000000","0.00000000"],["84746.03000000","0.00590000"],["84746.02000000","0.00000000"],["84746.01000000","0.00007000"],["84746.00000000","0.35099000"],["84745.99000000","0.68743000"],["84743.87000000","0.00000000"],["84725.16000000","0.00200000"],["84706.79000000","0.00000000"],["84633.42000000","0.03659000"],["84630.32000000","0.02589000"],["83481.71000000","0.00024000"],["76277.70000000","0.00353000"],["76277.00000000","0.00292000"],["67802.40000000","0.00261000"]],"a":[["84757.13000000","0.02000000"],["84758.20000000","0.00000000"],["84758.31000000","0.17896000"],["84760.13000000","0.17882000"],["84761.71000000","0.00200000"],["84765.84000000","0.00000000"],["84784.00000000","0.08770000"],["84887.71000000","0.06797000"]]}}
{"stream":"dogeusdt@depth@100ms","data":{"e":"depthUpdate","E":1790299067174,"s":"DOGEUSDT","U":25516669498,"u":25516669500,"b":[["0.09679000","33730.00000000"],["0.09660000","287618.00000000"],["0.09653000","100888.00000000"]],"a":[]}}
{"stream":"btcusdt@depth@100ms","data":{"e":"depthUpdate","E":1790299067214,"s":"BTCUSDT","U":100639384811,"u":100639384865,"b":[["84753.00000000","3.39583000"],["84750.28000000","0.02186000"],["84748.76000000","0.01101000"],["84746.61000000","0.03551000"],["84746.03000000","0.00596000"],["84746.01000000","0.00614000"],["84746.00000000","0.34899000"],["84744.53000000","0.02390000"],["84744.26000000","0.18151000"],["84743.86000000","0.11800000"],["84743.85000000","0.12957000"],["84731.29000000","0.00000000"],["84703.49000000","0.31884000"],["83481.71000000","0.00024000"],["76277.70000000","0.00368000"],["76277.00000000","0.00272000"],["67802.40000000","0.00232000"],["67802.00000000","0.00000000"]],"a":[["84754.72000000","0.00014000"],["84755.00000000","0.11892000"],["84757.12000000","0.00014000"],["84757.52000000","0.00000000"],["84757.62000000","0.01118000"],["84758.30000000","0.09554000"],["84758.31000000","0.00000000"],["84758.32000000","0.00000000"],["84758.48000000","0.00000000"],["84760.13000000","0.00000000"],["84771.24000000","0.16495000"],["84771.75000000","0.00377000"],["84773.98000000","0.00000000"],["84774.77000000","0.00000000"],["84781.22000000","0.58992000"],["84795.70000000","0.00000000"]]}}
{"stream":"btcusdt@depth@100ms","data":{"e":"depthUpdate","E":1790299067314,"s":"BTCUSDT","U":100639384866,"u":100639384883,"b":[["84753.00000000","3.39460000"],["84746.88000000","0.00006000"],["84746.66000000","0.00200000"],["84746.01000000","0.00014000"],["84746.00000000","0.34699000"],["84741.80000000","0.00600000"]],"a":[["84753.01000000","2.07916000"],["84753.02000000","0.00046000"],["84755.00000000","0.11898000"],["84755.27000000","0.01130000"],["84780.21000000","0.02439000"]]}}
{"stream":"btcusdt@depth@100ms","data":{"e":"depthUpdate","E":1790299067414,"s":"BTCUSDT","U":100639384884,"u":100639384898,"b":[["84753.00000000","3.73938000"],["84746.01000000","0.00200000"],["84746.00000000","0.00214000"],["84741.80000000","0.00400000"],["84617.63000000","0.01200000"],["83481.71000000","0.00024000"],["76277.70000000","0.00368000"],["67802.40000000","0.00203000"],["67802.00000000","0.00100000"]],"a":[["84758.29000000","0.00007000"],["84780.21000000","0.00472000"]]}}
{"stream":"btcusdt@depth@100ms","data":{"e":"depthUpdate","E":1790299067514,"s":"BTCUSDT","U":100639384899,"u":100639384910,"b":[["84753.00000000","3.83984000"],["83481.71000000","0.00016000"],["67802.40000000","0.00319000"],["67802.00000000","0.00000000"]],"a":[["84782.72000000","0.00200000"],["84790.00000000","0.70000000"]]}}
{"stream":"btcusdt@depth@100ms","data":{"e":"depthUpdate","E":1790299067614,"s":"BTCUSDT","U":100639384911,"u":100639384923,"b":[["84753.00000000","3.83943000"],["84746.00000000","0.00614000"],["84738.65000000","0.00006000"],["84706.79000000","0.08753000"],["83481.71000000","0.00024000"],["76277.70000000","0.00360000"],["76277.69000000","0.00008000"],["67802.40000000","0.00290000"]],"a":[["84772.56000000","0.00006000"],["84788.44000000","0.46669000"]]}}
{"stream":"btcusdt@depth@100ms","data":{"e":"depthUpdate","E":1790299067714,"s":"BTCUSDT","U":100639384924,"u":100639384943,"b":[["84726.31000000","0.00000000"],["84707.23000000","0.00024000"],["84546.68000000","0.00000000"],["84540.02000000","0.00734000"],["83481.71000000","0.00024000"],["76277.70000000","0.00345000"],["67802.40000000","0.00290000"]],"a":[["84753.01000000","2.07670000"],["84755.27000000","0.00000000"],["84758.30000000","0.13276000"],["84760.13000000","0.00000000"],["84761.70000000","0.17882000"],["84761.72000000","0.00000000"],["84762.52000000","0.02200000"],["84789.66000000","0.00000000"],["84813.19000000","0.16945000"],["84816.10000000","0.00000000"]]}}
{"stream":"dogeusdt@depth@100ms","data":{"e":"depthUpdate","E":1790299067774,"s":"DOGEUSDT","U":25516669501,"u":25516669515,"b":[["0.09679000","86392.00000000"],["0.09678000","88721.00000000"],["0.09677000","119182.00000000"],["0.09668000","225365.00000000"],["0.09667000","162361.00000000"],["0.09645000","5784.00000000"],["0.09639000","517073.00000000"]],"a":[["0.09680000","69023.00000000"],["0.09681000","22777.00000000"],["0.09683000","163701.00000000"],["0.09685000","137202.00000000"],["0.09688000","372970.00000000"],["0.09704000","227327.00000000"]]}}
{"stream":"btcusdt@depth@100ms","data":{"e":"depthUpdate","E":1790299067814,"s":"BTCUSDT","U":100639384944,"u":100639384962,"b":[["84753.00000000","3.84071000"],["84665.35000000","1.09581000"],["84648.61000000","0.00000000"],["83481.70000000","0.00626000"],["76277.70000000","0.00360000"],["67802.40000000","0.00261000"]],"a":[["84753.01000000","2.07663000"],["84753.02000000","0.00039000"],["84754.69000000","0.00000000"],["84754.93000000","0.00006000"],["84755.00000000","0.11892000"],["84755.49000000","0.01096000"],["84758.30000000","0.09554000"],["84761.31000000","0.00000000"],["84761.81000000","0.00000000"],["84762.52000000","0.02000000"]]}}
{"stream":"dogeusdt@depth@100ms","data":{"e":"depthUpdate","E":1790299067874,"s":"DOGEUSDT","U":25516669516,"u":25516669519,"b":[["0.09673000","337799.00000000"],["0.09672000","69252.00000000"]],"a":[["0.09687000","270179.00000000"]]}}
{"stream":"btcusdt@depth@100ms","data":{"e":"depthUpdate","E":1790299067914,"s":"BTCUSDT","U":100639384963,"u":100639385101,"b":[["84753.00000000","1.68557000"],["84752.99000000","0.00061000"],["84752.98000000","0.00026000"],["84752.54000000","0.01101000"],["84751.48000000","0.00000000"],["84751.24000000","0.00000000"],["84751.15000000","0.00000000"],["84750.90000000","0.00006000"],["84749.33000000","0.00000000"],["84749.32000000","0.00000000"],["84749.12000000","0.00000000"],["84747.00000000","0.00000000"],["84746.66000000","0.00000000"],["84746.62000000","0.00250000"],["84746.03000000","0.00000000"],["84746.01000000","0.00014000"],["84746.00000000","0.34499000"],["84745.97000000","1.93143000"],["84745.91000000","0.00000000"],["84744.90000000","0.00236000"],["84744.89000000","0.00000000"],["84744.53000000","0.02390000"],["84744.28000000","0.18211000"],["84744.27000000","0.00000000"],["84744.26000000","0.00000000"],["84744.02000000","0.00000000"],["84743.43000000","0.00236000"],["84743.19000000","0.00590000"],["84741.80000000","0.00590000"],["84741.41000000","0.00200000"],["84741.32000000","0.00000000"],["84740.65000000","0.00000000"],["84739.21000000","0.00000000"],["84738.61000000","0.00000000"],["84736.90000000","0.00000000"],["84736.74000000","0.00400000"],["84736.19000000","0.00200000"],["84735.42000000","0.35516000"],["84735.41000000","0.44080000"],["84735.40000000","0.88638000"],["84734.78000000","0.00025000"],["84728.09000000","0.00000000"],["84725.16000000","0.00000000"],["84720.76000000","0.00200000"],["84720.61000000","0.29504000"],["84719.45000000","0.00000000"],["84715.20000000","0.00400000"],["84713.08000000","0.00400000"],["84710.60000000","0.00006000"],["84706.72000000","0.00400000"],["84701.81000000","0.00171000"],["84665.35000000","0.00000000"],["84617.63000000","0.00000000"],["84602.13000000","0.01848000"],["84596.01000000","0.02166000"],["84592.78000000","0.00000000"],["83481.71000000","0.00024000"],["76277.70000000","0.00360000"],["76277.69000000","0.00000000"]],"a":[["84753.01000000","4.30709000"],["84753.02000000","0.00046000"],["84753.36000000","0.00400000"],["84754.93000000","0.00012000"],["84755.00000000","0.11898000"],["84755.48000000","0.00400000"],["84756.57000000","0.00000000"],["84756.81000000","0.00308000"],["84756.85000000","0.01540000"],["84757.12000000","0.00014000"],["84757.58000000","0.00590000"],["84757.60000000","0.00400000"],["84758.29000000","0.00007000"],["84758.30000000","0.04928000"],["84758.49000000","0.03545000"],["84758.54000000","0.00590000"],["84758.73000000","0.00590000"],["84760.13000000","0.00000000"],["84760.37000000","0.00236000"],["84761.48000000","0.01858000"],["84761.49000000","0.00207000"],["84761.69000000","0.00600000"],["84761.70000000","0.00000000"],["84762.39000000","0.00000000"],["84762.84000000","0.00000000"],["84762.85000000","0.00000000"],["84787.28000000","0.00000000"],["84789.40000000","0.00442000"],["84791.52000000","1.37410000"],["84897.02000000","0.00000000"]]}}
{"stream":"dogeusdt@depth@100ms","data":{"e":"depthUpdate","E":1790299067974,"s":"DOGEUSDT","U":25516669520,"u":25516669527,"b":[["0.09679000","33730.00000000"],["0.09678000","80051.00000000"],["0.09677000","77647.00000000"],["0.09546000","39820.00000000"]],"a":[["0.09680000","77023.00000000"],["0.09681000","30777.00000000"],["0.09685000","129202.00000000"]]}}
{"stream":"btcusdt@depth@100ms","data":{"e":"depthUpdate","E":1790299068014,"s":"BTCUSDT","U":100639385102,"u":100639385159,"b":[["84753.00000000","1.68509000"],["84752.99000000","0.00081000"],["84752.98000000","0.22009000"],["84752.97000000","0.68301000"],["84751.64000000","0.01823000"],["84746.62000000","0.00236000"],["84746.61000000","0.03545000"],["84745.99000000","0.68737000"],["84745.98000000","0.00013000"],["84743.85000000","0.12963000"],["84742.23000000","0.00048000"],["84735.41000000","0.41595000"],["84731.33000000","0.00000000"],["84722.14000000","0.22515000"],["84695.72000000","0.45817000"],["83481.71000000","0.00016000"],["67802.40000000","0.00232000"]],"a":[["84753.01000000","4.30710000"],["84753.02000000","0.00060000"],["84754.78000000","0.05018000"],["84755.49000000","0.01102000"],["84756.84000000","0.00014000"],["84757.13000000","0.02006000"],["84758.29000000","0.00000000"],["84758.54000000","0.00596000"],["84767.68000000","0.00000000"],["84787.62000000","0.22583000"],["84813.19000000","0.34151000"],["84814.06000000","0.46397000"],["86024.31000000","0.00030000"]]}}
{"stream":"dogeusdt@depth@100ms","data":{"e":"depthUpdate","E":1790299068074,"s":"DOGEUSDT","U":25516669528,"u":25516669530,"b":[["0.09673000","331387.00000000"],["0.09653000","248791.00000000"],["0.09527000","41411.00000000"]],"a":[]}}
{"stream":"btcusdt@depth@100ms","data":{"e":"depthUpdate","E":1790299068114,"s":"BTCUSDT","U":100639385160,"u":100639385176,"b":[["84750.90000000","0.00012000"],["84743.43000000","0.00000000"],["84738.27000000","0.00400000"],["84731.83000000","0.22386000"],["84643.05000000","1.25616000"],["84633.42000000","0.00000000"],["84597.70000000","0.00000000"],["83481.71000000","0.00024000"],["76277.70000000","0.00360000"],["67802.40000000","0.00232000"]],"a":[["84760.37000000","0.00000000"],["84780.21000000","0.02439000"],["84887.71000000","0.00000000"],["84919.77000000","0.00000000"]]}}
{"stream":"dogeusdt@depth@100ms","data":{"e":"depthUpdate","E":1790299068174,"s":"DOGEUSDT","U":25516669531,"u":25516669533,"b":[["0.09675000","128292.00000000"],["0.09578000","33981.00000000"],["0.09527000","38792.00000000"]],"a":[]}}
{"stream":"btcusdt@depth@100ms","data":{"e":"depthUpdate","E":1790299068214,"s":"BTCUSDT","U":100639385177,"u":100639385231,"b":[["84753.00000000","1.97880000"],["84752.99000000","0.00061000"],["84752.98000000","0.00032000"],["84750.90000000","0.00006000"],["84749.30000000","0.00000000"],["84746.87000000","0.00006000"],["84746.62000000","0.00250000"],["84744.25000000","0.00000000"],["84743.85000000","0.12957000"],["84743.22000000","0.00000000"],["84743.19000000","0.00000000"],["84742.85000000","0.00200000"],["84742.84000000","0.00012000"],["84741.41000000","0.00000000"],["84739.84000000","0.00000000"],["84738.81000000","0.00006000"],["84738.61000000","0.00200000"],["84738.27000000","0.00000000"],["84737.88000000","0.00200000"],["84737.68000000","0.00000000"],["84736.74000000","0.00200000"],["84735.43000000","0.35516000"],["84735.42000000","0.00000000"],["84734.78000000","0.00019000"],["84730.98000000","0.00166000"],["84621.29000000","0.13105000"],["84598.59000000","0.12427000"],["83481.71000000","0.00024000"],["67802.40000000","0.00203000"]],"a":[["84753.01000000","4.30881000"],["84753.06000000","0.00000000"],["84753.31000000","0.00014000"],["84753.32000000","0.01133000"],["84757.12000000","0.00000000"],["84761.87000000","0.00000000"],["84780.21000000","0.00472000"],["84875.54000000","0.03697000"]]}}
{"stream":"dogeusdt@depth@100ms","data":{"e":"depthUpdate","E":1790299068274,"s":"DOGEUSDT","U":25516669534,"u":25516669550,"b":[["0.09678000","80051.00000000"],["0.09677000","77647.00000000"],["0.09673000","336690.00000000"],["0.09672000","86828.00000000"],["0.09578000","31376.00000000"],["0.09546000","29364.00000000"],["0.09527000","30935.00000000"]],"a":[["0.09680000","77045.00000000"],["0.09681000","53467.00000000"],["0.09682000","140785.00000000"]]}}
{"stream":"btcusdt@depth@100ms","data":{"e":"depthUpdate","E":1790299068314,"s":"BTCUSDT","U":100639385232,"u":100639385239,"b":[["84753.00000000","1.97752000"],["84744.28000000","0.18217000"],["84743.87000000","0.00590000"],["84708.84000000","0.00400000"],["84706.72000000","0.00000000"],["84629.32000000","0.03659000"],["84621.29000000","0.00000000"],["76277.70000000","0.00345000"]],"a":[]}}
{"stream":"dogeusdt@depth@100ms","data":{"e":"depthUpdate","E":1790299068374,"s":"DOGEUSDT","U":25516669551,"u":25516669558,"b":[["0.09578000","28771.00000000"],["0.09546000","21522.00000000"],["0.09527000","23078.00000000"]],"a":[["0.09681000","197621.00000000"]]}}
{"stream":"btcusdt@depth@100ms","data":{"e":"depthUpdate","E":1790299068414,"s":"BTCUSDT","U":100639385240,"u":100639385284,"b":[["84753.00000000","1.97759000"],["84752.99000000","0.00075000"],["84752.98000000","0.21949000"],["84751.99000000","0.00007000"],["84751.64000000","0.01829000"],["84750.90000000","0.00012000"],["84750.89000000","0.01116000"],["84746.87000000","0.00012000"],["84746.62000000","0.00236000"],["84742.84000000","0.00018000"],["84738.81000000","0.00012000"],["84738.27000000","0.00200000"],["84734.78000000","0.00025000"],["84710.96000000","0.00400000"],["84708.84000000","0.00000000"],["84629.32000000","0.13105000"],["83481.71000000","0.00024000"],["76277.70000000","0.00338000"],["67802.40000000","0.00174000"]],"a":[["84753.01000000","4.25114000"],["84753.02000000","0.00067000"],["84753.31000000","0.00000000"],["84753.32000000","0.00000000"],["84757.12000000","0.00007000"],["84757.13000000","0.02000000"],["84757.58000000","0.00000000"],["84758.54000000","0.00590000"],["84758.73000000","0.00000000"],["84759.58000000","0.00590000"],["84760.01000000","0.00590000"],["84761.69000000","0.00400000"],["84761.83000000","0.00200000"]]}}
{"stream":"dogeusdt@depth@100ms","data":{"e":"depthUpdate","E":1790299068474,"s":"DOGEUSDT","U":25516669559,"u":25516669567,"b":[["0.09578000","20956.00000000"],["0.09546000","13680.00000000"],["0.09527000","15221.00000000"]],"a":[]}}
{"stream":"btcusdt@depth@100ms","data":{"e":"depthUpdate","E":1790299068514,"s":"BTCUSDT","U":100639385285,"u":100639385450,"b":[["84753.00000000","1.33296000"],["84752.99000000","0.00075000"],["84752.98000000","0.00032000"],["84752.97000000","0.68301000"],["84752.54000000","0.00000000"],["84752.35000000","0.00020000"],["84752.34000000","0.10462000"],["84751.64000000","0.01829000"],["84751.54000000","0.01104000"],["84751.03000000","0.00014000"],["84751.02000000","0.04170000"],["84750.90000000","0.00006000"],["84750.89000000","0.00000000"],["84750.28000000","0.02192000"],["84749.48000000","0.00014000"],["84749.47000000","0.04300000"],["84748.76000000","0.01095000"],["84747.55000000","0.00000000"],["84746.80000000","0.00024000"],["84746.62000000","0.00000000"],["84746.61000000","0.00006000"],["84746.00000000","0.34485000"],["84745.98000000","0.00006000"],["84744.91000000","0.00236000"],["84744.28000000","0.18211000"],["84744.25000000","0.00000000"],["84743.87000000","0.00000000"],["84743.85000000","0.12963000"],["84743.48000000","0.03539000"],["84742.85000000","0.00000000"],["84741.36000000","0.00590000"],["84741.31000000","0.07000000"],["84739.69000000","0.00000000"],["84739.54000000","0.00200000"],["84739.47000000","0.00000000"],["84739.46000000","0.00000000"],["84738.61000000","0.00000000"],["84738.27000000","0.00000000"],["84737.61000000","0.08000000"],["84736.74000000","0.00200000"],["84735.62000000","0.00200000"],["84706.57000000","0.00000000"],["84704.97000000","0.00353000"],["84629.32000000","0.00000000"],["83481.71000000","0.00016000"],["82386.87000000","0.00000000"],["76277.70000000","0.00353000"],["67802.40000000","0.00290000"],["67802.00000000","0.00000000"]],"a":[["84753.01000000","4.14400000"],["84753.02000000","0.00018000"],["84753.98000000","0.00016000"],["84754.72000000","0.00014000"],["84754.77000000","0.00014000"],["84754.93000000","0.00006000"],["84754.99000000","0.00014000"],["84755.49000000","0.01108000"],["84755.96000000","0.00596000"],["84756.38000000","0.00014000"],["84756.39000000","0.03539000"],["84756.84000000","0.00007000"],["84757.12000000","0.00000000"],["84758.15000000","0.00000000"],["84758.49000000","0.00006000"],["84758.54000000","0.00596000"],["84758.96000000","0.00006000"],["84760.01000000","0.00000000"],["84766.37000000","0.35516000"],["84766.38000000","0.00000000"],["84771.64000000","0.00000000"],["84772.04000000","0.00000000"],["84774.75000000","0.00000000"],["84777.38000000","0.00200000"],["84782.72000000","0.00000000"],["89076.24000000","0.00000000"]]}}
{"stream":"dogeusdt@depth@100ms","data":{"e":"depthUpdate","E":1790299068574,"s":"DOGEUSDT","U":25516669568,"u":25516669573,"b":[["0.09546000","5838.00000000"],["0.09527000","7364.00000000"]],"a":[]}}
{"stream":"btcusdt@depth@100ms","data":{"e":"depthUpdate","E":1790299068614,"s":"BTCUSDT","U":100639385451,"u":100639385613,"b":[["84753.00000000","1.33303000"],["84752.97000000","0.68295000"],["84752.35000000","0.00006000"],["84752.34000000","0.00000000"],["84750.72000000","0.00000000"],["84750.28000000","0.02186000"],["84749.48000000","0.00000000"],["84749.47000000","0.00000000"],["84748.57000000","0.00000000"],["84748.27000000","0.00000000"],["84747.08000000","0.00024000"],["84747.04000000","0.02006000"],["84746.99000000","0.00014000"],["84746.98000000","0.00000000"],["84746.87000000","0.00012000"],["84746.80000000","0.00000000"],["84746.00000000","0.34492000"],["84745.99000000","0.68743000"],["84745.66000000","0.01106000"],["84745.06000000","0.03200000"],["84744.90000000","0.00000000"],["84744.88000000","0.00000000"],["84744.28000000","0.07396000"],["84743.85000000","0.01118000"],["84743.48000000","0.00000000"],["84743.19000000","0.00236000"],["84742.24000000","0.00000000"],["84741.80000000","0.00000000"],["84741.31000000","0.00000000"],["84741.00000000","0.00000000"],["84738.82000000","0.00590000"],["84738.65000000","0.00006000"],["84738.41000000","0.02000000"],["84737.88000000","0.00200000"],["84737.81000000","0.01000000"],["84737.51000000","0.04000000"],["84736.74000000","0.00200000"],["84736.41000000","0.00200000"],["84736.19000000","0.00200000"],["84735.62000000","0.00000000"],["84729.00000000","0.10462000"],["84706.72000000","0.00400000"],["84706.57000000","0.00006000"],["84629.32000000","0.03659000"],["83481.71000000","0.00024000"],["76277.70000000","0.00353000"],["76277.00000000","0.00272000"],["67802.40000000","0.00261000"],["67802.00000000","0.00100000"]],"a":[["84753.01000000","4.26137000"],["84753.02000000","0.00012000"],["84754.29000000","0.03539000"],["84754.72000000","0.00000000"],["84754.77000000","0.00000000"],["84754.93000000","0.00012000"],["84754.99000000","0.00000000"],["84755.49000000","0.01108000"],["84755.96000000","0.00000000"],["84756.38000000","0.00000000"],["84756.39000000","0.00000000"],["84756.46000000","0.00590000"],["84756.84000000","0.00000000"],["84757.13000000","0.02006000"],["84757.58000000","0.00590000"],["84758.21000000","0.00000000"],["84758.30000000","0.04934000"],["84758.49000000","0.00000000"],["84758.54000000","0.00006000"],["84758.96000000","0.00012000"],["84759.50000000","0.10652000"],["84759.59000000","0.00000000"],["84763.09000000","0.00000000"],["84765.67000000","0.02994000"],["84766.36000000","0.35516000"],["84766.37000000","0.00000000"],["84772.56000000","0.00006000"],["84777.12000000","0.31857000"],["84800.91000000","0.00000000"],["84815.28000000","0.00000000"],["84875.54000000","0.00039000"]]}}
{"stream":"dogeusdt@depth@100ms","data":{"e":"depthUpdate","E":1790299068674,"s":"DOGEUSDT","U":25516669574,"u":25516669662,"b":[["0.09679000","0.00000000"],["0.09678000","21316.00000000"],["0.09677000","72565.00000000"],["0.09676000","123930.00000000"],["0.09675000","128292.00000000"],["0.09674000","318629.00000000"],["0.09672000","94880.00000000"],["0.09671000","275664.00000000"],["0.09667000","154500.00000000"],["0.09662000","241178.00000000"],["0.09660000","287629.00000000"],["0.09640000","30315.00000000"],["0.09638000","118523.00000000"],["0.09603000","1881.00000000"],["0.09546000","3224.00000000"],["0.09527000","4745.00000000"]],"a":[["0.09679000","111253.00000000"],["0.09680000","106024.00000000"],["0.09681000","197703.00000000"],["0.09682000","147681.00000000"],["0.09683000","156701.00000000"],["0.09684000","189500.00000000"],["0.09688000","380298.00000000"],["0.09689000","163945.00000000"],["0.09690000","266788.00000000"],["0.09691000","128564.00000000"],["0.09693000","676327.00000000"],["0.09698000","327828.00000000"],["0.09699000","393410.00000000"],["0.09701000","926.00000000"],["0.09728000","2299.00000000"],["0.09755000","1339.00000000"]]}}
{"stream":"btcusdt@depth@100ms","data":{"e":"depthUpdate","E":1790299068714,"s":"BTCUSDT","U":100639385614,"u":100639385854,"b":[["84753.00000000","2.44543000"],["84752.99000000","0.00075000"],["84752.98000000","0.23401000"],["84752.97000000","0.68301000"],["84752.35000000","0.00000000"],["84752.17000000","0.00014000"],["84752.16000000","0.10462000"],["84751.65000000","0.00000000"],["84751.55000000","0.00590000"],["84751.12000000","0.02994000"],["84751.03000000","0.00000000"],["84750.90000000","0.00012000"],["84747.72000000","0.00200000"],["84747.66000000","0.00000000"],["84747.04000000","0.00000000"],["84747.00000000","0.00400000"],["84746.99000000","0.00000000"],["84746.61000000","0.00000000"],["84746.02000000","1.64832000"],["84746.01000000","3.36611000"],["84746.00000000","0.00000000"],["84745.99000000","0.00006000"],["84745.98000000","0.00006000"],["84745.67000000","0.00000000"],["84745.06000000","0.03206000"],["84744.91000000","0.00000000"],["84744.88000000","0.00400000"],["84744.54000000","0.02994000"],["84744.28000000","0.10509000"],["84744.25000000","0.10462000"],["84743.19000000","0.00000000"],["84741.36000000","0.00000000"],["84740.95000000","0.00000000"],["84739.71000000","0.00166000"],["84739.54000000","0.00000000"],["84738.82000000","0.00000000"],["84738.27000000","0.00013000"],["84737.88000000","0.00000000"],["84736.74000000","0.00000000"],["84736.20000000","0.00000000"],["84736.19000000","0.00000000"],["84735.62000000","0.35516000"],["84735.43000000","0.00000000"],["84735.41000000","0.38960000"],["84734.78000000","0.00012000"],["84730.98000000","0.00000000"],["84729.00000000","0.00000000"],["84720.76000000","0.00000000"],["84717.32000000","0.00400000"],["84713.08000000","0.00000000"],["84711.81000000","0.00000000"],["84710.96000000","0.00000000"],["84710.60000000","0.00000000"],["84708.26000000","0.02294000"],["84706.72000000","0.00000000"],["84706.57000000","0.00000000"],["84643.05000000","0.67456000"],["84639.18000000","0.00000000"],["84639.17000000","0.00000000"],["84629.32000000","0.00000000"],["83481.71000000","0.00024000"],["76277.70000000","0.00345000"],["76277.69000000","0.00008000"],["67802.40000000","0.00261000"],["67802.00000000","0.00000000"]],"a":[["84753.01000000","0.63323000"],["84753.36000000","0.00000000"],["84753.98000000","0.00006000"],["84754.28000000","0.00014000"],["84754.72000000","0.00014000"],["84754.73000000","0.00000000"],["84754.77000000","0.00014000"],["84754.78000000","0.00000000"],["84754.93000000","0.00006000"],["84754.99000000","0.00014000"],["84755.00000000","0.11892000"],["84755.48000000","0.00000000"],["84755.49000000","0.00012000"],["84756.84000000","0.00007000"],["84757.13000000","0.00000000"],["84757.58000000","0.00000000"],["84757.62000000","0.00006000"],["84757.66000000","0.00000000"],["84758.30000000","0.06855000"],["84758.96000000","0.00006000"],["84759.50000000","0.00000000"],["84759.58000000","0.00000000"],["84760.13000000","0.16260000"],["84761.48000000","0.00000000"],["84761.49000000","0.00088000"],["84761.69000000","0.00000000"],["84761.71000000","0.00000000"],["84761.72000000","0.17882000"],["84761.83000000","0.00000000"],["84761.84000000","0.04537000"],["84761.85000000","0.00000000"],["84762.26000000","0.00152000"],["84762.99000000","0.00006000"],["84764.64000000","0.02000000"],["84765.46000000","0.00000000"],["84765.67000000","0.00000000"],["84766.01000000","0.00000000"],["84766.35000000","0.35516000"],["84766.36000000","0.00000000"],["84767.02000000","0.00006000"],["84768.43000000","0.00000000"],["84768.89000000","0.00590000"],["84768.91000000","0.03000000"],["84769.30000000","0.00000000"],["84769.89000000","0.00000000"],["84772.91000000","0.00400000"],["84773.16000000","0.00000000"],["84774.75000000","0.10652000"],["84777.12000000","0.00000000"],["84777.38000000","0.00000000"],["84777.77000000","0.00200000"],["84778.43000000","0.00000000"],["84778.99000000","0.00000000"],["84779.60000000","0.00000000"],["84781.22000000","0.00000000"],["84784.67000000","0.00000000"],["84786.58000000","0.00000000"],["84788.44000000","0.17117000"],["84788.90000000","0.00000000"],["84789.40000000","0.00842000"],["84790.00000000","0.00000000"],["84790.77000000","0.02325000"],["84793.64000000","0.00400000"],["84795.03000000","0.58982000"],["84797.69000000","0.00000000"],["84797.98000000","0.00000000"],["84799.26000000","0.00006000"],["84806.57000000","0.31846000"],["84832.22000000","1.16734000"],["84846.67000000","1.14323000"],["84846.68000000","0.00000000"],["84878.07000000","0.03658000"],["85180.70000000","0.00006000"]]}}
{"stream":"dogeusdt@depth@100ms","data":{"e":"depthUpdate","E":1790299068774,"s":"DOGEUSDT","U":25516669663,"u":25516669677,"b":[["0.09678000","21305.00000000"],["0.09677000","72565.00000000"],["0.09676000","87243.00000000"],["0.09673000","331387.00000000"],["0.09672000","86349.00000000"],["0.09671000","275675.00000000"],["0.09667000","154511.00000000"],["0.09578000","18351.00000000"]],"a":[["0.09679000","101761.00000000"],["0.09680000","106040.00000000"]]}}
{"stream":"btcusdt@depth@100ms","data":{"e":"depthUpdate","E":1790299068814,"s":"BTCUSDT","U":100639385855,"u":100639386130,"b":[["84753.00000000","2.75524000"],["84752.99000000","0.00226000"],["84752.98000000","0.23195000"],["84751.64000000","0.01829000"],["84751.55000000","0.00000000"],["84751.54000000","0.01110000"],["84751.24000000","0.00400000"],["84751.02000000","0.04176000"],["84750.29000000","0.00590000"],["84749.12000000","0.00400000"],["84748.76000000","0.01095000"],["84746.88000000","0.00000000"],["84746.03000000","0.35716000"],["84746.01000000","3.01095000"],["84745.66000000","0.01112000"],["84745.36000000","0.03539000"],["84742.56000000","0.00000000"],["84742.23000000","0.00000000"],["84732.98000000","0.00171000"],["84731.36000000","0.31874000"],["84721.14000000","0.59033000"],["84717.32000000","0.00000000"],["84715.20000000","0.00000000"],["84710.03000000","0.02600000"],["84703.49000000","0.00000000"],["84701.81000000","0.00000000"],["84666.80000000","0.00000000"],["84627.40000000","0.03659000"],["84540.02000000","0.00000000"],["84534.01000000","0.00734000"],["83481.70000000","0.00626000"],["76277.70000000","0.00345000"],["67802.40000000","0.00232000"],["67802.00000000","0.00300000"]],"a":[["84753.01000000","0.28315000"],["84753.02000000","0.00061000"],["84754.28000000","0.00000000"],["84754.29000000","0.00000000"],["84754.72000000","0.00000000"],["84754.77000000","0.00000000"],["84755.00000000","0.11886000"],["84755.49000000","0.00000000"],["84756.46000000","0.00000000"],["84756.81000000","0.00000000"],["84756.84000000","0.00000000"],["84756.85000000","0.00000000"],["84757.23000000","0.00014000"],["84757.24000000","0.03539000"],["84757.60000000","0.00000000"],["84758.29000000","0.17896000"],["84758.30000000","0.00012000"],["84758.54000000","0.00000000"],["84759.71000000","0.00014000"],["84759.78000000","0.01129000"],["84760.11000000","0.00014000"],["84760.12000000","0.17888000"],["84760.13000000","0.00000000"],["84761.71000000","0.00000000"],["84761.84000000","0.10251000"],["84761.95000000","0.00590000"],["84762.99000000","0.00012000"],["84763.48000000","0.00048000"],["84763.68000000","0.00000000"],["84763.69000000","0.17882000"],["84763.84000000","0.00006000"],["84764.15000000","0.00048000"],["84764.49000000","0.00188000"],["84764.64000000","0.00000000"],["84765.47000000","0.17882000"],["84765.52000000","0.00016000"],["84766.18000000","0.00000000"],["84766.33000000","0.17882000"],["84766.34000000","0.35516000"],["84766.35000000","0.00000000"],["84767.02000000","0.00012000"],["84767.14000000","0.00024000"],["84768.24000000","0.02000000"],["84768.88000000","0.00590000"],["84769.24000000","0.00010000"],["84769.89000000","0.00400000"],["84772.41000000","0.00000000"],["84772.59000000","0.00000000"],["84772.60000000","0.00000000"],["84772.63000000","0.00200000"],["84772.91000000","0.00000000"],["84774.64000000","0.00000000"],["84777.77000000","0.00000000"],["84778.63000000","0.00200000"],["84780.66000000","0.29503000"],["84781.32000000","0.11796000"],["84785.15000000","0.29503000"],["84786.59000000","0.00000000"],["84789.12000000","0.29503000"],["84790.77000000","0.00000000"],["84793.53000000","0.29503000"],["84797.88000000","0.00400000"],["84797.96000000","0.00000000"],["84802.04000000","0.38315000"],["84878.07000000","0.00000000"]]}}
{"stream":"dogeusdt@depth@100ms","data":{"e":"depthUpdate","E":1790299068874,"s":"DOGEUSDT","U":25516669678,"u":25516669699,"b":[["0.09678000","46664.00000000"],["0.09677000","96559.00000000"],["0.09676000","86211.00000000"],["0.09675000","155537.00000000"],["0.09674000","355314.00000000"]],"a":[["0.09679000","27583.00000000"],["0.09680000","98040.00000000"],["0.09681000","217417.00000000"],["0.09682000","125912.00000000"],["0.09684000","197500.00000000"]]}}
{"stream":"btcusdt@depth@100ms","data":{"e":"depthUpdate","E":1790299068914,"s":"BTCUSDT","U":100639386131,"u":100639386200,"b":[["84753.00000000","2.75716000"],["84746.88000000","0.00400000"],["84742.74000000","0.00000000"],["84740.28000000","0.25378000"],["84740.23000000","0.35412000"],["84728.53000000","0.00200000"],["84721.14000000","0.00000000"],["84627.40000000","0.00000000"],["83481.71000000","0.00024000"],["67802.00000000","0.00000000"]],"a":[["84753.01000000","0.28305000"],["84753.02000000","0.00061000"],["84757.24000000","0.03545000"],["84758.28000000","0.17754000"],["84758.29000000","0.17882000"],["84759.71000000","0.00000000"],["84759.72000000","0.01092000"],["84761.71000000","0.00007000"],["84761.84000000","0.14261000"],["84761.97000000","0.00190000"],["84766.34000000","0.00000000"],["84766.39000000","0.35516000"],["84769.89000000","0.00600000"],["84770.31000000","0.00200000"],["84772.63000000","0.00000000"],["84775.16000000","0.00200000"],["84778.63000000","0.00000000"],["84795.76000000","0.00400000"],["84885.34000000","0.06797000"],["84982.77000000","0.00000000"],["85039.18000000","0.02817000"]]}}
{"stream":"dogeusdt@depth@100ms","data":{"e":"depthUpdate","E":1790299068974,"s":"DOGEUSDT","U":25516669700,"u":25516669701,"b":[["0.09546000","610.00000000"],["0.09527000","2126.00000000"]],"a":[]}}
{"stream":"btcusdt@depth@100ms","data":{"e":"depthUpdate","E":1790299069014,"s":"BTCUSDT","U":100639386201,"u":100639386226,"b":[["84751.52000000","0.00200000"],["84633.20000000","0.03659000"],["83481.71000000","0.00016000"],["76277.70000000","0.00345000"],["67802.40000000","0.00319000"]],"a":[["84753.01000000","0.28312000"],["84753.02000000","0.00068000"],["84756.57000000","0.00000000"],["84757.24000000","0.03551000"],["84758.14000000","0.00024000"],["84758.27000000","0.00014000"],["84761.71000000","0.00000000"],["84761.84000000","0.10251000"],["84763.69000000","0.17881000"],["84766.33000000","0.00000000"],["84766.38000000","0.17881000"],["86024.31000000","0.00030000"]]}}
{"stream":"dogeusdt@depth@100ms","data":{"e":"depthUpdate","E":1790299069074,"s":"DOGEUSDT","U":25516669702,"u":25516669702,"b":[["0.09634000","244.00000000"],["0.09625000","125411.00000000"]],"a":[]}}
{"stream":"btcusdt@depth@100ms","data":{"e":"depthUpdate","E":1790299069114,"s":"BTCUSDT","U":100639386227,"u":100639386244,"b":[["84742.84000000","0.00012000"],["84731.83000000","0.29840000"],["84657.69000000","0.00000000"],["83481.71000000","0.00024000"],["76277.70000000","0.00330000"],["67802.40000000","0.00339000"]],"a":[["84754.99000000","0.00020000"],["84761.84000000","0.14317000"],["84763.69000000","0.00000000"],["84766.38000000","0.00000000"],["84779.60000000","1.06018000"],["84985.38000000","0.00017000"]]}}
{"stream":"dogeusdt@depth@100ms","data":{"e":"depthUpdate","E":1790299069174,"s":"DOGEUSDT","U":25516669703,"u":25516669707,"b":[["0.09677000","92559.00000000"],["0.09676000","90211.00000000"],["0.09674000","356260.00000000"],["0.09657000","40674.00000000"]],"a":[]}}
{"stream":"btcusdt@depth@100ms","data":{"e":"depthUpdate","E":1790299069214,"s":"BTCUSDT","U":100639386245,"u":100639386319,"b":[["84753.00000000","2.53382000"],["84752.99000000","0.00275000"],["84751.52000000","0.00000000"],["84751.02000000","0.04182000"],["84750.30000000","0.00590000"],["83481.71000000","0.00024000"],["76277.70000000","0.00345000"],["67802.40000000","0.00290000"]],"a":[["84753.01000000","0.57692000"],["84753.02000000","0.00061000"],["84755.00000000","0.11886000"],["84756.56000000","0.00000000"],["84756.57000000","0.00000000"],["84757.24000000","0.03545000"],["84758.27000000","0.16251000"],["84758.28000000","0.07181000"],["84758.29000000","0.00000000"],["84759.78000000","0.01123000"],["84760.11000000","0.00000000"],["84760.12000000","0.00006000"],["84760.13000000","0.17881000"],["84761.71000000","0.00014000"],["84761.83000000","0.00007000"],["84761.84000000","0.10251000"],["84763.69000000","0.17881000"],["84766.38000000","0.17881000"],["84769.89000000","0.00800000"]]}}
{"stream":"dogeusdt@depth@100ms","data":{"e":"depthUpdate","E":1790299069274,"s":"DOGEUSDT","U":25516669708,"u":25516669712,"b":[["0.09678000","21316.00000000"]],"a":[["0.09679000","68777.00000000"]]}}
{"stream":"btcusdt@depth@100ms","data":{"e":"depthUpdate","E":1790299069314,"s":"BTCUSDT","U":100639386320,"u":100639386349,"b":[["84738.42000000","0.00000000"],["84736.05000000","0.02984000"],["84696.05000000","0.00000000"],["84693.68000000","0.00377000"],["84662.15000000","0.00000000"],["84659.78000000","0.00377000"],["76277.70000000","0.00345000"]],"a":[["84753.01000000","0.57706000"],["84753.02000000","0.00075000"],["84757.24000000","0.03551000"],["84758.26000000","0.00020000"],["84758.28000000","0.11605000"],["84758.54000000","0.00590000"],["84759.78000000","0.01129000"],["84760.12000000","0.00013000"],["84761.71000000","0.00007000"],["84761.83000000","0.00000000"],["84761.84000000","0.14317000"],["84761.95000000","0.00000000"],["84766.38000000","0.00000000"],["84769.88000000","0.00400000"],["84776.82000000","0.08827000"],["84784.96000000","0.00200000"],["84821.42000000","0.73600000"]]}}
{"stream":"btcusdt@depth@100ms","data":{"e":"depthUpdate","E":1790299069414,"s":"BTCUSDT","U":100639386350,"u":100639386442,"b":[["84753.00000000","2.53902000"],["84752.99000000","0.00226000"],["84751.02000000","0.04176000"],["84750.30000000","0.00000000"],["84713.33000000","0.02351000"],["84708.26000000","0.00000000"],["84611.73000000","0.00000000"],["83481.71000000","0.00024000"],["76277.69000000","0.00000000"],["67802.40000000","0.00261000"]],"a":[["84753.01000000","0.09461000"],["84753.02000000","0.00068000"],["84756.57000000","0.00000000"],["84757.24000000","0.03551000"],["84758.14000000","0.00000000"],["84758.24000000","0.17895000"],["84758.25000000","0.00020000"],["84758.26000000","0.00006000"],["84758.27000000","0.00000000"],["84758.28000000","0.00000000"],["84758.54000000","0.00000000"],["84759.78000000","0.01123000"],["84760.12000000","0.00006000"],["84760.13000000","0.17881000"],["84761.84000000","0.10251000"],["84763.69000000","0.16374000"],["84766.38000000","0.53397000"],["84766.39000000","0.00000000"],["84769.88000000","0.00000000"],["84769.89000000","0.00600000"],["84815.28000000","0.01200000"]]}}
{"stream":"dogeusdt@depth@100ms","data":{"e":"depthUpdate","E":1790299069474,"s":"DOGEUSDT","U":25516669713,"u":25516669713,"b":[],"a":[["0.09679000","67285.00000000"]]}}
{"stream":"btcusdt@depth@100ms","data":{"e":"depthUpdate","E":1790299069514,"s":"BTCUSDT","U":100639386443,"u":100639386520,"b":[["84753.00000000","2.46694000"],["84751.61000000","0.00200000"],["84751.54000000","0.01116000"],["84751.25000000","0.00590000"],["84751.02000000","0.04170000"],["84750.29000000","0.00000000"],["84746.04000000","0.00014000"],["84746.03000000","0.35723000"],["84738.78000000","0.00095000"],["84546.68000000","0.00733000"],["84534.01000000","0.00000000"],["83481.71000000","0.00016000"],["76277.70000000","0.00345000"]],"a":[["84753.01000000","0.27961000"],["84753.02000000","0.00082000"],["84754.79000000","0.17881000"],["84755.00000000","0.11892000"],["84756.56000000","0.00014000"],["84756.57000000","0.17881000"],["84757.24000000","0.03551000"],["84758.21000000","0.00014000"],["84758.22000000","0.16371000"],["84758.23000000","0.12527000"],["84758.24000000","0.00000000"],["84758.25000000","0.00006000"],["84758.60000000","0.00024000"],["84758.96000000","0.00012000"],["84759.78000000","0.01129000"],["84760.12000000","0.00006000"],["84761.71000000","0.00000000"],["84761.97000000","0.00000000"],["84766.37000000","0.17881000"],["84766.38000000","0.35516000"],["84772.51000000","0.11796000"],["84774.75000000","0.10462000"]]}}
{"stream":"btcusdt@depth@100ms","data":{"e":"depthUpdate","E":1790299069614,"s":"BTCUSDT","U":100639386521,"u":100639386549,"b":[["84751.61000000","0.00000000"],["84746.04000000","0.00000000"],["84746.03000000","0.35716000"],["84743.85000000","0.01112000"],["84743.18000000","0.00006000"],["84738.65000000","0.00000000"],["83481.71000000","0.00024000"],["82386.87000000","0.00010000"],["67802.40000000","0.00232000"],["67802.00000000","0.00000000"]],"a":[["84753.01000000","0.27981000"],["84753.02000000","0.00089000"],["84754.78000000","0.00014000"],["84754.99000000","0.00014000"],["84758.22000000","0.16357000"],["84758.25000000","0.00000000"],["84758.26000000","0.00000000"],["84759.78000000","0.01135000"],["84759.91000000","0.00590000"],["84763.69000000","0.00000000"],["84766.37000000","0.17881000"],["84772.56000000","0.00000000"],["84794.00000000","0.70000000"]]}}
{"stream":"dogeusdt@depth@100ms","data":{"e":"depthUpdate","E":1790299069674,"s":"DOGEUSDT","U":25516669714,"u":25516669715,"b":[["0.09553000","2674.00000000"],["0.09534000","2759.00000000"]],"a":[]}}
{"stream":"btcusdt@depth@100ms","data":{"e":"depthUpdate","E":1790299069714,"s":"BTCUSDT","U":100639386550,"u":100639386574,"b":[["84738.65000000","0.00006000"],["83481.71000000","0.00024000"],["76277.70000000","0.00345000"],["67802.40000000","0.00232000"]],"a":[["84753.01000000","0.27974000"],["84753.02000000","0.00082000"],["84757.24000000","0.03551000"],["84758.20000000","0.00007000"],["84758.21000000","0.12257000"],["84758.23000000","0.00000000"],["84759.78000000","0.01129000"],["84760.13000000","0.00000000"],["84761.83000000","0.00010000"],["84761.84000000","0.14084000"],["84763.69000000","0.17881000"],["84772.56000000","0.00006000"]]}}
{"stream":"btcusdt@depth@100ms","data":{"e":"depthUpdate","E":1790299069814,"s":"BTCUSDT","U":100639386575,"u":100639386604,"b":[["83481.70000000","0.00626000"],["76277.70000000","0.00338000"],["76277.00000000","0.00292000"],["67802.40000000","0.00203000"]],"a":[["84753.01000000","0.27796000"],["84753.02000000","0.00075000"],["84754.99000000","0.00020000"],["84756.56000000","0.00020000"],["84757.24000000","0.03545000"],["84758.21000000","0.11764000"],["84758.22000000","0.00000000"],["84759.91000000","0.00596000"],["84760.13000000","0.17881000"],["84769.89000000","0.01000000"],["84770.83000000","0.04000000"],["84773.74000000","0.08000000"],["89076.24000000","0.00010000"],["94000.00000000","15.44921000"],["95000.00000000","53.15162000"],["96000.00000000","12.01209000"],["97000.00000000","17.11496000"],["98000.00000000","30.39908000"]]}}
{"stream":"dogeusdt@depth@100ms","data":{"e":"depthUpdate","E":1790299069874,"s":"DOGEUSDT","U":25516669716,"u":25516669719,"b":[],"a":[["0.09679000","76777.00000000"],["0.09680000","106040.00000000"],["0.09684000","189500.00000000"]]}}
{"stream":"btcusdt@depth@100ms","data":{"e":"depthUpdate","E":1790299069914,"s":"BTCUSDT","U":100639386605,"u":100639386614,"b":[["84750.87000000","0.00200000"],["84741.83000000","0.05918000"],["83481.71000000","0.00024000"],["76277.70000000","0.00353000"],["76277.00000000","0.00272000"]],"a":[["84766.37000000","0.00000000"],["84787.28000000","0.00400000"],["84797.88000000","0.00000000"],["93000.00000000","42.24874000"]]}}
{"stream":"dogeusdt@depth@100ms","data":{"e":"depthUpdate","E":1790299069974,"s":"DOGEUSDT","U":25516669720,"u":25516669734,"b":[["0.09678000","22966.00000000"],["0.09584000","2919.00000000"],["0.09552000","3170.00000000"],["0.09533000","6170.00000000"],["0.09325000","53982.00000000"]],"a":[["0.09679000","68777.00000000"],["0.09680000","124366.00000000"],["0.09681000","197703.00000000"],["0.09686000","148758.00000000"]]}}
{"stream":"btcusdt@depth@100ms","data":{"e":"depthUpdate","E":1790299070014,"s":"BTCUSDT","U":100639386615,"u":100639386648,"b":[["84751.76000000","0.01099000"],["83481.71000000","0.00016000"],["76277.70000000","0.00345000"],["76277.69000000","0.00008000"],["67802.40000000","0.00290000"]],"a":[["84753.01000000","0.27577000"],["84754.78000000","0.00000000"],["84754.79000000","0.00000000"],["84755.00000000","0.11886000"],["84756.56000000","0.00006000"],["84756.57000000","0.00000000"],["84758.20000000","0.17901000"],["84760.12000000","0.00020000"],["84761.71000000","0.00007000"],["84761.84000000","0.39035000"],["84765.45000000","0.17881000"],["84765.46000000","0.85230000"],["84765.47000000","0.00000000"]]}}
{"stream":"dogeusdt@depth@100ms","data":{"e":"depthUpdate","E":1790299070074,"s":"DOGEUSDT","U":25516669735,"u":25516669743,"b":[["0.09633000","223434.00000000"],["0.09625000","944.00000000"],["0.09584000","8125.00000000"],["0.09553000","5286.00000000"],["0.09552000","8394.00000000"],["0.09534000","5376.00000000"],["0.09533000","11404.00000000"]],"a":[]}}
{"stream":"btcusdt@depth@100ms","data":{"e":"depthUpdate","E":1790299070114,"s":"BTCUSDT","U":100639386649,"u":100639386732,"b":[["84752.16000000","0.10468000"],["84751.31000000","0.00236000"],["84743.18000000","0.00000000"],["84741.88000000","0.00007000"],["84733.05000000","0.00007000"],["84598.75000000","0.54674000"],["84598.74000000","1.41413000"],["84598.59000000","0.00000000"],["83481.71000000","0.00024000"],["82419.23000000","0.00363000"]],"a":[["84753.01000000","0.27575000"],["84753.02000000","0.00081000"],["84754.78000000","0.00020000"],["84754.79000000","0.17881000"],["84754.99000000","0.00026000"],["84755.00000000","0.11886000"],["84756.56000000","0.00020000"],["84756.57000000","0.17881000"],["84757.23000000","0.00000000"],["84757.24000000","0.00006000"],["84758.18000000","0.00014000"],["84758.19000000","0.12591000"],["84758.20000000","0.00000000"],["84758.21000000","0.00000000"],["84759.66000000","0.00000000"],["84759.72000000","0.00000000"],["84759.78000000","0.00006000"],["84760.12000000","0.00013000"],["84761.71000000","0.00000000"],["84763.69000000","0.00000000"],["84765.20000000","0.00047000"],["84768.25000000","0.00236000"],["84771.75000000","0.00000000"],["84775.55000000","0.00377000"],["84784.00000000","0.00000000"],["84787.61000000","0.29607000"],["84788.44000000","0.00000000"],["84814.14000000","0.00000000"],["84817.94000000","0.00377000"],["84848.05000000","0.00000000"],["84851.85000000","0.35893000"],["84920.82000000","1.41413000"],["85004.25000000","0.00007000"],["85021.20000000","0.00007000"],["86024.31000000","0.00030000"]]}}
{"stream":"dogeusdt@depth@100ms","data":{"e":"depthUpdate","E":1790299070174,"s":"DOGEUSDT","U":25516669744,"u":25516669846,"b":[["0.09678000","0.00000000"],["0.09677000","41590.00000000"],["0.09676000","102427.00000000"],["0.09675000","172176.00000000"],["0.09673000","331398.00000000"],["0.09664000","44276.00000000"],["0.09659000","698452.00000000"],["0.09638000","208930.00000000"],["0.09602000","651.00000000"],["0.09585000","2725.00000000"],["0.09553000","7898.00000000"],["0.09552000","13618.00000000"],["0.09534000","7993.00000000"],["0.09533000","16638.00000000"]],"a":[["0.09678000","69522.00000000"],["0.09679000","79466.00000000"],["0.09680000","136502.00000000"],["0.09681000","185599.00000000"],["0.09682000","128820.00000000"],["0.09683000","156742.00000000"],["0.09684000","189448.00000000"],["0.09685000","349128.00000000"],["0.09686000","923072.00000000"],["0.09688000","377268.00000000"],["0.09697000","216598.00000000"],["0.09699000","373725.00000000"],["0.09700000","1442605.00000000"],["0.09712000","186899.00000000"]]}}
{"stream":"btcusdt@depth@100ms","data":{"e":"depthUpdate","E":1790299070214,"s":"BTCUSDT","U":100639386733,"u":100639386947,"b":[["84753.00000000","2.45574000"],["84752.99000000","0.00075000"],["84751.54000000","0.01104000"],["84751.32000000","0.00000000"],["84751.31000000","0.00000000"],["84751.25000000","0.00000000"],["84751.12000000","0.00000000"],["84750.87000000","0.00000000"],["84750.29000000","0.00000000"],["84750.28000000","0.02186000"],["84749.75000000","0.00236000"],["84749.14000000","0.00236000"],["84749.13000000","0.00000000"],["84748.76000000","0.01101000"],["84748.67000000","0.00000000"],["84748.29000000","0.00000000"],["84747.73000000","0.00000000"],["84747.72000000","0.00000000"],["84746.88000000","0.00000000"],["84746.53000000","0.00596000"],["84746.52000000","0.00200000"],["84746.04000000","0.01214000"],["84746.03000000","0.35735000"],["84746.02000000","0.83687000"],["84746.01000000","0.88514000"],["84745.36000000","0.03545000"],["84745.07000000","0.00590000"],["84736.41000000","0.00000000"],["84728.53000000","0.00000000"],["84725.73000000","0.00200000"],["84643.05000000","1.25616000"],["84639.17000000","2.12381000"],["84546.68000000","0.00000000"],["84546.20000000","0.00733000"],["83481.71000000","0.00024000"],["76277.70000000","0.00345000"],["67802.40000000","0.00261000"],["67802.00000000","0.00000000"]],"a":[["84753.01000000","1.56913000"],["84753.02000000","0.00088000"],["84754.77000000","0.00014000"],["84754.78000000","0.04139000"],["84754.79000000","0.00000000"],["84754.99000000","0.00014000"],["84755.00000000","0.11886000"],["84756.56000000","0.00000000"],["84756.57000000","0.00000000"],["84756.81000000","0.00308000"],["84756.84000000","0.00014000"],["84756.85000000","0.01552000"],["84757.71000000","0.00596000"],["84757.97000000","0.00014000"],["84757.98000000","0.10462000"],["84758.17000000","0.00000000"],["84758.18000000","0.00014000"],["84758.19000000","0.74049000"],["84759.78000000","0.00000000"],["84759.91000000","0.00000000"],["84760.12000000","0.00006000"],["84760.13000000","0.00006000"],["84760.51000000","0.01122000"],["84761.05000000","0.03539000"],["84761.70000000","0.00000000"],["84761.71000000","2.12381000"],["84761.72000000","0.00000000"],["84762.12000000","0.00590000"],["84765.44000000","0.06456000"],["84765.45000000","0.00000000"],["84766.69000000","0.00236000"],["84768.25000000","0.00000000"],["84768.88000000","0.00000000"],["84769.89000000","0.00200000"],["84775.17000000","0.00000000"],["84779.56000000","0.11796000"],["84781.32000000","0.00000000"],["84791.52000000","1.37810000"],["84795.76000000","0.00000000"],["84798.10000000","0.02435000"],["92000.00000000","26.68497000"]]}}
{"stream":"dogeusdt@depth@100ms","data":{"e":"depthUpdate","E":1790299070274,"s":"DOGEUSDT","U":25516669847,"u":25516669888,"b":[["0.09677000","64497.00000000"],["0.09676000","97392.00000000"],["0.09675000","146998.00000000"],["0.09673000","331398.00000000"],["0.09672000","77304.00000000"],["0.09667000","161855.00000000"],["0.09666000","708364.00000000"],["0.09665000","101890.00000000"],["0.09664000","51622.00000000"],["0.09657000","65154.00000000"],["0.09647000","80844.00000000"],["0.09614000","41208.00000000"],["0.09608000","6561.00000000"],["0.09584000","13331.00000000"],["0.09552000","26678.00000000"],["0.09533000","27106.00000000"]],"a":[["0.09678000","69548.00000000"],["0.09679000","79482.00000000"],["0.09683000","156716.00000000"],["0.09685000","355348.00000000"],["0.09686000","914090.00000000"],["0.09697000","152212.00000000"],["0.09698000","265428.00000000"],["0.09699000","255859.00000000"],["0.09754000","1422.00000000"]]}}
{"stream":"btcusdt@depth@100ms","data":{"e":"depthUpdate","E":1790299070315,"s":"BTCUSDT","U":100639386948,"u":100639386993,"b":[["84753.00000000","2.45581000"],["84750.64000000","0.00236000"],["84749.75000000","0.00000000"],["84747.64000000","0.00200000"],["84732.98000000","0.00000000"],["84714.95000000","0.00171000"]],"a":[["84753.01000000","1.62806000"],["84753.02000000","0.00046000"],["84754.99000000","0.00020000"],["84755.00000000","0.11880000"],["84756.81000000","0.00000000"],["84756.84000000","0.00000000"],["84756.85000000","0.00006000"],["84757.71000000","0.00006000"],["84761.70000000","0.00007000"],["84765.44000000","0.05856000"],["84766.69000000","0.00000000"],["84767.58000000","0.00236000"],["84768.19000000","0.00400000"]]}}
{"stream":"dogeusdt@depth@100ms","data":{"e":"depthUpdate","E":1790299070374,"s":"DOGEUSDT","U":25516669889,"u":25516669906,"b":[["0.09677000","36605.00000000"],["0.09676000","104392.00000000"],["0.09675000","152443.00000000"],["0.09674000","356260.00000000"],["0.09673000","358626.00000000"],["0.09671000","275727.00000000"],["0.09533000","29723.00000000"]],"a":[["0.09678000","90114.00000000"],["0.09685000","362048.00000000"]]}}
{"stream":"btcusdt@depth@100ms","data":{"e":"depthUpdate","E":1790299070414,"s":"BTCUSDT","U":100639386994,"u":100639387007,"b":[["84742.52000000","0.00192000"],["83481.71000000","0.00024000"],["76277.70000000","0.00345000"],["67802.40000000","0.00232000"]],"a":[["84761.70000000","0.00607000"],["84768.19000000","0.00000000"],["84769.89000000","0.00000000"],["84780.11000000","0.01967000"],["91000.00000000","15.64091000"]]}}
{"stream":"dogeusdt@depth@100ms","data":{"e":"depthUpdate","E":1790299070474,"s":"DOGEUSDT","U":25516669907,"u":25516669908,"b":[["0.09552000","29290.00000000"],["0.09533000","32340.00000000"]],"a":[]}}
{"stream":"btcusdt@depth@100ms","data":{"e":"depthUpdate","E":1790299070514,"s":"BTCUSDT","U":100639387008,"u":100639387025,"b":[["84753.00000000","2.45581000"],["84742.52000000","0.00000000"],["83481.71000000","0.00016000"],["76277.70000000","0.00330000"]],"a":[["84761.70000000","0.00007000"],["84765.43000000","0.00600000"],["84771.36000000","0.00377000"],["84775.55000000","0.00000000"],["84780.11000000","0.00000000"],["84813.75000000","0.00377000"],["84817.94000000","0.00000000"],["84847.66000000","0.00377000"],["84851.85000000","0.35516000"]]}}
{"stream":"dogeusdt@depth@100ms","data":{"e":"depthUpdate","E":1790299070574,"s":"DOGEUSDT","U":25516669909,"u":25516669955,"b":[["0.09677000","86544.00000000"],["0.09676000","123589.00000000"],["0.09673000","358678.00000000"],["0.09672000","69304.00000000"],["0.09671000","275675.00000000"],["0.09661000","140417.00000000"],["0.09660000","200106.00000000"],["0.09657000","83788.00000000"],["0.09654000","275578.00000000"],["0.09635000","51384.00000000"]],"a":[["0.09678000","1309.00000000"],["0.09679000","78424.00000000"],["0.09680000","118176.00000000"],["0.09682000","116537.00000000"],["0.09683000","135662.00000000"],["0.09684000","158839.00000000"],["0.09685000","142122.00000000"],["0.09686000","139776.00000000"]]}}
{"stream":"btcusdt@depth@100ms","data":{"e":"depthUpdate","E":1790299070614,"s":"BTCUSDT","U":100639387026,"u":100639387044,"b":[["84753.00000000","2.45769000"],["84704.97000000","0.00000000"],["84704.87000000","0.00353000"],["84659.97000000","0.00000000"],["84546.20000000","0.00000000"],["84540.02000000","0.00734000"],["83481.71000000","0.00024000"],["76277.70000000","0.00345000"],["67802.40000000","0.00203000"]],"a":[["84753.01000000","1.62806000"],["84753.02000000","0.00046000"],["84761.70000000","0.01007000"],["84765.43000000","0.00200000"]]}}
{"stream":"dogeusdt@depth@100ms","data":{"e":"depthUpdate","E":1790299070674,"s":"DOGEUSDT","U":25516669956,"u":25516669964,"b":[["0.09677000","86566.00000000"],["0.09675000","146998.00000000"],["0.09552000","31902.00000000"],["0.09533000","34957.00000000"]],"a":[["0.09681000","175830.00000000"],["0.09699000","531809.00000000"]]}}
{"stream":"btcusdt@depth@100ms","data":{"e":"depthUpdate","E":1790299070714,"s":"BTCUSDT","U":100639387045,"u":100639387057,"b":[["84738.65000000","0.00006000"],["83481.71000000","0.00024000"],["76277.70000000","0.00345000"],["76277.69000000","0.00000000"],["67802.40000000","0.00203000"]],"a":[["84753.01000000","1.62681000"],["84772.56000000","0.00006000"],["84780.11000000","0.01967000"],["90000.00000000","190.98331000"]]}}
{"stream":"dogeusdt@depth@100ms","data":{"e":"depthUpdate","E":1790299070774,"s":"DOGEUSDT","U":25516669965,"u":25516669977,"b":[["0.09677000","108196.00000000"],["0.09676000","110836.00000000"],["0.09673000","347787.00000000"],["0.09672000","69252.00000000"]],"a":[["0.09678000","19041.00000000"],["0.09680000","118198.00000000"],["0.09682000","136709.00000000"],["0.09683000","135688.00000000"],["0.09697000","218306.00000000"]]}}
{"stream":"btcusdt@depth@100ms","data":{"e":"depthUpdate","E":1790299070814,"s":"BTCUSDT","U":100639387058,"u":100639387065,"b":[["84668.14000000","1.09581000"],["83481.70000000","0.00626000"],["77972.77000000","0.00008000"],["67802.40000000","0.00174000"]],"a":[["84762.94000000","0.00200000"],["84780.11000000","0.00000000"],["85900.00000000","2.52780000"]]}}
{"stream":"btcusdt@depth@100ms","data":{"e":"depthUpdate","E":1790299070914,"s":"BTCUSDT","U":100639387066,"u":100639387078,"b":[["84753.00000000","2.45687000"],["84725.73000000","0.00000000"],["84724.47000000","0.00200000"],["83481.71000000","0.00024000"],["76277.70000000","0.00345000"]],"a":[["84758.19000000","0.74055000"],["84760.36000000","0.00590000"],["84784.96000000","0.00000000"],["84793.00000000","0.70000000"],["84794.00000000","0.00000000"],["89000.00000000","36.51334000"]]}}
{"stream":"dogeusdt@depth@100ms","data":{"e":"depthUpdate","E":1790299070974,"s":"DOGEUSDT","U":25516669978,"u":25516669988,"b":[["0.09677000","108185.00000000"],["0.09672000","74442.00000000"]],"a":[["0.09679000","22101.00000000"],["0.09680000","110198.00000000"],["0.09681000","186397.00000000"],["0.09682000","131709.00000000"],["0.09683000","140688.00000000"],["0.09684000","166839.00000000"]]}}
{"stream":"btcusdt@depth@100ms","data":{"e":"depthUpdate","E":1790299071014,"s":"BTCUSDT","U":100639387079,"u":100639387089,"b":[["84695.54000000","0.23603000"],["84668.95000000","0.00000000"],["83481.71000000","0.00016000"],["76277.00000000","0.00272000"],["67802.40000000","0.00261000"]],"a":[["84761.05000000","0.00000000"]]}}
{"stream":"dogeusdt@depth@100ms","data":{"e":"depthUpdate","E":1790299071074,"s":"DOGEUSDT","U":25516669989,"u":25516669990,"b":[["0.09674000","355314.00000000"]],"a":[["0.09682000","143534.00000000"]]}}
{"stream":"btcusdt@depth@100ms","data":{"e":"depthUpdate","E":1790299071114,"s":"BTCUSDT","U":100639387090,"u":100639387113,"b":[["84753.00000000","2.45499000"],["84752.75000000","0.00328000"],["84742.87000000","0.00191000"],["84732.31000000","0.00000000"],["84685.81000000","1.16935000"],["84502.07000000","0.01848000"],["84490.43000000","0.00000000"],["83481.71000000","0.00024000"],["76277.70000000","0.00345000"]],"a":[["84753.01000000","1.62688000"],["84753.02000000","0.00053000"],["84754.99000000","0.00014000"],["84758.19000000","0.74061000"],["84758.51000000","0.03539000"],["84797.88000000","0.53092000"],["84800.65000000","1.16777000"],["84965.46000000","0.00000000"],["86024.31000000","0.00030000"]]}}
{"stream":"dogeusdt@depth@100ms","data":{"e":"depthUpdate","E":1790299071174,"s":"DOGEUSDT","U":25516669991,"u":25516669997,"b":[["0.09677000","100185.00000000"]],"a":[["0.09679000","40231.00000000"],["0.09681000","206427.00000000"],["0.09682000","128362.00000000"],["0.09683000","135688.00000000"]]}}
{"stream":"btcusdt@depth@100ms","data":{"e":"depthUpdate","E":1790299071214,"s":"BTCUSDT","U":100639387114,"u":100639387152,"b":[["84753.00000000","1.77644000"],["84752.99000000","0.00082000"],["84752.75000000","0.00000000"],["84751.25000000","0.00236000"],["84747.64000000","0.00000000"],["84746.87000000","0.00012000"],["84746.05000000","0.00014000"],["84746.04000000","0.35699000"],["84746.03000000","0.35528000"],["84740.29000000","0.00200000"],["84738.27000000","0.00000000"],["84736.19000000","0.00013000"],["84724.47000000","0.00000000"],["84686.00000000","0.60602000"],["83481.71000000","0.00024000"],["77972.76000000","0.00013000"],["67802.40000000","0.00232000"]],"a":[["84753.01000000","1.99652000"],["84757.97000000","0.00014000"],["84761.48000000","0.01858000"],["84761.49000000","0.00007000"],["84761.50000000","0.01117000"],["84761.70000000","0.01000000"],["84762.94000000","0.00000000"],["88000.00000000","89.47064000"]]}}
{"stream":"btcusdt@depth@100ms","data":{"e":"depthUpdate","E":1790299071314,"s":"BTCUSDT","U":100639387153,"u":100639387182,"b":[["84753.00000000","1.77630000"],["84752.99000000","0.00082000"],["84750.64000000","0.00000000"],["84748.91000000","0.00236000"],["84740.29000000","0.00000000"],["76277.70000000","0.00345000"]],"a":[["84753.01000000","1.99659000"],["84753.02000000","0.00060000"],["84756.92000000","0.00190000"],["84761.70000000","0.00000000"],["84765.43000000","0.01000000"],["84765.85000000","0.00236000"],["84767.58000000","0.00000000"],["84769.30000000","0.00190000"],["84799.26000000","0.00000000"],["85180.70000000","0.00000000"]]}}
{"stream":"btcusdt@depth@100ms","data":{"e":"depthUpdate","E":1790299071414,"s":"BTCUSDT","U":100639387183,"u":100639387190,"b":[["84722.74000000","0.00200000"],["84616.03000000","0.01200000"],["84542.01000000","0.00734000"],["84540.02000000","0.00000000"],["83481.71000000","0.00024000"],["76277.70000000","0.00330000"],["67802.40000000","0.00203000"]],"a":[["87000.00000000","58.71269000"]]}}
{"stream":"dogeusdt@depth@100ms","data":{"e":"depthUpdate","E":1790299071474,"s":"DOGEUSDT","U":25516669998,"u":25516670046,"b":[["0.09677000","70413.00000000"],["0.09676000","110565.00000000"],["0.09675000","150998.00000000"],["0.09673000","328532.00000000"],["0.09672000","77304.00000000"],["0.09671000","275675.00000000"],["0.09669000","232464.00000000"],["0.09668000","121975.00000000"],["0.09667000","164857.00000000"],["0.09658000","374971.00000000"],["0.09654000","195654.00000000"]],"a":[["0.09678000","69560.00000000"],["0.09679000","52231.00000000"],["0.09680000","116407.00000000"],["0.09681000","186397.00000000"],["0.09683000","135662.00000000"],["0.09684000","193370.00000000"],["0.09693000","573453.00000000"],["0.09698000","326051.00000000"],["0.09699000","414656.00000000"]]}}
{"stream":"btcusdt@depth@100ms","data":{"e":"depthUpdate","E":1790299071514,"s":"BTCUSDT","U":100639387191,"u":100639387197,"b":[["84616.03000000","0.00000000"],["83481.71000000","0.00016000"],["67802.40000000","0.00319000"]],"a":[["84754.99000000","0.00020000"]]}}
{"stream":"dogeusdt@depth@100ms","data":{"e":"depthUpdate","E":1790299071574,"s":"DOGEUSDT","U":25516670047,"u":25516670053,"b":[["0.09677000","70402.00000000"],["0.09676000","110543.00000000"]],"a":[["0.09678000","48473.00000000"],["0.09679000","44231.00000000"],["0.09680000","124407.00000000"]]}}
{"stream":"btcusdt@depth@100ms","data":{"e":"depthUpdate","E":1790299071614,"s":"BTCUSDT","U":100639387198,"u":100639387204,"b":[["84746.33000000","0.00200000"],["84746.05000000","0.00214000"],["83481.71000000","0.00024000"],["76277.70000000","0.00330000"],["67802.40000000","0.00290000"]],"a":[["84754.99000000","0.00014000"]]}}
{"stream":"dogeusdt@depth@100ms","data":{"e":"depthUpdate","E":1790299071674,"s":"DOGEUSDT","U":25516670054,"u":25516670060,"b":[["0.09677000","64685.00000000"],["0.09676000","93392.00000000"]],"a":[["0.09679000","62833.00000000"],["0.09680000","124407.00000000"]]}}
{"stream":"btcusdt@depth@100ms","data":{"e":"depthUpdate","E":1790299071714,"s":"BTCUSDT","U":100639387205,"u":100639387221,"b":[["84753.00000000","1.77683000"],["84746.33000000","0.00000000"],["84741.83000000","0.00000000"],["84738.65000000","0.00006000"],["83481.71000000","0.00024000"],["77972.76000000","0.00000000"],["67802.40000000","0.00290000"]],"a":[["84753.01000000","1.99672000"],["84753.02000000","0.00060000"],["84772.56000000","0.00006000"],["86000.00000000","15.23216000"]]}}
{"stream":"dogeusdt@depth@100ms","data":{"e":"depthUpdate","E":1790299071774,"s":"DOGEUSDT","U":25516670061,"u":25516670090,"b":[["0.09677000","65935.00000000"],["0.09676000","113376.00000000"],["0.09666000","741600.00000000"],["0.09665000","205052.00000000"],["0.09633000","99070.00000000"],["0.09625000","125411.00000000"]],"a":[["0.09678000","46316.00000000"],["0.09679000","70833.00000000"],["0.09680000","98176.00000000"],["0.09689000","191960.00000000"],["0.09690000","369694.00000000"]]}}
{"stream":"btcusdt@depth@100ms","data":{"e":"depthUpdate","E":1790299071814,"s":"BTCUSDT","U":100639387222,"u":100639387232,"b":[["83481.70000000","0.00626000"],["76277.70000000","0.00330000"],["67802.40000000","0.00261000"],["67802.00000000","0.00000000"]],"a":[["84780.11000000","0.01967000"],["84780.38000000","0.00200000"]]}}
{"stream":"dogeusdt@depth@100ms","data":{"e":"depthUpdate","E":1790299071874,"s":"DOGEUSDT","U":25516670091,"u":25516670095,"b":[["0.09676000","116820.00000000"],["0.09675000","168218.00000000"]],"a":[["0.09679000","62833.00000000"],["0.09680000","106176.00000000"]]}}
{"stream":"btcusdt@depth@100ms","data":{"e":"depthUpdate","E":1790299071914,"s":"BTCUSDT","U":100639387233,"u":100639387265,"b":[["84753.00000000","1.96185000"],["84752.97000000","0.68295000"],["84752.17000000","0.00000000"],["84752.16000000","0.00006000"],["84751.24000000","0.00000000"],["84751.03000000","0.00014000"],["84748.91000000","0.00000000"],["84747.76000000","0.00236000"],["84710.96000000","0.00400000"],["84000.00000000","18.03027000"],["83481.71000000","0.00024000"]],"a":[["84753.01000000","1.99672000"],["84759.72000000","0.00400000"],["84761.48000000","0.01858000"],["84761.49000000","0.00007000"],["84764.70000000","0.00236000"],["84765.85000000","0.00000000"],["84780.11000000","0.00000000"],["84792.00000000","0.70000000"],["84793.00000000","0.00000000"],["84793.64000000","0.00000000"],["84809.14000000","0.35176000"],["84811.32000000","0.00006000"],["84962.00000000","3.53199000"]]}}
{"stream":"dogeusdt@depth@100ms","data":{"e":"depthUpdate","E":1790299071974,"s":"DOGEUSDT","U":25516670096,"u":25516670096,"b":[["0.09675000","149616.00000000"]],"a":[]}}
{"stream":"btcusdt@depth@100ms","data":{"e":"depthUpdate","E":1790299072014,"s":"BTCUSDT","U":100639387266,"u":100639387283,"b":[["84753.00000000","1.96178000"],["84752.99000000","0.00075000"],["84746.72000000","0.00200000"],["84738.99000000","0.06331000"],["83481.71000000","0.00016000"],["76277.70000000","0.00330000"],["67802.40000000","0.00232000"]],"a":[["84753.01000000","1.99679000"],["84753.02000000","0.00067000"],["84757.60000000","0.00400000"],["84765.42000000","0.00200000"],["84784.02000000","0.44185000"],["84791.52000000","1.37410000"]]}}
{"stream":"btcusdt@depth@100ms","data":{"e":"depthUpdate","E":1790299072114,"s":"BTCUSDT","U":100639387284,"u":100639387296,"b":[["84752.75000000","0.00328000"],["84751.99000000","0.00000000"],["84713.08000000","0.00400000"],["84710.96000000","0.00000000"],["83481.71000000","0.00024000"],["76277.70000000","0.00315000"],["76277.00000000","0.00272000"],["67802.00000000","0.00000000"]],"a":[["86024.31000000","0.00030000"],["87728.55000000","0.00094000"]]}}
{"stream":"dogeusdt@depth@100ms","data":{"e":"depthUpdate","E":1790299072174,"s":"DOGEUSDT","U":25516670097,"u":25516670102,"b":[["0.09677000","64685.00000000"],["0.09673000","329455.00000000"]],"a":[["0.09678000","63852.00000000"],["0.09679000","70833.00000000"],["0.09680000","118357.00000000"]]}}
{"stream":"btcusdt@depth@100ms","data":{"e":"depthUpdate","E":1790299072214,"s":"BTCUSDT","U":100639387297,"u":100639387553,"b":[["84753.00000000","1.02055000"],["84752.99000000","0.00068000"],["84752.98000000","0.00026000"],["84752.16000000","0.00000000"],["84751.76000000","0.00000000"],["84751.48000000","0.00000000"],["84751.25000000","0.00000000"],["84750.90000000","0.00006000"],["84749.23000000","0.00000000"],["84749.14000000","0.00000000"],["84749.12000000","0.00000000"],["84748.76000000","0.01095000"],["84747.76000000","0.00000000"],["84747.08000000","0.00000000"],["84746.87000000","0.00006000"],["84746.83000000","0.00000000"],["84746.72000000","0.00000000"],["84746.53000000","0.00006000"],["84746.52000000","0.00000000"],["84746.05000000","0.00014000"],["84746.04000000","0.34485000"],["84746.03000000","0.00020000"],["84746.02000000","0.61318000"],["84746.01000000","0.00000000"],["84745.98000000","0.00013000"],["84745.37000000","0.00236000"],["84745.36000000","0.03539000"],["84745.07000000","0.00000000"],["84744.54000000","0.00000000"],["84744.28000000","0.06900000"],["84744.25000000","0.00000000"],["84744.12000000","0.02000000"],["84743.52000000","0.00236000"],["84742.84000000","0.00006000"],["84742.20000000","0.00013000"],["84741.89000000","0.00000000"],["84741.39000000","0.00013000"],["84741.07000000","0.00590000"],["84740.58000000","0.00013000"],["84740.28000000","0.14728000"],["84740.23000000","0.00000000"],["84740.00000000","0.00000000"],["84739.77000000","0.00013000"],["84738.96000000","0.00013000"],["84738.27000000","0.00590000"],["84737.45000000","0.00000000"],["84737.40000000","0.00200000"],["84737.02000000","0.00000000"],["84736.86000000","0.00000000"],["84736.79000000","0.00000000"],["84736.77000000","0.00000000"],["84736.74000000","0.00000000"],["84736.41000000","0.00000000"],["84736.19000000","0.00000000"],["84736.07000000","0.00400000"],["84735.62000000","0.00000000"],["84735.42000000","0.35516000"],["84731.85000000","0.00200000"],["84731.37000000","0.00000000"],["84731.36000000","0.00000000"],["84730.86000000","0.00000000"],["84730.05000000","0.00000000"],["84729.24000000","0.00000000"],["84729.00000000","0.10462000"],["84728.43000000","0.00000000"],["84727.62000000","0.00000000"],["84722.92000000","0.91888000"],["84722.91000000","0.59032000"],["84722.74000000","0.00000000"],["84722.03000000","0.00000000"],["84719.19000000","0.00200000"],["84715.20000000","0.00400000"],["84710.60000000","0.00006000"],["84704.25000000","0.31896000"],["84668.14000000","0.00000000"],["84633.20000000","0.00000000"],["84632.99000000","0.04013000"],["83481.71000000","0.00024000"],["83000.00000000","61.02863000"],["76277.70000000","0.00330000"],["67802.40000000","0.00203000"]],"a":[["84753.01000000","4.22969000"],["84753.02000000","0.00012000"],["84754.77000000","0.00014000"],["84754.93000000","0.00012000"],["84755.00000000","0.11886000"],["84755.16000000","0.00019000"],["84756.57000000","0.00000000"],["84756.85000000","0.00000000"],["84756.92000000","0.00000000"],["84757.35000000","0.00308000"],["84757.39000000","0.01546000"],["84757.53000000","0.02006000"],["84757.58000000","0.00590000"],["84757.71000000","0.00000000"],["84757.97000000","0.00000000"],["84757.98000000","0.00000000"],["84758.18000000","0.00000000"],["84758.19000000","0.74055000"],["84758.35000000","0.00000000"],["84758.51000000","0.03545000"],["84758.68000000","0.01101000"],["84758.89000000","0.00236000"],["84760.36000000","0.00000000"],["84760.58000000","0.00000000"],["84761.70000000","0.00400000"],["84764.70000000","0.00000000"],["84765.42000000","0.00000000"],["84765.43000000","0.00200000"],["84768.24000000","0.00000000"],["84768.89000000","0.00000000"],["84768.94000000","0.13727000"],["84769.24000000","0.00000000"],["84770.31000000","0.00000000"],["84770.42000000","0.07571000"],["84771.24000000","0.00000000"],["84771.95000000","0.11796000"],["84772.51000000","0.00000000"],["84774.75000000","0.00000000"],["84774.93000000","0.11796000"],["84777.80000000","0.31857000"],["84779.56000000","0.00000000"],["84780.38000000","0.00000000"],["84781.15000000","0.58992000"],["84795.03000000","0.00000000"],["84800.64000000","1.17968000"],["84801.89000000","0.01663000"],["84806.57000000","0.00000000"],["84815.28000000","0.00000000"],["84885.34000000","0.00000000"],["84887.28000000","0.06797000"]]}}
{"stream":"dogeusdt@depth@100ms","data":{"e":"depthUpdate","E":1790299072274,"s":"DOGEUSDT","U":25516670103,"u":25516670111,"b":[["0.09677000","26365.00000000"],["0.09676000","121820.00000000"]],"a":[]}}
{"stream":"btcusdt@depth@100ms","data":{"e":"depthUpdate","E":1790299072314,"s":"BTCUSDT","U":100639387554,"u":100639387635,"b":[["84753.00000000","1.01922000"],["84752.99000000","0.00061000"],["84752.98000000","0.00032000"],["84748.91000000","0.10557000"],["84747.00000000","0.00000000"],["84746.87000000","0.00012000"],["84746.35000000","0.00024000"],["84745.06000000","0.03200000"],["84742.84000000","0.00012000"],["84742.37000000","0.00047000"],["84741.71000000","0.00048000"],["84740.81000000","0.00000000"],["84738.99000000","0.00000000"],["84738.32000000","0.00200000"],["84737.45000000","0.00000000"],["84737.40000000","0.00000000"],["84736.74000000","0.00000000"],["84714.95000000","0.00000000"],["84706.72000000","0.00400000"],["84706.57000000","0.00006000"],["84693.48000000","0.00171000"],["84632.99000000","0.13105000"],["76277.70000000","0.00338000"],["67802.00000000","0.00000000"]],"a":[["84753.01000000","4.25675000"],["84754.78000000","0.04145000"],["84754.97000000","0.00014000"],["84754.98000000","0.01123000"],["84755.00000000","0.11892000"],["84755.48000000","0.00400000"],["84755.85000000","0.01090000"],["84756.72000000","0.00236000"],["84757.38000000","0.00000000"],["84758.89000000","0.00000000"],["84759.50000000","0.10462000"],["84763.48000000","0.00000000"],["84764.15000000","0.00000000"],["84764.49000000","0.00000000"],["84765.20000000","0.00000000"],["84765.66000000","0.02994000"],["84769.63000000","0.11797000"],["84774.93000000","0.00000000"],["84789.40000000","0.00442000"],["84803.05000000","0.00000000"],["84887.28000000","0.00000000"]]}}
{"stream":"dogeusdt@depth@100ms","data":{"e":"depthUpdate","E":1790299072374,"s":"DOGEUSDT","U":25516670112,"u":25516670117,"b":[["0.09677000","24365.00000000"],["0.09676000","120376.00000000"],["0.09675000","142728.00000000"]],"a":[]}}
{"stream":"btcusdt@depth@100ms","data":{"e":"depthUpdate","E":1790299072414,"s":"BTCUSDT","U":100639387636,"u":100639387673,"b":[["84753.00000000","1.01922000"],["84752.99000000","0.00061000"],["84751.64000000","0.01823000"],["84751.54000000","0.00006000"],["84748.93000000","0.02192000"],["84748.92000000","0.00014000"],["84745.98000000","0.00006000"],["84740.63000000","0.00236000"],["84739.71000000","0.00000000"],["84736.41000000","0.00200000"],["84730.58000000","0.00166000"],["83481.71000000","0.00024000"],["82000.00000000","117.78245000"],["67802.40000000","0.00174000"]],"a":[["84753.01000000","4.25769000"],["84753.36000000","0.00400000"],["84757.38000000","0.00014000"],["84757.52000000","0.00007000"],["84758.68000000","0.01107000"],["84760.12000000","0.00000000"],["84760.13000000","0.00000000"],["84762.26000000","0.00000000"],["84779.41000000","0.31856000"],["84787.28000000","0.00000000"],["84797.89000000","0.00000000"],["84881.37000000","0.09105000"]]}}
{"stream":"btcusdt@depth@100ms","data":{"e":"depthUpdate","E":1790299072514,"s":"BTCUSDT","U":100639387674,"u":100639387708,"b":[["84752.73000000","0.00013000"],["84751.92000000","0.00013000"],["84751.11000000","0.00013000"],["84750.30000000","0.00013000"],["84749.49000000","0.00013000"],["84748.68000000","0.00013000"],["84747.87000000","0.00013000"],["84747.06000000","0.00013000"],["84746.25000000","0.00013000"],["84745.44000000","0.00013000"],["84742.20000000","0.00000000"],["84742.13000000","0.00200000"],["84741.39000000","0.00000000"],["84740.58000000","0.00000000"],["84739.77000000","0.00000000"],["84738.96000000","0.00000000"],["84736.08000000","0.00200000"],["84734.91000000","0.00000000"],["84734.10000000","0.00000000"],["84733.29000000","0.00000000"],["84732.48000000","0.00000000"],["84731.67000000","0.00000000"],["84659.62000000","0.76755000"],["84656.98000000","1.09581000"],["84542.01000000","0.00000000"],["84540.02000000","0.00734000"],["83481.71000000","0.00016000"],["76277.70000000","0.00353000"],["67802.40000000","0.00290000"]],"a":[["84753.54000000","0.00013000"],["84754.35000000","0.00013000"],["84761.64000000","0.00000000"],["84762.45000000","0.00000000"]]}}
{"stream":"dogeusdt@depth@100ms","data":{"e":"depthUpdate","E":1790299072574,"s":"DOGEUSDT","U":25516670118,"u":25516670128,"b":[["0.09676000","108056.00000000"],["0.09675000","132396.00000000"],["0.09666000","772828.00000000"],["0.09665000","323901.00000000"],["0.09662000","215906.00000000"],["0.09661000","14064.00000000"]],"a":[["0.09699000","368092.00000000"]]}}
{"stream":"btcusdt@depth@100ms","data":{"e":"depthUpdate","E":1790299072614,"s":"BTCUSDT","U":100639387709,"u":100639387761,"b":[["84753.00000000","1.01915000"],["84751.99000000","0.00007000"],["84746.53000000","0.00000000"],["84746.05000000","0.00000000"],["84746.04000000","0.00000000"],["84745.98000000","0.00013000"],["84744.28000000","0.16335000"],["84743.09000000","0.34486000"],["84742.13000000","0.00000000"],["84739.80000000","0.00000000"],["84739.78000000","0.00000000"],["84739.67000000","0.00000000"],["84739.17000000","0.00200000"],["84738.32000000","0.00000000"],["84737.45000000","0.00600000"],["84737.10000000","0.00400000"],["84736.41000000","0.00000000"],["84736.08000000","0.00000000"],["84736.07000000","0.00000000"],["84722.92000000","0.53244000"],["84719.19000000","0.00000000"],["84718.80000000","0.00200000"],["83481.71000000","0.00024000"],["67802.40000000","0.00261000"],["67802.00000000","0.00000000"]],"a":[["84753.01000000","4.25838000"],["84757.38000000","0.00014000"],["84757.52000000","0.00007000"],["84803.86000000","0.00013000"]]}}
{"stream":"dogeusdt@depth@100ms","data":{"e":"depthUpdate","E":1790299072674,"s":"DOGEUSDT","U":25516670129,"u":25516670142,"b":[["0.09677000","5302.00000000"],["0.09676000","81680.00000000"],["0.09662000","215917.00000000"]],"a":[["0.09678000","71852.00000000"],["0.09679000","91275.00000000"],["0.09680000","139711.00000000"],["0.09681000","193397.00000000"],["0.09682000","121362.00000000"]]}}
{"stream":"btcusdt@depth@100ms","data":{"e":"depthUpdate","E":1790299072714,"s":"BTCUSDT","U":100639387762,"u":100639387888,"b":[["84753.00000000","0.63968000"],["84751.22000000","0.01097000"],["84748.91000000","0.00000000"],["84747.27000000","0.00095000"],["84746.87000000","0.00006000"],["84746.35000000","0.00000000"],["84745.36000000","0.00000000"],["84744.88000000","0.00000000"],["84744.14000000","0.00000000"],["84742.84000000","0.00012000"],["84741.55000000","0.03539000"],["84740.63000000","0.00000000"],["84739.17000000","0.00000000"],["84738.78000000","0.00095000"],["84738.65000000","0.00000000"],["84738.29000000","0.00000000"],["84737.61000000","0.00000000"],["84737.56000000","0.00000000"],["84737.51000000","0.00000000"],["84737.45000000","0.00000000"],["84737.10000000","0.00000000"],["84736.98000000","0.00000000"],["84736.83000000","0.00200000"],["84736.74000000","0.00000000"],["84736.07000000","0.00000000"],["84735.62000000","0.00000000"],["84735.43000000","0.36116000"],["84735.42000000","0.00000000"],["84732.51000000","0.00000000"],["84732.18000000","0.00000000"],["84731.85000000","0.00200000"],["84730.20000000","0.12000000"],["84724.35000000","0.00000000"],["84718.80000000","0.00000000"],["84710.96000000","0.00400000"],["84704.87000000","0.00000000"],["84702.54000000","0.00000000"],["83481.71000000","0.00024000"],["81000.00000000","71.08861000"],["76277.70000000","0.00345000"],["76277.69000000","0.00008000"]],"a":[["84753.01000000","4.26428000"],["84753.02000000","0.00022000"],["84753.42000000","0.03539000"],["84754.04000000","0.00190000"],["84754.77000000","0.00000000"],["84754.78000000","0.06419000"],["84754.89000000","0.00000000"],["84754.97000000","0.00000000"],["84754.99000000","0.00000000"],["84755.00000000","0.11898000"],["84755.19000000","0.00590000"],["84755.62000000","0.00000000"],["84756.72000000","0.00000000"],["84757.38000000","0.00000000"],["84757.52000000","0.00000000"],["84757.58000000","0.00000000"],["84758.19000000","0.74049000"],["84758.51000000","0.00006000"],["84758.80000000","0.03000000"],["84761.13000000","0.85230000"],["84765.52000000","0.00006000"],["84766.50000000","0.00000000"],["84767.08000000","0.00000000"],["84768.91000000","0.00000000"],["84769.30000000","0.00000000"],["84771.95000000","0.00000000"],["84772.56000000","0.00000000"],["84778.21000000","0.01967000"],["84789.40000000","0.00000000"],["84791.75000000","1.16789000"],["84962.00000000","0.00000000"]]}}
{"stream":"dogeusdt@depth@100ms","data":{"e":"depthUpdate","E":1790299072774,"s":"DOGEUSDT","U":25516670143,"u":25516670152,"b":[["0.09675000","124396.00000000"],["0.09674000","373916.00000000"],["0.09666000","599026.00000000"]],"a":[["0.09679000","89553.00000000"],["0.09680000","147711.00000000"],["0.09683000","127662.00000000"],["0.09684000","185370.00000000"],["0.09685000","123515.00000000"]]}}
{"stream":"btcusdt@depth@100ms","data":{"e":"depthUpdate","E":1790299072814,"s":"BTCUSDT","U":100639387889,"u":100639387937,"b":[["84753.00000000","0.63891000"],["84752.99000000","0.00061000"],["84751.64000000","0.01823000"],["84751.22000000","0.00000000"],["84748.93000000","0.02180000"],["84748.92000000","0.00000000"],["84748.76000000","0.00006000"],["84746.35000000","0.00024000"],["84745.98000000","0.00020000"],["84745.66000000","0.01106000"],["84743.10000000","0.00007000"],["84742.76000000","0.00000000"],["84742.60000000","0.00070000"],["84738.65000000","0.00006000"],["84713.33000000","0.00000000"],["84708.84000000","0.00400000"],["84702.97000000","0.00353000"],["83481.70000000","0.00626000"],["76277.70000000","0.00330000"],["67802.40000000","0.00232000"]],"a":[["84753.01000000","4.26421000"],["84755.00000000","0.11898000"],["84757.53000000","0.02000000"],["84758.68000000","0.01113000"],["84771.90000000","0.00442000"],["84772.56000000","0.00006000"],["84778.21000000","0.00000000"],["84781.38000000","0.00118000"],["84781.67000000","0.00442000"],["84792.38000000","0.02325000"],["84798.10000000","0.00169000"]]}}
{"stream":"dogeusdt@depth@100ms","data":{"e":"depthUpdate","E":1790299072874,"s":"DOGEUSDT","U":25516670153,"u":25516670160,"b":[["0.09677000","24376.00000000"],["0.09676000","62003.00000000"],["0.09675000","128597.00000000"],["0.09674000","394923.00000000"],["0.09671000","283675.00000000"]],"a":[["0.09685000","142117.00000000"]]}}
{"stream":"btcusdt@depth@100ms","data":{"e":"depthUpdate","E":1790299072914,"s":"BTCUSDT","U":100639387938,"u":100639388082,"b":[["84753.00000000","1.00861000"],["84752.99000000","0.00061000"],["84742.65000000","0.00000000"],["84742.60000000","0.00000000"],["84739.24000000","0.00000000"],["84738.95000000","0.00000000"],["84738.88000000","0.00000000"],["84738.84000000","0.00200000"],["84738.41000000","0.00000000"],["84737.45000000","0.00200000"],["84736.83000000","0.00000000"],["84735.44000000","0.00200000"],["84735.43000000","0.35916000"],["83481.71000000","0.00024000"],["80000.00000000","117.90091000"],["77972.77000000","0.00000000"],["76277.70000000","0.00345000"]],"a":[["84753.01000000","4.15582000"],["84753.41000000","0.00014000"],["84753.80000000","0.00000000"],["84754.04000000","0.00000000"],["84754.11000000","0.00000000"],["84754.13000000","0.00000000"],["84754.15000000","0.00000000"],["84754.18000000","0.00000000"],["84754.23000000","0.00000000"],["84754.38000000","0.00007000"],["84754.52000000","0.00200000"],["84754.77000000","0.00014000"],["84754.93000000","0.00006000"],["84754.97000000","0.00014000"],["84754.99000000","0.00014000"],["84755.85000000","0.01096000"],["84756.77000000","0.00000000"],["84757.38000000","0.00000000"],["84757.76000000","0.00590000"],["84758.18000000","0.00000000"],["84758.68000000","0.01107000"],["84758.96000000","0.00006000"],["84759.20000000","0.00200000"],["84759.50000000","0.00000000"],["84761.12000000","0.00600000"],["84761.70000000","0.00000000"],["84762.12000000","0.00000000"],["84765.43000000","0.00000000"],["84769.30000000","0.00190000"],["84775.16000000","0.00000000"],["84931.48000000","0.01848000"],["84989.49000000","0.00000000"]]}}
{"stream":"dogeusdt@depth@100ms","data":{"e":"depthUpdate","E":1790299072974,"s":"DOGEUSDT","U":25516670161,"u":25516670300,"b":[["0.09677000","0.00000000"],["0.09676000","34210.00000000"],["0.09675000","38491.00000000"],["0.09674000","217078.00000000"],["0.09673000","9163.00000000"],["0.09670000","198834.00000000"],["0.09669000","218834.00000000"],["0.09668000","105892.00000000"],["0.09666000","376741.00000000"],["0.09665000","333111.00000000"],["0.09664000","71734.00000000"],["0.09662000","438202.00000000"],["0.09659000","181617.00000000"],["0.09658000","374982.00000000"],["0.09657000","600623.00000000"],["0.09647000","132505.00000000"],["0.09645000","153687.00000000"],["0.09640000","258946.00000000"],["0.09628000","508.00000000"]],"a":[["0.09677000","178092.00000000"],["0.09678000","78504.00000000"],["0.09679000","91921.00000000"],["0.09680000","213518.00000000"],["0.09681000","193449.00000000"],["0.09682000","125312.00000000"],["0.09683000","127610.00000000"],["0.09684000","385961.00000000"],["0.09685000","884989.00000000"],["0.09686000","136935.00000000"],["0.09687000","286057.00000000"],["0.09688000","429696.00000000"],["0.09690000","350358.00000000"],["0.09691000","129594.00000000"],["0.09694000","667451.00000000"],["0.09696000","158959.00000000"],["0.09697000","182002.00000000"]]}}
{"stream":"btcusdt@depth@100ms","data":{"e":"depthUpdate","E":1790299073014,"s":"BTCUSDT","U":100639388083,"u":100639388148,"b":[["84753.00000000","1.00837000"],["84746.02000000","0.61330000"],["84745.99000000","0.00000000"],["84745.97000000","1.92024000"],["84745.76000000","0.01098000"],["84745.66000000","0.01100000"],["84745.06000000","0.00000000"],["84743.24000000","0.00070000"],["84742.76000000","0.03200000"],["84741.55000000","0.00000000"],["84737.81000000","0.00000000"],["84735.51000000","0.03000000"],["84711.58000000","0.04600000"],["84710.74000000","0.04400000"],["84702.54000000","0.00000000"],["84690.43000000","0.03600000"],["84689.57000000","0.04800000"],["83481.71000000","0.00016000"],["76277.70000000","0.00345000"],["76277.69000000","0.00000000"],["67802.40000000","0.00319000"]],"a":[["84753.01000000","4.26025000"],["84753.41000000","0.00000000"],["84753.42000000","0.00000000"],["84754.77000000","0.00000000"],["84754.93000000","0.00012000"],["84754.97000000","0.00000000"],["84754.99000000","0.00000000"],["84755.85000000","0.01090000"],["84757.53000000","0.02006000"],["84758.96000000","0.00012000"],["84759.50000000","0.10462000"],["84759.70000000","0.02000000"],["84760.65000000","0.02000000"],["84761.12000000","0.00600000"],["84763.98000000","0.02000000"],["84764.84000000","0.02000000"],["84765.39000000","0.35516000"],["84766.38000000","0.00000000"]]}}
{"stream":"dogeusdt@depth@100ms","data":{"e":"depthUpdate","E":1790299073074,"s":"DOGEUSDT","U":25516670301,"u":25516670367,"b":[["0.09676000","15125.00000000"],["0.09675000","11690.00000000"],["0.09674000","84538.00000000"],["0.09673000","70791.00000000"],["0.09672000","225207.00000000"],["0.09671000","283664.00000000"],["0.09668000","101384.00000000"],["0.09667000","119609.00000000"],["0.09664000","64388.00000000"],["0.09663000","264654.00000000"],["0.09662000","438202.00000000"],["0.09661000","130.00000000"],["0.09660000","74565.00000000"],["0.09658000","518899.00000000"],["0.09638000","207243.00000000"],["0.09636000","1952.00000000"],["0.09611000","1666.00000000"],["0.09608000","6550.00000000"],["0.09601000","561.00000000"]],"a":[["0.09677000","178103.00000000"],["0.09678000","78520.00000000"],["0.09685000","892319.00000000"],["0.09688000","422368.00000000"],["0.09689000","199298.00000000"],["0.09691000","122268.00000000"],["0.09693000","551178.00000000"],["0.09695000","154397.00000000"],["0.09696000","175697.00000000"],["0.09697000","115908.00000000"],["0.09698000","256218.00000000"],["0.09699000","237891.00000000"],["0.09714000","53576.00000000"],["0.09718000","118049.00000000"],["0.09753000","2052.00000000"]]}}
{"stream":"btcusdt@depth@100ms","data":{"e":"depthUpdate","E":1790299073114,"s":"BTCUSDT","U":100639388149,"u":100639388185,"b":[["84753.00000000","1.00830000"],["84752.99000000","0.00061000"],["84752.75000000","0.00000000"],["84751.99000000","0.00000000"],["84738.87000000","0.03539000"],["84737.45000000","0.00600000"],["84718.77000000","0.00200000"],["84689.60000000","0.04800000"],["84686.23000000","0.04600000"],["84685.72000000","0.04200000"],["84661.87000000","0.00000000"],["84658.37000000","0.00000000"],["84657.54000000","0.00000000"],["83481.71000000","0.00024000"]],"a":[["84753.01000000","4.26038000"],["84754.51000000","0.00007000"],["84755.19000000","0.00596000"],["84755.83000000","0.03539000"],["84760.56000000","0.02325000"],["84764.45000000","0.02000000"],["84770.14000000","0.00000000"],["84770.20000000","0.00000000"],["84770.42000000","0.05463000"],["84773.50000000","0.00000000"],["84774.00000000","0.00000000"],["84774.40000000","0.00000000"],["84811.66000000","0.00000000"],["84815.90000000","0.00000000"],["84931.48000000","0.00000000"],["84981.56000000","0.01848000"],["86024.31000000","0.00030000"]]}}
{"stream":"dogeusdt@depth@100ms","data":{"e":"depthUpdate","E":1790299073174,"s":"DOGEUSDT","U":25516670368,"u":25516670389,"b":[["0.09676000","15109.00000000"],["0.09674000","75153.00000000"],["0.09673000","100925.00000000"],["0.09666000","374313.00000000"],["0.09662000","440602.00000000"]],"a":[["0.09677000","178125.00000000"],["0.09678000","90763.00000000"],["0.09679000","71479.00000000"],["0.09683000","365733.00000000"],["0.09684000","1160435.00000000"],["0.09715000","670143.00000000"]]}}
{"stream":"btcusdt@depth@100ms","data":{"e":"depthUpdate","E":1790299073214,"s":"BTCUSDT","U":100639388186,"u":100639388212,"b":[["84753.00000000","1.00789000"],["84746.02000000","0.61324000"],["84745.76000000","0.00000000"],["84743.43000000","0.00069000"],["84743.24000000","0.00000000"],["84667.72000000","0.00000000"],["84664.33000000","0.00000000"],["83481.71000000","0.00024000"],["79000.00000000","82.43884000"],["76277.70000000","0.00345000"],["67802.40000000","0.00290000"]],"a":[["84753.01000000","4.26038000"],["84769.25000000","0.00000000"],["84771.61000000","0.11796000"],["84783.00000000","0.70000000"],["84791.52000000","1.95885000"],["84792.00000000","0.00000000"]]}}
{"stream":"dogeusdt@depth@100ms","data":{"e":"depthUpdate","E":1790299073274,"s":"DOGEUSDT","U":25516670390,"u":25516670611,"b":[["0.09676000","0.00000000"],["0.09675000","0.00000000"],["0.09674000","55509.00000000"],["0.09673000","25573.00000000"],["0.09672000","122958.00000000"],["0.09671000","297635.00000000"],["0.09670000","197811.00000000"],["0.09669000","226834.00000000"],["0.09668000","110417.00000000"],["0.09667000","101979.00000000"],["0.09666000","315711.00000000"],["0.09665000","336172.00000000"],["0.09664000","63871.00000000"],["0.09662000","440602.00000000"],["0.09661000","7490.00000000"],["0.09660000","68168.00000000"],["0.09659000","182134.00000000"],["0.09657000","600634.00000000"],["0.09656000","382024.00000000"],["0.09655000","66114.00000000"],["0.09642000","15809.00000000"],["0.09637000","16692.00000000"],["0.09600000","10861.00000000"],["0.09599000","127.00000000"]],"a":[["0.09675000","58946.00000000"],["0.09676000","64632.00000000"],["0.09677000","123943.00000000"],["0.09678000","86008.00000000"],["0.09679000","159111.00000000"],["0.09680000","213570.00000000"],["0.09681000","178334.00000000"],["0.09683000","110444.00000000"],["0.09684000","185370.00000000"],["0.09685000","121918.00000000"],["0.09686000","189375.00000000"],["0.09687000","286068.00000000"],["0.09689000","195273.00000000"],["0.09692000","218566.00000000"],["0.09693000","551175.00000000"],["0.09694000","667440.00000000"],["0.09695000","112437.00000000"],["0.09696000","149749.00000000"],["0.09697000","106698.00000000"],["0.09707000","12028.00000000"],["0.09718000","6833.00000000"],["0.09724000","827.00000000"],["0.09751000","3312.00000000"],["0.09752000","3218.00000000"]]}}
{"stream":"btcusdt@depth@100ms","data":{"e":"depthUpdate","E":1790299073314,"s":"BTCUSDT","U":100639388213,"u":100639388243,"b":[["84753.00000000","0.63819000"],["84752.99000000","0.00068000"],["84751.54000000","0.00000000"],["84751.03000000","0.00000000"],["84751.02000000","0.00000000"],["84748.93000000","0.02186000"],["84748.51000000","0.00014000"],["84748.50000000","0.04157000"],["84745.66000000","0.01106000"],["84744.75000000","0.00000000"],["84743.46000000","0.00000000"],["84743.43000000","0.00000000"],["84741.19000000","0.00000000"],["84737.45000000","0.00200000"],["84657.12000000","0.00000000"],["76277.00000000","0.00272000"]],"a":[["84753.01000000","4.26038000"],["84755.85000000","0.01096000"],["84756.89000000","0.04000000"],["84761.12000000","0.00800000"]]}}
{"stream":"dogeusdt@depth@100ms","data":{"e":"depthUpdate","E":1790299073374,"s":"DOGEUSDT","U":25516670612,"u":25516670639,"b":[["0.09674000","57588.00000000"],["0.09672000","104865.00000000"],["0.09671000","315575.00000000"],["0.09670000","234506.00000000"],["0.09668000","116911.00000000"],["0.09667000","117993.00000000"],["0.09666000","314114.00000000"],["0.09664000","63860.00000000"],["0.09662000","442199.00000000"],["0.09614000","17290.00000000"],["0.09611000","1677.00000000"],["0.09609000","24306.00000000"],["0.09605000","1036081.00000000"]],"a":[["0.09676000","64695.00000000"],["0.09677000","171455.00000000"],["0.09678000","230162.00000000"],["0.09681000","167767.00000000"],["0.09682000","211546.00000000"],["0.09683000","93373.00000000"],["0.09688000","306589.00000000"]]}}
{"stream":"btcusdt@depth@100ms","data":{"e":"depthUpdate","E":1790299073414,"s":"BTCUSDT","U":100639388244,"u":100639388259,"b":[["84753.00000000","0.63700000"],["84752.99000000","0.00061000"],["84745.66000000","0.01100000"],["84743.39000000","0.00070000"],["84735.43000000","0.00400000"],["84660.97000000","0.00000000"],["84604.73000000","0.01200000"],["83481.71000000","0.00024000"],["78000.00000000","93.36425000"],["76277.70000000","0.00353000"],["67802.40000000","0.00261000"]],"a":[["84803.28000000","0.02652000"]]}}
{"stream":"dogeusdt@depth@100ms","data":{"e":"depthUpdate","E":1790299073474,"s":"DOGEUSDT","U":25516670640,"u":25516670646,"b":[["0.09661000","16700.00000000"],["0.09655000","52191.00000000"]],"a":[["0.09681000","197143.00000000"],["0.09682000","199559.00000000"],["0.09697000","183179.00000000"]]}}
{"stream":"btcusdt@depth@100ms","data":{"e":"depthUpdate","E":1790299073514,"s":"BTCUSDT","U":100639388260,"u":100639388276,"b":[["84753.00000000","0.63707000"],["84752.99000000","0.00068000"],["84748.93000000","0.02192000"],["84748.67000000","0.00014000"],["84748.66000000","0.10462000"],["84743.10000000","0.00000000"],["84737.10000000","0.00400000"],["84718.77000000","0.00000000"],["83481.71000000","0.00016000"],["76277.70000000","0.00338000"],["67802.00000000","0.00000000"]],"a":[["84753.01000000","4.26038000"],["84775.54000000","0.00200000"]]}}
{"stream":"dogeusdt@depth@100ms","data":{"e":"depthUpdate","E":1790299073574,"s":"DOGEUSDT","U":25516670647,"u":25516670658,"b":[["0.09674000","58622.00000000"],["0.09668000","121540.00000000"],["0.09654000","269918.00000000"]],"a":[["0.09683000","138929.00000000"],["0.09692000","247127.00000000"],["0.09695000","149392.00000000"],["0.09696000","181598.00000000"]]}}
{"stream":"btcusdt@depth@100ms","data":{"e":"depthUpdate","E":1790299073614,"s":"BTCUSDT","U":100639388277,"u":100639388281,"b":[["83481.71000000","0.00024000"],["76277.70000000","0.00353000"],["67802.40000000","0.00232000"]],"a":[["84753.01000000","4.26038000"]]}}
{"stream":"dogeusdt@depth@100ms","data":{"e":"depthUpdate","E":1790299073674,"s":"DOGEUSDT","U":25516670659,"u":25516670678,"b":[["0.09674000","30666.00000000"],["0.09673000","44343.00000000"],["0.09672000","104876.00000000"]],"a":[["0.09676000","79440.00000000"],["0.09677000","193199.00000000"],["0.09678000","212026.00000000"]]}}
